Workbook
Name _: #REF!
Name _.xls: #REF!
Name _00: #REF!
Name _005: #REF!
Name _01.xls: #REF!
Name _02.xls: #REF!
Name _03.xls: #REF!
Name _0hlz: #REF!
Name _0hw: #REF!
Name _0hz: #REF!
Name _0HZL: #REF!
Name _0hzlr: #REF!
Name _0hzww: #REF!
Name _1_: #REF!
Name _11.xls: #REF!
Name _11U400_: OFFSET(Full_Print,0,0,K1_400折旧测试!Last_Row)
Name _11U400_: OFFSET(Full_Print,0,0,Last_Row)
Name _12.xls: #REF!
Name _121.dbf: #REF!
Name _1212002.dbf: #REF!
Name _13U500_: IF(K1_400折旧测试!Values_Entered,Header_Row+K1_400折旧测试!Number_of_Payments,Header_Row)
Name _13U500_: IF(Values_Entered,Header_Row+Number_of_Payments,Header_Row)
Name _15其他资产_开办费除外_明细表: #REF!
Name _17103.dbf: #REF!
Name _171032002.dbf: #REF!
Name _2¸ß¼ÛÖÜ×ª¼þ_¨º½²Ä¹ý¶É: #REF!
Name _3hlz: #REF!
Name _3hw: #REF!
Name _3hz: #REF!
Name _4¹Ì¶¨×Ê²úÇåµ: #REF!
Name _5hlz: #REF!
Name _5hw: #REF!
Name _5hzl: #REF!
Name _7G100_: DATE(YEAR(Loan_Start),MONTH(Loan_Start)+Payment_Number,DAY(Loan_Start))
Name _7G100_: DATE(YEAR(Loan_Start),MONTH(Loan_Start)+Payment_Number,DAY(Loan_Start))
Name _8未还DB_查询: #REF!
Name _9U300_: MATCH(0.01,End_Bal,-1)+1
Name _9U300_: MATCH(0.01,End_Bal,-1)+1
Name _DAT1: #REF!
Name _DAT10: #REF!
Name _DAT11: #REF!
Name _DAT12: #REF!
Name _DAT13: #REF!
Name _DAT14: #REF!
Name _DAT2: #REF!
Name _DAT3: #REF!
Name _DAT4: #REF!
Name _DAT5: #REF!
Name _DAT6: #REF!
Name _DAT7: #REF!
Name _DAT8: #REF!
Name _DAT9: #REF!
Name _DIV01: #REF!
Name _DIV02: #REF!
Name _DIV31: #REF!
Name _DIV32: #REF!
Name _DIV34: #REF!
Name _DIV38: #REF!
Name _DIV93: #REF!
Name _exr99: 115

Sheet Comments【归档前删除】
A1: EY Ref. | B1: Tab Ref. | C1: Cell Ref. | D1: Question/Comment | E1: Answer/Comment | F1: Closed?
A2: 1 | B2: K1_400折旧测试 | C2: $P$142 | D2: Momo Li: 这个测算为啥要用36，账面不是60吗，这个是折旧期更长应该也不是因为税法的影响吧 | F2: No
A3: 2 | B3: K1_400折旧测试 | C3: $U$325 | D3: Momo Li: 这个差异是因为残值率的不同吧，也要调整吗 | F3: No
A4: 3 | B4: K1_400折旧测试 | C4: $C$435 | D4: Momo Li: 这个部分和agree sl to gl是不是重复了，留一个就行吧 | E4: 已更正 | F4: No
A5: 4 | B5: K.02.1 新增测试 | C5: $L$34 | D5: Momo Li: 注意更新 | F5: No

Sheet 汇总 
A1: V6 SWP
B2: 该科目涉及OSP底稿可参考此链接 | F2: OSP K1 SWP 固定资产及在建工程盘点 202YMMDD XYZ公司.xlsx
F3: OSP K1 SWP 固定资产权属检查 202YMMDD XYZ公司.xlsx
B5: K.00 | C5: K.00 Lead Sheet | F5: 程序页 | G5: 执行 | H5: 不执行的原因 | I5: 注意事项
B6: 1 | C6: 获取和编制固定资产两期变动的引导表，并与试算平衡表和上年底稿核对一致。对固定资产变动建立预期并说明理由，对不符合预期的变动以及异常变动进行调查和分析。 | F6: K.00 Lead Sheet | G6: 是
B7: K.01 | C7: K.01 Agree SL to GL（认定：BS：E、V、C IS：M、C） | F7: 程序页 | G7: 执行 | H7: 不执行的原因 | I7: 注意事项
B8: 1 | C8: 获取固定资产后推明细表，并将其与试算平衡表和固定资产清单核对一致。 | F8: K.01 Agree SL to GL | G8: 是
B9: K.02 | C9: K.02.1 新增测试（认定：BS：E、V、C、R&O、P&D IS：M,P&D） | F9: 程序页 | G9: 执行 | H9: 不执行的原因 | I9: 注意事项
B10: 1 | C10: 获取当期按类别划分的所有固定资产新增清单，并将该清单与固定资产后推核对一致，调查超过SAD名义金额的差额。 | F10: 新增清单 | G10: 是 | I10: 若在建工程为不重大账户未开底稿，则项目组需要在K1 SWP中核对在建工程转入与转出金额是否一致，并按照<J.02.2 CIP transfer (ToD)>的测试属性执行该程序。
B11: 2 | C11: 对本年新增资产执行关键性样本测试和代表性样本测试（如需要）。 | F11: K.02.1 新增测试 | G11: 是
F12: K.02.1a 新增选样输出
B13: K.02 | C13: K.02.2 处置测试（认定：BS：E、V、C、R&O、P&D IS：M,P&D） | F13: 程序页 | G13: 执行 | H13: 不执行的原因 | I13: 注意事项
B14: 1 | C14: 获取当期按类别划分的所有固定资产处置清单，包括记录的处置的损益，并将该清单与固定资产后推核对一致，我们调查超过SAD名义金额的差额。 | F14: 处置清单 | G14: 是
B15: 2 | C15: 对本年处置资产执行关键性样本测试和代表性样本测试（如需要）。 | F15: K.02.2 处置测试 | G15: 否 | H15: 处置金额小于TE，不执行该程序
F16: K.02.2a 处置选样输出
B17: K.03 | C17: K.03 折旧测试（认定：BS：V IS:O、M、P&D） | F17: 程序页 | G17: 执行 | H17: 不执行的原因 | I17: 注意事项
B18: 1 | C18: 执行实质性分析程序(SAP)测试折旧费用，可参考264 GL 或K.03.1 SAP模板执行。如不执行，可直接执行K.03.2 折旧测试TOD。 | F18: K.03.1 SAP | G18: 否 | H18: 进行折旧测试，详见<K1_400折旧测试>
B19: 2 | C19: 如选择执行详细测试，可使用该底稿记录。 | F19: K.03.2 折旧测试TOD | G19: 是 | H19: 进行折旧测试，详见<K1_400折旧测试>
B20: 3 | C20: 检查固定资产各项目的折旧政策是否符合有关规定，是否与上期一致，评价其合理性。若改变折旧政策，检查其依据是否充分。 | F20: K.03.3 折旧政策复核 | G20: 是
B21: K.04 | C21: K.04 固定资产的减值（认定：BS：V IS：M） | F21: 程序页 | G21: 执行 | H21: 不执行的原因 | I21: 注意事项
B22: 1 | C22: 1.使用在审计过程中所获得的信息来确定管理层是否已识别适当的减值迹象；可使用PSP Canvas form K.04：识别减值迹象，也可使用 <SWP减值迹象识别> 对减值迹象进行评估，并根据指引要求获取相关支持性文件。 2.如有减值迹象的，评价管理层假设、未来现金流等减值评估的合理性，核实并测算减值金额。 3.检查是否存在转回固定资产减值准备的情况，确定减值准备在以后会计期间没有转回。 | F22: 项目组自行填写底稿索引 | G22: 否 | H22: 本期无减值迹象

Sheet K.00 Lead Sheet
B1: 标准工作底稿: K1 SWP 不动产、厂房和设备及相关账户（PPE）
B2: 客户名称 | C2: B医疗公司 | D2: 此工作底稿需要与以下 Canvas PSP guided workflow forms一起使用： •K.00 PPE引导表 •K.01 将明细账与总账核对一致 •K.02 增加和处置 •K.03 折旧、损耗和摊销 •K.04 固定资产减值 •账户结论
B3: 期末 | C3: 46022
B4: 分析日期 | C4: 46022
B5: 可容忍误差（TE） | C5: 213730
B6: 名义金额（SAD） | C6: 38900
B7: 适用会计准则（GAAP） | C7: 企业会计准则
B8: 记账本位币 | C8: CNY
B9: K.00 编制引导表并比较余额
B11: 返回汇总页
D13: Threshold(s) | J13: 安永标记
B14: 认定 | C14: CRA | D14: 各项认定1 | E14: 所有相关认定 2 | H14: TB | I14: 已与科目余额表核对无误
B15: 完整性（C） | C15: Minimal | D15: =IF(C15="Minimal",$C$5*100%,IF(C15="Low",$C$5*75%,IF(C15="Moderate",$C$5*50%,IF(C15="High",$C$5*25%,IF(C15="N/A","-",))))) -> 213730 | E15: =MIN($D$15:$D$19) -> 160297.5 | H15: PY | I15: 与上年最终审定数核对一致
B16: 存在性/发生 (E/O) | C16: Minimal | D16: =IF(C16="Minimal",$C$5*100%,IF(C16="Low",$C$5*75%,IF(C16="Moderate",$C$5*50%,IF(C16="High",$C$5*25%,IF(C16="N/A","-",))))) -> 213730 | H16: A3 | I16: 与未审数、审定数核对一致
B17: 计价/计量（V/M） | C17: Low | D17: =IF(C17="Minimal",$C$5*100%,IF(C17="Low",$C$5*75%,IF(C17="Moderate",$C$5*50%,IF(C17="High",$C$5*25%,IF(C17="N/A","-",))))) -> 160297.5 | H17: A5 | I17: 与审计调整核对一致
B18: 权利和义务（R&O） | C18: Minimal | D18: =IF(C18="Minimal",$C$5*100%,IF(C18="Low",$C$5*75%,IF(C18="Moderate",$C$5*50%,IF(C18="High",$C$5*25%,IF(C18="N/A","-",))))) -> 213730 | H18: FS | I18: 与FS.0x与财务报表核对无误
B19: 列报和披露（P&D） | C19: Minimal | D19: =IF(C19="Minimal",$C$5*100%,IF(C19="Low",$C$5*75%,IF(C19="Moderate",$C$5*50%,IF(C19="High",$C$5*25%,IF(C19="N/A","-",))))) -> 213730 | H19: w | I19: 低于SAD的金额——放弃进一步调查
B20: 1 各项认定的测试阈值，是根据EY GAM SUBSTANTIVE DESIGN 2.2.1 | H20: Rx | I20: 重新计算，无异常
B21: 中的示例测试阈值（用占TE的百分比表示）在相应风险等级（CRA）区间的上限计算得出的。 | H21: m | I21: 余额/活动不符合测试范围–无需进一步调查
B22: 除负债/费用类别账户的完整性认定应当使用负债/费用账户表之外，其他类别账户和认定均可使用资产/收入账户表。 | H22: SL | I22: 已与明细账核对无误
B23: 2 所有相关认定的测试阈值，是所有有效认定对应之测试阈值的最小值。我们在
B24: Lead中使用该测试阈值：（a）作为选取总账账户进行测试的起点；（b）作为（需要进一步调查的）金额波动范围的起点。
B26: 在下文中描述我们对固定资产在此期间的相关账户余额和相关波动的预期，以及我们对这些预期的依据和理由。
B27: 账户变更 | C27: 预期及额外考虑
B28: 新增 | C28: 被审计单位为了满足不断增长的客户需求，购买新的设备和生产用具等资产，以取代已折旧和处置的资产和/或维护资本支出支持其现有的生产经营活动；因此，我们预计本期固定资产的原值将存在新增的变动。
B29: 减少 | C29: 随着公司处置在使用寿命(3-5年)内已完全折旧的工具和设备，公司将对部分已报废资产进行处置。因此，我们预计本期固定资产的原值将存在处置的变动。
B30: 在建工程转入（如适用） | C30: 上年购买的需要安装的固定资产预计本期达到使用状态而转固。
B31: 转让、外汇和其他调整 | C31: 被审计单位本期不涉及其他资产的转让、外汇业务等事项。
B32: 折旧方法 | C32: 直线法，我们预计本年较上年无变化。
B33: 折旧费用 | C33: 因为被审计单位折旧方法和使用寿命没有变化，将与往年一样正常计提折旧；同时，本年新增的机器设备将在全年投入使用，且无重大处置资产。因此，我们预计本年度累计折旧较上年增加。
B34: 使用寿命变化 | C34: 由于本年度被审计单位的折旧政策未发生变化，我们预计被审计单位固定资产的使用寿命也不会发生变化。
B37: 波动范围
B38: ="波动幅度 ("&C8&"):" -> 波动幅度 (CNY): | C38: =$E$15 -> 160297.5
B39: 波动幅度 (%): | C39: 0.1
B41: 我们获取或编制了与上期对比的重大账户（固定资产）引导表。我们将本期余额与试算平衡表核对一致，并将上期余额与上期审定数核对一致（如适用）。
B42: 我们将期末余额与上期余额进行对比。调查超出测试阈值（金额和百分比）的波动，以及代表异常或预期外变动或未发生预期中变动的波动，并确定其对我们计划实质性程序的影响 (如有)。
E45: |------- TB -------| | J45: |------- PY -------|
E46: ="货币/单位: "&C8 -> 货币/单位: CNY
E47: =$C$3 -> 46022 | J47: =DATE(YEAR($C$3)-1,12,31) -> 45657 | K47: 本期和上期期末余额 | N47: 基于波动幅度判断，是否进一步调查？ | O47: 基于定性考虑判断，是否进一步调查？
B48: 总账科目编码 | C48: 科目名称 | D48: 索引号 | E48: 期末账面数 | F48: 账表调整数 | G48: 期末未审数 | H48: 审计调整数 | I48: 期末审定数 | J48: 上期末审定数 | K48: 变动金额 | L48: 变动% | M48: Notes
...

Sheet K.01 Agree SL to GL
B1: 标准工作底稿: K1 SWP 不动产、厂房和设备及相关账户（PPE）
B2: K.01 将明细账与总账核对一致
B4: 返回汇总页
B6: 获取上期末至本期末（或中期，如适用）固定资产及相关新增、处置、转让和折旧的后推明细表。（原值、累计折旧、减值均为正数填列，本期减少以负数填列，账表调整、审计调整数据均直接链接至K.00 Lead。）
B7: 我们将期初固定资产余额与上期审定数核对一致，将期末固定资产余额与固定资产明细账和试算表核对一致。我们调查了大于SAD的差异。我们将利润表金额（如，折旧费用）与试算表核对一致（如适用）。
B8: 我们选择了超过测试阈值的后推活动（如，新增、处置、固定资产转入、转移和折旧费用），以执行K.02和K.03的实质性程序。对于未包含在本程序表范围内的程序，我们交叉索引至完成该程序的单独程序表。我们评估了固定资产的转移和其他调整，以了解调整的性质，并确定是否需要执行额外程序。
B9: 表1 | Z9: |--------------------------- Rx ------------------------------|
D10: 固定资产类别 | F10: 办公设备 | I10: 电子设备 | L10: 仪器设备 | O10: 其他设备 | R10: 运输工具 | U10: 【…】 | X10: 【…】 | AA10: 合计
E11: 账面数 | F11: 账表调整/审计调整 | G11: 审定数 | H11: 账面数 | I11: 账表调整/审计调整 | J11: 审定数 | K11: 账面数 | L11: 账表调整/审计调整 | M11: 审定数 | N11: 账面数 | O11: 账表调整/审计调整 | P11: 审定数 | Q11: 账面数 | R11: 账表调整/审计调整 | S11: 审定数 | T11: 账面数 | U11: 账表调整/审计调整 | V11: 审定数 | W11: 账面数 | X11: 账表调整/审计调整 | Y11: 审定数 | Z11: 账面数 | AA11: 账表调整/审计调整 | AB11: 审定数 | AC11: CHECK
C12: 年初余额 | D12: PY | E12: 899364.01 | F12: 0 | G12: =SUM(E12:F12) -> 899364.01 | H12: 938864.49 | I12: 0 | J12: =SUM(H12:I12) -> 938864.49 | K12: 13882261 | L12: 0 | M12: =SUM(K12:L12) -> 13882261 | N12: 320088.5 | O12: 0 | P12: =SUM(N12:O12) -> 320088.5 | Q12: 1293363.6 | R12: 0 | S12: =SUM(Q12:R12) -> 1293363.6 | V12: =SUM(T12:U12) -> 0 | Y12: =SUM(W12:X12) -> 0 | Z12: =SUM(E12,H12,K12,N12,Q12,T12,W12) -> 17333942 | AA12: =SUM(F12,I12,L12,O12,R12,U12,X12) -> 0 | AB12: =SUM(G12,J12,M12,P12,S12,V12,Y12) -> 17333942 | AC12: =AB12-'K.00 Lead Sheet'!J49 -> 0
C13: 购置 | D13: K.02.1 | E13: =SUMIFS(新增清单!$K:$K,新增清单!$B:$B,'K.01 Agree SL to GL'!F10) -> 0 | G13: =SUM(E13:F13) -> 0 | H13: =SUMIFS(新增清单!$K:$K,新增清单!$B:$B,'K.01 Agree SL to GL'!I10) -> 25746.67 | J13: =SUM(H13:I13) -> 25746.67 | K13: =SUMIFS(新增清单!$K:$K,新增清单!$B:$B,'K.01 Agree SL to GL'!L10) -> 774300 | M13: =SUM(K13:L13) -> 774300 | N13: =SUMIFS(新增清单!$K:$K,新增清单!$B:$B,'K.01 Agree SL to GL'!O10) -> 6500 | P13: =SUM(N13:O13) -> 6500 | Q13: =SUMIFS(新增清单!$K:$K,新增清单!$B:$B,'K.01 Agree SL to GL'!R10) -> 60000 | S13: =SUM(Q13:R13) -> 60000 | V13: =SUM(T13:U13) -> 0 | Y13: =SUM(W13:X13) -> 0 | Z13: =SUM(E13,H13,K13,N13,Q13,T13,W13) -> 866546.67 | AA13: =SUM(F13,I13,L13,O13,R13,U13,X13) -> 0 | AB13: =SUM(G13,J13,M13,P13,S13,V13,Y13) -> 866546.67
C14: 在建工程转入 | D14: J1.02 | E14: 0 | G14: =SUM(E14:F14) -> 0 | H14: 0 | J14: =SUM(H14:I14) -> 0 | K14: 0 | M14: =SUM(K14:L14) -> 0 | N14: 0 | P14: =SUM(N14:O14) -> 0 | Q14: 0 | S14: =SUM(Q14:R14) -> 0 | V14: =SUM(T14:U14) -> 0 | Y14: =SUM(W14:X14) -> 0 | Z14: =SUM(E14,H14,K14,N14,Q14,T14,W14) -> 0 | AA14: =SUM(F14,I14,L14,O14,R14,U14,X14) -> 0 | AB14: =SUM(G14,J14,M14,P14,S14,V14,Y14) -> 0
B15: 原值 | C15: 处置或报废 | D15: K.02.2 | E15: 0 | G15: =SUM(E15:F15) -> 0 | H15: 0 | J15: =SUM(H15:I15) -> 0 | K15: -159633 | M15: =SUM(K15:L15) -> -159633 | N15: 0 | P15: =SUM(N15:O15) -> 0 | Q15: 0 | S15: =SUM(Q15:R15) -> 0 | V15: =SUM(T15:U15) -> 0 | Y15: =SUM(W15:X15) -> 0 | Z15: =SUM(E15,H15,K15,N15,Q15,T15,W15) -> -159633 | AA15: =SUM(F15,I15,L15,O15,R15,U15,X15) -> 0 | AB15: =SUM(G15,J15,M15,P15,S15,V15,Y15) -> -159633
C16: 内部重分类 | E16: 0 | G16: =SUM(E16:F16) -> 0 | H16: 0 | J16: =SUM(H16:I16) -> 0 | K16: 0 | M16: =SUM(K16:L16) -> 0 | N16: 0 | P16: =SUM(N16:O16) -> 0 | Q16: 0 | S16: =SUM(Q16:R16) -> 0 | V16: =SUM(T16:U16) -> 0 | Y16: =SUM(W16:X16) -> 0 | Z16: =SUM(E16,H16,K16,N16,Q16,T16,W16) -> 0 | AA16: =SUM(F16,I16,L16,O16,R16,U16,X16) -> 0 | AB16: =SUM(G16,J16,M16,P16,S16,V16,Y16) -> 0
C17: […] | E17: 0 | G17: =SUM(E17:F17) -> 0 | H17: 0 | J17: =SUM(H17:I17) -> 0 | K17: 0 | M17: =SUM(K17:L17) -> 0 | N17: 0 | P17: =SUM(N17:O17) -> 0 | Q17: 0 | S17: =SUM(Q17:R17) -> 0 | V17: =SUM(T17:U17) -> 0 | Y17: =SUM(W17:X17) -> 0 | Z17: =SUM(E17,H17,K17,N17,Q17,T17,W17) -> 0 | AA17: =SUM(F17,I17,L17,O17,R17,U17,X17) -> 0 | AB17: =SUM(G17,J17,M17,P17,S17,V17,Y17) -> 0
C18: 年末余额 | D18: Rx | E18: =E12+E13+E14+E15+E16+E17 -> 899364.01 | F18: =F12+F13+F14+F15+F16+F17 -> 0 | G18: =G12+G13+G14+G15+G16+G17 -> 899364.01 | H18: =H12+H13+H14+H15+H16+H17 -> 964611.16 | I18: =I12+I13+I14+I15+I16+I17 -> 0 | J18: =J12+J13+J14+J15+J16+J17 -> 964611.16 | K18: =K12+K13+K14+K15+K16+K17 -> 14496928 | L18: =L12+L13+L14+L15+L16+L17 -> 0 | ... AB18: =AB12+AB13+AB14+AB15+AB16+AB17 -> 18040855 | AC18: =AB18-'K.00 Lead Sheet'!I49 -> 200000
C19: 年初余额 | D19: PY | E19: 697552.19 | F19: 96280.484 | G19: =SUM(E19:F19) -> 793832.67 | H19: 595604.84 | I19: -1830.9517 | J19: =SUM(H19:I19) -> 593773.89 | K19: 9626407.2 | L19: -32942.688 | M19: =SUM(K19:L19) -> 9593464.6 | N19: 288875.61 | O19: -2150.8306 | P19: =SUM(N19:O19) -> 286724.78 | Q19: 1051307.2 | R19: -0.076364583 | S19: =SUM(Q19:R19) -> 1051307.1 | V19: =SUM(T19:U19) -> 0 | Y19: =SUM(W19:X19) -> 0 | Z19: =SUM(E19,H19,K19,N19,Q19,T19,W19) -> 12259747 | AA19: =SUM(F19,I19,L19,O19,R19,U19,X19) -> 59355.938 | AB19: =SUM(G19,J19,M19,P19,S19,V19,Y19) -> 12319103 | AC19: =AB19-'K.00 Lead Sheet'!J50 -> 0
C20: 计提 | D20: K.03.2 | E20: =SUMIFS('K.01.1a FA list'!$K$17:$K$330,'K.01.1a FA list'!$C$17:$C$330,'K.01 Agree SL to GL'!F10) -> 68138.69 | G20: =SUM(E20:F20) -> 68138.69 | H20: =SUMIFS('K.01.1a FA list'!$K$17:$K$330,'K.01.1a FA list'!$C$17:$C$330,'K.01 Agree SL to GL'!I10) -> 182580.15 | J20: =SUM(H20:I20) -> 182580.15 | K20: =SUMIFS('K.01.1a FA list'!$K$17:$K$330,'K.01.1a FA list'!$C$17:$C$330,'K.01 Agree SL to GL'!L10) -> 1548955.8 | M20: =SUM(K20:L20) -> 1548955.8 | N20: =SUMIFS('K.01.1a FA list'!$K$17:$K$330,'K.01.1a FA list'!$C$17:$C$330,'K.01 Agree SL to GL'!O10) -> 18731.5 | P20: =SUM(N20:O20) -> 18731.5 | Q20: =SUMIFS('K.01.1a FA list'!$K$17:$K$330,'K.01.1a FA list'!$C$17:$C$330,'K.01 Agree SL to GL'!R10) -> 116461.38 | S20: =SUM(Q20:R20) -> 116461.38 | V20: =SUM(T20:U20) -> 0 | Y20: =SUM(W20:X20) -> 0 | Z20: =SUM(E20,H20,K20,N20,Q20,T20,W20) -> 1934867.5 | AA20: =SUM(F20,I20,L20,O20,R20,U20,X20) -> 0 | AB20: =SUM(G20,J20,M20,P20,S20,V20,Y20) -> 1934867.5 | AC20: <K.03 折旧测试>
B21: 累计折旧 | C21: 处置或报废 | D21: K.02.2 | E21: 0 | G21: =SUM(E21:F21) -> 0 | H21: 0 | J21: =SUM(H21:I21) -> 0 | K21: -86185.34 | M21: =SUM(K21:L21) -> -86185.34 | N21: 0 | P21: =SUM(N21:O21) -> 0 | Q21: 0 | S21: =SUM(Q21:R21) -> 0 | V21: =SUM(T21:U21) -> 0 | Y21: =SUM(W21:X21) -> 0 | Z21: =SUM(E21,H21,K21,N21,Q21,T21,W21) -> -86185.34 | AA21: =SUM(F21,I21,L21,O21,R21,U21,X21) -> 0 | AB21: =SUM(G21,J21,M21,P21,S21,V21,Y21) -> -86185.34
C22: 内部重分类 | E22: 0 | G22: =SUM(E22:F22) -> 0 | H22: 0 | J22: =SUM(H22:I22) -> 0 | K22: 0 | M22: =SUM(K22:L22) -> 0 | N22: 0 | P22: =SUM(N22:O22) -> 0 | Q22: 0 | S22: =SUM(Q22:R22) -> 0 | V22: =SUM(T22:U22) -> 0 | Y22: =SUM(W22:X22) -> 0 | Z22: =SUM(E22,H22,K22,N22,Q22,T22,W22) -> 0 | AA22: =SUM(F22,I22,L22,O22,R22,U22,X22) -> 0 | AB22: =SUM(G22,J22,M22,P22,S22,V22,Y22) -> 0
C23: […] | E23: 0 | G23: =SUM(E23:F23) -> 0 | H23: 0 | J23: =SUM(H23:I23) -> 0 | K23: 0 | M23: =SUM(K23:L23) -> 0 | N23: 0 | P23: =SUM(N23:O23) -> 0 | Q23: 0 | S23: =SUM(Q23:R23) -> 0 | V23: =SUM(T23:U23) -> 0 | Y23: =SUM(W23:X23) -> 0 | Z23: =SUM(E23,H23,K23,N23,Q23,T23,W23) -> 0 | AA23: =SUM(F23,I23,L23,O23,R23,U23,X23) -> 0 | AB23: =SUM(G23,J23,M23,P23,S23,V23,Y23) -> 0
C24: 年末余额 | D24: Rx | E24: =E19+E20+E21+E22+E23 -> 765690.88 | F24: =F19+F20+F21+F22+F23 -> 96280.484 | G24: =G19+G20+G21+G22+G23 -> 861971.36 | H24: =H19+H20+H21+H22+H23 -> 778184.99 | I24: =I19+I20+I21+I22+I23 -> -1830.9517 | J24: =J19+J20+J21+J22+J23 -> 776354.04 | K24: =K19+K20+K21+K22+K23 -> 11089178 | L24: =L19+L20+L21+L22+L23 -> -32942.688 | ... AB24: =AB19+AB20+AB21+AB22+AB23 -> 14167785 | AC24: =AB24-'K.00 Lead Sheet'!I50 -> 0
C25: 年初余额 | D25: PY | E25: 0 | G25: =SUM(E25:F25) -> 0 | H25: 0 | J25: =SUM(H25:I25) -> 0 | K25: 0 | M25: =SUM(K25:L25) -> 0 | N25: 0 | P25: =SUM(N25:O25) -> 0 | Q25: 0 | S25: =SUM(Q25:R25) -> 0 | V25: =SUM(T25:U25) -> 0 | Y25: =SUM(W25:X25) -> 0 | Z25: =SUM(E25,H25,K25,N25,Q25,T25,W25) -> 0 | AA25: =SUM(F25,I25,L25,O25,R25,U25,X25) -> 0 | AB25: =SUM(G25,J25,M25,P25,S25,V25,Y25) -> 0 | AC25: =AB25-'K.00 Lead Sheet'!J51 -> 0
C26: 计提 | D26: SWP 减值 | E26: 0 | G26: =SUM(E26:F26) -> 0 | H26: 0 | J26: =SUM(H26:I26) -> 0 | K26: 0 | M26: =SUM(K26:L26) -> 0 | N26: 0 | P26: =SUM(N26:O26) -> 0 | Q26: 0 | S26: =SUM(Q26:R26) -> 0 | V26: =SUM(T26:U26) -> 0 | Y26: =SUM(W26:X26) -> 0 | Z26: =SUM(E26,H26,K26,N26,Q26,T26,W26) -> 0 | AA26: =SUM(F26,I26,L26,O26,R26,U26,X26) -> 0 | AB26: =SUM(G26,J26,M26,P26,S26,V26,Y26) -> 0
B27: 减值准备 | C27: 处置或报废 | D27: K.02.2 | E27: 0 | G27: =SUM(E27:F27) -> 0 | H27: 0 | J27: =SUM(H27:I27) -> 0 | K27: 0 | M27: =SUM(K27:L27) -> 0 | N27: 0 | P27: =SUM(N27:O27) -> 0 | Q27: 0 | S27: =SUM(Q27:R27) -> 0 | V27: =SUM(T27:U27) -> 0 | Y27: =SUM(W27:X27) -> 0 | Z27: =SUM(E27,H27,K27,N27,Q27,T27,W27) -> 0 | AA27: =SUM(F27,I27,L27,O27,R27,U27,X27) -> 0 | AB27: =SUM(G27,J27,M27,P27,S27,V27,Y27) -> 0
C28: 内部重分类 | E28: 0 | G28: =SUM(E28:F28) -> 0 | H28: 0 | J28: =SUM(H28:I28) -> 0 | K28: 0 | M28: =SUM(K28:L28) -> 0 | N28: 0 | P28: =SUM(N28:O28) -> 0 | Q28: 0 | S28: =SUM(Q28:R28) -> 0 | V28: =SUM(T28:U28) -> 0 | Y28: =SUM(W28:X28) -> 0 | Z28: =SUM(E28,H28,K28,N28,Q28,T28,W28) -> 0 | AA28: =SUM(F28,I28,L28,O28,R28,U28,X28) -> 0 | AB28: =SUM(G28,J28,M28,P28,S28,V28,Y28) -> 0
C29: […] | E29: 0 | G29: =SUM(E29:F29) -> 0 | H29: 0 | J29: =SUM(H29:I29) -> 0 | K29: 0 | M29: =SUM(K29:L29) -> 0 | N29: 0 | P29: =SUM(N29:O29) -> 0 | Q29: 0 | S29: =SUM(Q29:R29) -> 0 | V29: =SUM(T29:U29) -> 0 | Y29: =SUM(W29:X29) -> 0 | Z29: =SUM(E29,H29,K29,N29,Q29,T29,W29) -> 0 | AA29: =SUM(F29,I29,L29,O29,R29,U29,X29) -> 0 | AB29: =SUM(G29,J29,M29,P29,S29,V29,Y29) -> 0
C30: 年末余额 | D30: Rx | E30: =E25+E26+E27+E28+E29 -> 0 | F30: =F25+F26+F27+F28+F29 -> 0 | G30: =G25+G26+G27+G28+G29 -> 0 | H30: =H25+H26+H27+H28+H29 -> 0 | I30: =I25+I26+I27+I28+I29 -> 0 | J30: =J25+J26+J27+J28+J29 -> 0 | K30: =K25+K26+K27+K28+K29 -> 0 | L30: =L25+L26+L27+L28+L29 -> 0 | ... AB30: =AB25+AB26+AB27+AB28+AB29 -> 0 | AC30: =AB30-'K.00 Lead Sheet'!I51 -> 0
B31: 净值 (NBV) | C31: 年初余额 | D31: Rx | E31: =E12-E19-E25 -> 201811.82 | F31: =F12-F19-F25 -> -96280.484 | G31: =G12-G19-G25 -> 105531.34 | H31: =H12-H19-H25 -> 343259.65 | I31: =I12-I19-I25 -> 1830.9517 | J31: =J12-J19-J25 -> 345090.6 | K31: =K12-K19-K25 -> 4255853.8 | L31: =L12-L19-L25 -> 32942.688 | ... AB31: =AB12-AB19-AB25 -> 5014838.7 | AC31: =AB31-'K.00 Lead Sheet'!J55 -> 0
C32: 年末余额 | D32: Rx | E32: =E18-E24-E30 -> 133673.13 | F32: =F18-F24-F30 -> -96280.484 | G32: =G18-G24-G30 -> 37392.646 | H32: =H18-H24-H30 -> 186426.17 | I32: =I18-I24-I30 -> 1830.9517 | J32: =J18-J24-J30 -> 188257.12 | K32: =K18-K24-K30 -> 3407750.3 | L32: =L18-L24-L30 -> 32942.688 | ... AB32: =AB18-AB24-AB30 -> 3873070.1 | AC32: =AB32-'K.00 Lead Sheet'!I55 -> 0
B33: 变动 | C33: 原值变动金额 | D33: 本年VS上年 | E33: =E18-E12 -> 0 | G33: =G18-G12 -> 0 | H33: =H18-H12 -> 25746.67 | J33: =J18-J12 -> 25746.67 | K33: =K18-K12 -> 614667 | M33: =M18-M12 -> 614667 | N33: =N18-N12 -> 6500 | P33: =P18-P12 -> 6500 | Q33: =Q18-Q12 -> 60000 | S33: =S18-S12 -> 60000 | T33: =T18-T12 -> 0 | V33: =V18-V12 -> 0 | W33: =W18-W12 -> 0 | Y33: =Y18-Y12 -> 0 | Z33: =Z18-Z12 -> 706913.67 | AA33: =AA18-AA12 -> 0 | AB33: =AB18-AB12 -> 706913.67
C34: 原值变动比例 | D34: % | E34: =IFERROR(E33/E12,1) -> 0 | G34: =IFERROR(G33/G12,1) -> 0 | H34: =IFERROR(H33/H12,1) -> 0.027423201 | J34: =IFERROR(J33/J12,1) -> 0.027423201 | K34: =IFERROR(K33/K12,1) -> 0.044277153 | M34: =IFERROR(M33/M12,1) -> 0.044277153 | N34: =IFERROR(N33/N12,1) -> 0.020306884 | P34: =IFERROR(P33/P12,1) -> 0.020306884 | Q34: =IFERROR(Q33/Q12,1) -> 0.046390666 | S34: =IFERROR(S33/S12,1) -> 0.046390666 | T34: =IFERROR(T33/T12,1) -> 1 | V34: =IFERROR(V33/V12,1) -> 1 | W34: =IFERROR(W33/W12,1) -> 1 | Y34: =IFERROR(Y33/Y12,1) -> 1 | Z34: =IFERROR(Z33/Z12,1) -> 0.04078205 | AA34: =IFERROR(AA33/AA12,1) -> 1 | AB34: =IFERROR(AB33/AB12,1) -> 0.04078205
C35: 累计折旧变动金额 | D35: 本年VS上年 | E35: =E24-E19 -> 68138.69 | G35: =G24-G19 -> 68138.69 | H35: =H24-H19 -> 182580.15 | J35: =J24-J19 -> 182580.15 | K35: =K24-K19 -> 1462770.5 | M35: =M24-M19 -> 1462770.5 | N35: =N24-N19 -> 18731.5 | P35: =P24-P19 -> 18731.5 | Q35: =Q24-Q19 -> 116461.38 | S35: =S24-S19 -> 116461.38 | T35: =T24-T19 -> 0 | V35: =V24-V19 -> 0 | W35: =W24-W19 -> 0 | Y35: =Y24-Y19 -> 0 | Z35: =Z24-Z19 -> 1848682.2 | AA35: =AA24-AA19 -> 0 | AB35: =AB24-AB19 -> 1848682.2
C36: 累计折旧变动比例 | D36: % | E36: =IFERROR(E35/E19,1) -> 0.097682569 | G36: =IFERROR(G35/G19,1) -> 0.085835079 | H36: =IFERROR(H35/H19,1) -> 0.30654578 | J36: =IFERROR(J35/J19,1) -> 0.30749104 | K36: =IFERROR(K35/K19,1) -> 0.15195394 | M36: =IFERROR(M35/M19,1) -> 0.15247573 | N36: =IFERROR(N35/N19,1) -> 0.064842788 | P36: =IFERROR(P35/P19,1) -> 0.065329198 | Q36: =IFERROR(Q35/Q19,1) -> 0.11077769 | S36: =IFERROR(S35/S19,1) -> 0.1107777 | T36: =IFERROR(T35/T19,1) -> 1 | V36: =IFERROR(V35/V19,1) -> 1 | W36: =IFERROR(W35/W19,1) -> 1 | Y36: =IFERROR(Y35/Y19,1) -> 1 | Z36: =IFERROR(Z35/Z19,1) -> 0.15079285 | AA36: =IFERROR(AA35/AA19,1) -> 0 | AB36: =IFERROR(AB35/AB19,1) -> 0.1500663
C37: 减值准备变动金额 | D37: 本年VS上年 | E37: =E30-E25 -> 0 | G37: =G30-G25 -> 0 | H37: =H30-H25 -> 0 | J37: =J30-J25 -> 0 | K37: =K30-K25 -> 0 | M37: =M30-M25 -> 0 | N37: =N30-N25 -> 0 | P37: =P30-P25 -> 0 | Q37: =Q30-Q25 -> 0 | S37: =S30-S25 -> 0 | T37: =T30-T25 -> 0 | V37: =V30-V25 -> 0 | W37: =W30-W25 -> 0 | Y37: =Y30-Y25 -> 0 | Z37: =Z30-Z25 -> 0 | AA37: =AA30-AA25 -> 0 | AB37: =AB30-AB25 -> 0
C38: 减值准备变动比例 | D38: % | E38: =IFERROR(E37/E25,1) -> 1 | G38: =IFERROR(G37/G25,1) -> 1 | H38: =IFERROR(H37/H25,1) -> 1 | J38: =IFERROR(J37/J25,1) -> 1 | K38: =IFERROR(K37/K25,1) -> 1 | M38: =IFERROR(M37/M25,1) -> 1 | N38: =IFERROR(N37/N25,1) -> 1 | P38: =IFERROR(P37/P25,1) -> 1 | Q38: =IFERROR(Q37/Q25,1) -> 1 | S38: =IFERROR(S37/S25,1) -> 1 | T38: =IFERROR(T37/T25,1) -> 1 | V38: =IFERROR(V37/V25,1) -> 1 | W38: =IFERROR(W37/W25,1) -> 1 | Y38: =IFERROR(Y37/Y25,1) -> 1 | Z38: =IFERROR(Z37/Z25,1) -> 1 | AA38: =IFERROR(AA37/AA25,1) -> 1 | AB38: =IFERROR(AB37/AB25,1) -> 1
C39: 净值变动金额 | D39: 本年VS上年 | E39: =E32-E31 -> -68138.69 | G39: =G32-G31 -> -68138.69 | H39: =H32-H31 -> -156833.48 | J39: =J32-J31 -> -156833.48 | K39: =K32-K31 -> -848103.48 | M39: =M32-M31 -> -848103.48 | N39: =N32-N31 -> -12231.5 | P39: =P32-P31 -> -12231.5 | Q39: =Q32-Q31 -> -56461.38 | S39: =S32-S31 -> -56461.38 | T39: =T32-T31 -> 0 | V39: =V32-V31 -> 0 | W39: =W32-W31 -> 0 | Y39: =Y32-Y31 -> 0 | Z39: =Z32-Z31 -> -1141768.5 | AA39: =AA32-AA31 -> 0 | AB39: =AB32-AB31 -> -1141768.5
C40: 净值变动比例 | D40: % | E40: =IFERROR(E39/E31,1) -> -0.33763478 | G40: =IFERROR(G39/G31,1) -> -0.64567258 | H40: =IFERROR(H39/H31,1) -> -0.4568946 | J40: =IFERROR(J39/J31,1) -> -0.45447045 | K40: =IFERROR(K39/K31,1) -> -0.19927928 | M40: =IFERROR(M39/M31,1) -> -0.1977486 | N40: =IFERROR(N39/N31,1) -> -0.39187336 | P40: =IFERROR(P39/P31,1) -> -0.36661079 | Q40: =IFERROR(Q39/Q31,1) -> -0.23325707 | S40: =IFERROR(S39/S31,1) -> -0.23325699 | T40: =IFERROR(T39/T31,1) -> 1 | V40: =IFERROR(V39/V31,1) -> 1 | W40: =IFERROR(W39/W31,1) -> 1 | Y40: =IFERROR(Y39/Y31,1) -> 1 | Z40: =IFERROR(Z39/Z31,1) -> -0.22501473 | AA40: =IFERROR(AA39/AA31,1) -> 0 | AB40: =IFERROR(AB39/AB31,1) -> -0.22767802
B42: TB-原值 | E42: =899364.01-200000 -> 699364.01 | H42: 964611.16 | K42: 14496928 | N42: 326588.5 | Q42: 1353363.6 | Z42: =SUM(E42,H42,K42,N42,Q42,T42,W42) -> 17840855
B43: 差异 | E43: =E18-E42 -> 200000 | H43: =H18-H42 -> 0 | K43: =K18-K42 -> 0 | N43: =N18-N42 -> 0 | Q43: =Q18-Q42 -> 0 | T43: =T18-T42 -> 0 | W43: =W18-W42 -> 0 | Z43: =Z18-Z42 -> 200000
...

Sheet K.01.1a FA list
O2: 返回汇总页
T4: 汇总 | Y4: check with BKD
R5: 固定资产类别 | S5: 原值 | T5: 累计折旧 | U5: 减值准备 | V5: 净值 | X5: 原值 | Y5: 累计折旧 | Z5: 减值准备 | AA5: 净值
R6: ='[7]K.01.1 BKD'!G17 -> 办公设备 | S6: =SUMIF($C$16:$C$335,$R6,L$16:L$335) -> 899364.01 | T6: =SUMIF($C$16:$C$335,$R6,M$16:M$335) -> 765690.88 | U6: =SUMIF($C$16:$C$335,$R6,N$16:N$335) -> 0 | V6: =SUMIF($C$16:$C$335,$R6,O$16:O$335) -> 133673.13 | X6: =S6-'K.01 Agree SL to GL'!E18 -> 0 | Y6: =T6-'K.01 Agree SL to GL'!E24 -> 0 | Z6: =U6-'[7]K.01.1 BKD'!F37 -> 0 | AA6: =V6-'K.01 Agree SL to GL'!E32 -> 0
R7: ='[7]K.01.1 BKD'!J17 -> 电子设备 | S7: =SUMIF($C$16:$C$335,$R7,L$16:L$335) -> 964611.16 | T7: =SUMIF($C$16:$C$335,$R7,M$16:M$335) -> 778184.99 | U7: =SUMIF($C$16:$C$335,$R7,N$16:N$335) -> 0 | V7: =SUMIF($C$16:$C$335,$R7,O$16:O$335) -> 186426.17 | X7: =S7-'K.01 Agree SL to GL'!H18 -> 0 | Y7: =T7-'K.01 Agree SL to GL'!H24 -> 0 | Z7: =U7-'[7]K.01.1 BKD'!I37 -> 0 | AA7: =V7-'K.01 Agree SL to GL'!H32 -> -2.6193447e-10
R8: ='[7]K.01.1 BKD'!M17 -> 仪器设备 | S8: =SUMIF($C$16:$C$335,$R8,L$16:L$335) -> 14496928 | T8: =SUMIF($C$16:$C$335,$R8,M$16:M$335) -> 11175363 | U8: =SUMIF($C$16:$C$335,$R8,N$16:N$335) -> 0 | V8: =SUMIF($C$16:$C$335,$R8,O$16:O$335) -> 3407750.3 | X8: =S8-'K.01 Agree SL to GL'!K18 -> 0 | Y8: 0 | Z8: =U8-'[7]K.01.1 BKD'!L37 -> 0 | AA8: =V8-'K.01 Agree SL to GL'!K32 -> 0
R9: ='[7]K.01.1 BKD'!P17 -> 其他设备 | S9: =SUMIF($C$16:$C$335,$R9,L$16:L$335) -> 326588.5 | T9: =SUMIF($C$16:$C$335,$R9,M$16:M$335) -> 307607.11 | U9: =SUMIF($C$16:$C$335,$R9,N$16:N$335) -> 0 | V9: =SUMIF($C$16:$C$335,$R9,O$16:O$335) -> 18981.39 | X9: =S9-'K.01 Agree SL to GL'!N18 -> 0 | Y9: =T9-'K.01 Agree SL to GL'!N24 -> 0 | Z9: =U9-'[7]K.01.1 BKD'!O37 -> 0 | AA9: =V9-'K.01 Agree SL to GL'!N32 -> 0
R10: ='[7]K.01.1 BKD'!S17 -> 运输工具 | S10: =SUMIF($C$16:$C$335,$R10,L$16:L$335) -> 1353363.6 | T10: =SUMIF($C$16:$C$335,$R10,M$16:M$335) -> 1167768.6 | U10: =SUMIF($C$16:$C$335,$R10,N$16:N$335) -> 0 | V10: =SUMIF($C$16:$C$335,$R10,O$16:O$335) -> 185595.08 | X10: =S10-'K.01 Agree SL to GL'!Q18 -> 0 | Y10: =T10-'K.01 Agree SL to GL'!Q24 -> 0 | Z10: =U10-'[7]K.01.1 BKD'!R37 -> 0 | AA10: =V10-'K.01 Agree SL to GL'!Q32 -> 0
C11: 3.不要"硬塞"及"自创" 固定资产类别：固定资产类别按照被审计单位自己的分类列示，此处仅为举例，如无特殊情况，避免将对审计单位某一类别的固定资产中的部分资产进行类别调整。 | R11: 合计 | S11: =SUM(S6:S10) -> 18040855 | T11: =SUM(T6:T10) -> 14194615 | U11: =SUM(U6:U10) -> 0 | V11: =SUM(V6:V10) -> 3932426.1
S12: Rx | T12: Rx | U12: Rx | V12: Rx
C14: |-----------------------------------------------------------------------------------必需字段*--------------------------------------------------------------------------------------------------------------------------------------------------|
B15: 表1 | C15: 固定资产明细清单
C16: 固定资产类别 | D16: 固定资产编号 | E16: 固定资产名称 | F16: 入账开始日期 | G16: 使用寿命(月) | H16: 残值率 | I16: 期初原值 | J16: 期初累计折旧 | K16: 本期计提折旧 | L16: 期末原值 | M16: 期末累计折旧 | N16: 减值准备 | O16: 净值 | P16: 已提足折旧
C17: 办公设备 | D17: 01-02-0063 | E17: 白色储物柜置物架 | F17: 2019-11-30 | G17: 60 | H17: 0.05 | I17: 7360 | J17: =_xlfn.XLOOKUP(D17,'[7]K.01.1a FA list'!$D$22:$D$348,'[7]K.01.1a FA list'!$M$22:$M$348) -> 6992 | K17: =M17-J17 -> 0 | L17: 7360 | M17: =_xlfn.XLOOKUP(D17,[8]新增资产!$C:$C,[8]新增资产!$L:$L) -> 6992 | N17: 0 | O17: =L17-M17 -> 368 | P17: =IF(ROUND(L17*(1-H17),0)=ROUND(M17,0),"是","否") -> 是
C18: 办公设备 | D18: 01-02-0064 | E18: 白色电脑桌 | F18: 2019-11-30 | G18: 60 | H18: 0.05 | I18: 4060 | J18: =_xlfn.XLOOKUP(D18,'[7]K.01.1a FA list'!$D$22:$D$348,'[7]K.01.1a FA list'!$M$22:$M$348) -> 3857 | K18: =M18-J18 -> 0 | L18: 4060 | M18: =_xlfn.XLOOKUP(D18,[8]新增资产!$C:$C,[8]新增资产!$L:$L) -> 3857 | N18: 0 | O18: =L18-M18 -> 203 | P18: =IF(ROUND(L18*(1-H18),0)=ROUND(M18,0),"是","否") -> 是
C19: 办公设备 | D19: 01-02-0065 | E19: 墨绿色 布艺双人沙发 | F19: 2019-11-30 | G19: 60 | H19: 0.05 | I19: 2790 | J19: =_xlfn.XLOOKUP(D19,'[7]K.01.1a FA list'!$D$22:$D$348,'[7]K.01.1a FA list'!$M$22:$M$348) -> 2650.5 | K19: =M19-J19 -> 0 | L19: 2790 | M19: =_xlfn.XLOOKUP(D19,[8]新增资产!$C:$C,[8]新增资产!$L:$L) -> 2650.5 | N19: 0 | O19: =L19-M19 -> 139.5 | P19: =IF(ROUND(L19*(1-H19),0)=ROUND(M19,0),"是","否") -> 是
C20: 办公设备 | D20: 01-02-0066 | E20: 橱柜 | F20: 2019-11-30 | G20: 60 | H20: 0.05 | I20: 4000 | J20: =_xlfn.XLOOKUP(D20,'[7]K.01.1a FA list'!$D$22:$D$348,'[7]K.01.1a FA list'!$M$22:$M$348) -> 3800 | K20: =M20-J20 -> 0 | L20: 4000 | M20: =_xlfn.XLOOKUP(D20,[8]新增资产!$C:$C,[8]新增资产!$L:$L) -> 3800 | N20: 0 | O20: =L20-M20 -> 200 | P20: =IF(ROUND(L20*(1-H20),0)=ROUND(M20,0),"是","否") -> 是
C21: 办公设备 | D21: 020056 | E21: 办公家具 | F21: 2014-08-01 | G21: 36 | H21: 0.05 | I21: 14170 | J21: =_xlfn.XLOOKUP(D21,'[7]K.01.1a FA list'!$D$22:$D$348,'[7]K.01.1a FA list'!$M$22:$M$348) -> 13603.2 | K21: =M21-J21 -> 0 | L21: 14170 | M21: =_xlfn.XLOOKUP(D21,[8]新增资产!$C:$C,[8]新增资产!$L:$L) -> 13603.2 | N21: 0 | O21: =L21-M21 -> 566.8 | P21: =IF(ROUND(L21*(1-H21),0)=ROUND(M21,0),"是","否") -> 否
C22: 办公设备 | D22: 020057 | E22: 防火门三套 | F22: 2014-09-01 | G22: 36 | H22: 0.05 | I22: 6950 | J22: =_xlfn.XLOOKUP(D22,'[7]K.01.1a FA list'!$D$22:$D$348,'[7]K.01.1a FA list'!$M$22:$M$348) -> 6672 | K22: =M22-J22 -> 0 | L22: 6950 | M22: =_xlfn.XLOOKUP(D22,[8]新增资产!$C:$C,[8]新增资产!$L:$L) -> 6672 | N22: 0 | O22: =L22-M22 -> 278 | P22: =IF(ROUND(L22*(1-H22),0)=ROUND(M22,0),"是","否") -> 否
C23: 办公设备 | D23: 020058 | E23: 鱼缸 | F23: 2014-10-01 | G23: 36 | H23: 0.05 | I23: 16000 | J23: =_xlfn.XLOOKUP(D23,'[7]K.01.1a FA list'!$D$22:$D$348,'[7]K.01.1a FA list'!$M$22:$M$348) -> 15360 | K23: =M23-J23 -> 0 | L23: 16000 | M23: =_xlfn.XLOOKUP(D23,[8]新增资产!$C:$C,[8]新增资产!$L:$L) -> 15360 | N23: 0 | O23: =L23-M23 -> 640 | P23: =IF(ROUND(L23*(1-H23),0)=ROUND(M23,0),"是","否") -> 否
C24: 办公设备 | D24: 020059 | E24: 展示柜 | F24: 2015-08-01 | G24: 36 | H24: 0.05 | I24: 8886 | J24: =_xlfn.XLOOKUP(D24,'[7]K.01.1a FA list'!$D$22:$D$348,'[7]K.01.1a FA list'!$M$22:$M$348) -> 8530.56 | K24: =M24-J24 -> 0 | L24: 8886 | M24: =_xlfn.XLOOKUP(D24,[8]新增资产!$C:$C,[8]新增资产!$L:$L) -> 8530.56 | N24: 0 | O24: =L24-M24 -> 355.44 | P24: =IF(ROUND(L24*(1-H24),0)=ROUND(M24,0),"是","否") -> 否
C25: 办公设备 | D25: 020060 | E25: 输液椅 | F25: 2017-07-01 | G25: 60 | H25: 0.05 | I25: 4400 | J25: =_xlfn.XLOOKUP(D25,'[7]K.01.1a FA list'!$D$22:$D$348,'[7]K.01.1a FA list'!$M$22:$M$348) -> 4224 | K25: =M25-J25 -> 0 | L25: 4400 | M25: =_xlfn.XLOOKUP(D25,[8]新增资产!$C:$C,[8]新增资产!$L:$L) -> 4224 | N25: 0 | O25: =L25-M25 -> 176 | P25: =IF(ROUND(L25*(1-H25),0)=ROUND(M25,0),"是","否") -> 否
C26: 办公设备 | D26: 020061 | E26: 白色更衣柜1组 | F26: 2017-11-01 | G26: 36 | H26: 0.05 | I26: 2400 | J26: =_xlfn.XLOOKUP(D26,'[7]K.01.1a FA list'!$D$22:$D$348,'[7]K.01.1a FA list'!$M$22:$M$348) -> 2280 | K26: =M26-J26 -> 0 | L26: 2400 | M26: =_xlfn.XLOOKUP(D26,[8]新增资产!$C:$C,[8]新增资产!$L:$L) -> 2280 | N26: 0 | O26: =L26-M26 -> 120 | P26: =IF(ROUND(L26*(1-H26),0)=ROUND(M26,0),"是","否") -> 是
C27: 办公设备 | D27: 020062 | E27: 白色更衣柜1组 | F27: 2017-11-01 | G27: 36 | H27: 0.05 | I27: 2600 | J27: =_xlfn.XLOOKUP(D27,'[7]K.01.1a FA list'!$D$22:$D$348,'[7]K.01.1a FA list'!$M$22:$M$348) -> 2470 | K27: =M27-J27 -> 0 | L27: 2600 | M27: =_xlfn.XLOOKUP(D27,[8]新增资产!$C:$C,[8]新增资产!$L:$L) -> 2470 | N27: 0 | O27: =L27-M27 -> 130 | P27: =IF(ROUND(L27*(1-H27),0)=ROUND(M27,0),"是","否") -> 是
C28: 办公设备 | D28: 030001 | E28: 电热水器三台 | F28: 2013-08-01 | G28: 36 | H28: 0.05 | I28: 11992 | J28: =_xlfn.XLOOKUP(D28,'[7]K.01.1a FA list'!$D$22:$D$348,'[7]K.01.1a FA list'!$M$22:$M$348) -> 11512.32 | K28: =M28-J28 -> 0 | L28: 11992 | M28: =_xlfn.XLOOKUP(D28,[8]新增资产!$C:$C,[8]新增资产!$L:$L) -> 11512.32 | N28: 0 | O28: =L28-M28 -> 479.68 | P28: =IF(ROUND(L28*(1-H28),0)=ROUND(M28,0),"是","否") -> 否
... C256: 其他设备 | D256: 01-06-0008 | E256: 咖啡机 | F256: 2022-11-30 | G256: 36 | H256: 0.05000162 | I256: 29000 | J256: =_xlfn.XLOOKUP(D256,'[7]K.01.1a FA list'!$D$22:$D$348,'[7]K.01.1a FA list'!$M$22:$M$348) -> 19132 | K256: =M256-J256 -> 8418 | L256: 29000 | M256: =_xlfn.XLOOKUP(D256,[8]新增资产!$C:$C,[8]新增资产!$L:$L) -> 27550 | N256: 0 | O256: =L256-M256 -> 1450 | P256: =IF(ROUND(L256*(1-H256),0)=ROUND(M256,0),"是","否") -> 是
C257: 运输工具 | D257: 01-07-0001 | E257: 特斯拉纯电动乘用车 | F257: 2020-12-31 | G257: 48 | H257: 0.05 | I257: 848000 | J257: =_xlfn.XLOOKUP(D257,'[7]K.01.1a FA list'!$D$22:$D$348,'[7]K.01.1a FA list'!$M$22:$M$348) -> 805600 | K257: =M257-J257 -> 0 | L257: 848000 | M257: 805600 | N257: 0 | O257: =L257-M257 -> 42400 | P257: =IF(ROUND(L257*(1-H257),0)=ROUND(M257,0),"是","否") -> 是
C258: 运输工具 | D258: 01-07-0002 | E258: 越野乘用车 | F258: 2022-06-08 | G258: 48 | H258: 0.05 | I258: 404223.01 | J258: =_xlfn.XLOOKUP(D258,'[7]K.01.1a FA list'!$D$22:$D$348,'[7]K.01.1a FA list'!$M$22:$M$348) -> 240007.5 | K258: =M258-J258 -> 96003 | L258: 404223.01 | M258: 336010.5 | N258: 0 | O258: =L258-M258 -> 68212.51 | P258: =IF(ROUND(L258*(1-H258),0)=ROUND(M258,0),"是","否") -> 否
C259: 办公设备 | D259: 01-03-0005 | E259: 冰箱 | F259: 2023-08-16 | G259: 36 | H259: 0.05 | I259: 1399 | J259: =_xlfn.XLOOKUP(D259,'[7]K.01.1a FA list'!$D$22:$D$348,'[7]K.01.1a FA list'!$M$22:$M$348) -> 590.72 | K259: =M259-J259 -> 443.04 | L259: 1399 | M259: =_xlfn.XLOOKUP(D259,[8]新增资产!$C:$C,[8]新增资产!$L:$L) -> 1033.76 | N259: 0 | O259: =L259-M259 -> 365.24 | P259: =IF(ROUND(L259*(1-H259),0)=ROUND(M259,0),"是","否") -> 否
C260: 电子设备 | D260: 01-04-0057 | E260: 索尼镜头 | F260: 2023-08-04 | G260: 36 | H260: 0.05 | I260: 5399 | J260: =_xlfn.XLOOKUP(D260,'[7]K.01.1a FA list'!$D$22:$D$348,'[7]K.01.1a FA list'!$M$22:$M$348) -> 2279.52 | K260: =M260-J260 -> 1709.64 | L260: 5399 | M260: =_xlfn.XLOOKUP(D260,[8]新增资产!$C:$C,[8]新增资产!$L:$L) -> 3989.16 | N260: 0 | O260: =L260-M260 -> 1409.84 | P260: =IF(ROUND(L260*(1-H260),0)=ROUND(M260,0),"是","否") -> 否
C261: 电子设备 | D261: 01-04-0058 | E261: 电脑兼容机 | F261: 2023-08-04 | G261: 36 | H261: 0.05 | I261: 13000 | J261: =_xlfn.XLOOKUP(D261,'[7]K.01.1a FA list'!$D$22:$D$348,'[7]K.01.1a FA list'!$M$22:$M$348) -> 5488.96 | K261: =M261-J261 -> 4116.72 | L261: 13000 | M261: =_xlfn.XLOOKUP(D261,[8]新增资产!$C:$C,[8]新增资产!$L:$L) -> 9605.68 | N261: 0 | O261: =L261-M261 -> 3394.32 | P261: =IF(ROUND(L261*(1-H261),0)=ROUND(M261,0),"是","否") -> 否
C262: 电子设备 | D262: 01-04-0059 | E262: 小度添添闺蜜机 | F262: 2023-08-31 | G262: 36 | H262: 0.05 | I262: 5199 | J262: =_xlfn.XLOOKUP(D262,'[7]K.01.1a FA list'!$D$22:$D$348,'[7]K.01.1a FA list'!$M$22:$M$348) -> 2195.2 | K262: =M262-J262 -> 1646.4 | L262: 5199 | M262: =_xlfn.XLOOKUP(D262,[8]新增资产!$C:$C,[8]新增资产!$L:$L) -> 3841.6 | N262: 0 | O262: =L262-M262 -> 1357.4 | P262: =IF(ROUND(L262*(1-H262),0)=ROUND(M262,0),"是","否") -> 否
C263: 电子设备 | D263: 01-04-0060 | E263: 荣耀X50智能手机 | F263: 2023-08-31 | G263: 36 | H263: 0.05 | I263: 1569 | J263: =_xlfn.XLOOKUP(D263,'[7]K.01.1a FA list'!$D$22:$D$348,'[7]K.01.1a FA list'!$M$22:$M$348) -> 662.4 | K263: =M263-J263 -> 496.8 | L263: 1569 | M263: =_xlfn.XLOOKUP(D263,[8]新增资产!$C:$C,[8]新增资产!$L:$L) -> 1159.2 | N263: 0 | O263: =L263-M263 -> 409.8 | P263: =IF(ROUND(L263*(1-H263),0)=ROUND(M263,0),"是","否") -> 否
C264: 电子设备 | D264: 01-04-0061 | E264: 荣耀X50手机 | F264: 2023-09-08 | G264: 36 | H264: 0.05 | I264: 6276 | J264: =_xlfn.XLOOKUP(D264,'[7]K.01.1a FA list'!$D$22:$D$348,'[7]K.01.1a FA list'!$M$22:$M$348) -> 2484.3 | K264: =M264-J264 -> 1987.44 | L264: 6276 | M264: =_xlfn.XLOOKUP(D264,[8]新增资产!$C:$C,[8]新增资产!$L:$L) -> 4471.74 | N264: 0 | O264: =L264-M264 -> 1804.26 | P264: =IF(ROUND(L264*(1-H264),0)=ROUND(M264,0),"是","否") -> 否
C265: 电子设备 | D265: 01-04-0062 | E265: 苹果手机 | F265: 2023-09-19 | G265: 36 | H265: 0.05 | I265: 30000 | J265: =_xlfn.XLOOKUP(D265,'[7]K.01.1a FA list'!$D$22:$D$348,'[7]K.01.1a FA list'!$M$22:$M$348) -> 11875.05 | K265: =M265-J265 -> 9500.04 | L265: 30000 | M265: =_xlfn.XLOOKUP(D265,[8]新增资产!$C:$C,[8]新增资产!$L:$L) -> 21375.09 | N265: 0 | O265: =L265-M265 -> 8624.91 | P265: =IF(ROUND(L265*(1-H265),0)=ROUND(M265,0),"是","否") -> 否
C266: 电子设备 | D266: 01-04-0063 | E266: SONY相机+定焦镜头 | F266: 2023-09-19 | G266: 36 | H266: 0.05 | I266: 86560 | J266: =_xlfn.XLOOKUP(D266,'[7]K.01.1a FA list'!$D$22:$D$348,'[7]K.01.1a FA list'!$M$22:$M$348) -> 34263.3 | K266: =M266-J266 -> 27410.64 | L266: 86560 | M266: =_xlfn.XLOOKUP(D266,[8]新增资产!$C:$C,[8]新增资产!$L:$L) -> 61673.94 | N266: 0 | O266: =L266-M266 -> 24886.06 | P266: =IF(ROUND(L266*(1-H266),0)=ROUND(M266,0),"是","否") -> 否
C267: 电子设备 | D267: 01-04-0064 | E267: 神牛补光灯 | F267: 2023-09-19 | G267: 36 | H267: 0.05 | I267: 29600 | J267: =_xlfn.XLOOKUP(D267,'[7]K.01.1a FA list'!$D$22:$D$348,'[7]K.01.1a FA list'!$M$22:$M$348) -> 11716.65 | K267: =M267-J267 -> 9373.32 | L267: 29600 | M267: =_xlfn.XLOOKUP(D267,[8]新增资产!$C:$C,[8]新增资产!$L:$L) -> 21089.97 | N267: 0 | O267: =L267-M267 -> 8510.03 | P267: =IF(ROUND(L267*(1-H267),0)=ROUND(M267,0),"是","否") -> 否
C268: 电子设备 | D268: 01-04-0065 | E268: 台式电脑含24寸升降显示屏 | F268: 2023-09-19 | G268: 36 | H268: 0.05 | I268: 43534 | J268: =_xlfn.XLOOKUP(D268,'[7]K.01.1a FA list'!$D$22:$D$348,'[7]K.01.1a FA list'!$M$22:$M$348) -> 17232.15 | K268: =M268-J268 -> 13785.72 | L268: 43534 | M268: =_xlfn.XLOOKUP(D268,[8]新增资产!$C:$C,[8]新增资产!$L:$L) -> 31017.87 | N268: 0 | O268: =L268-M268 -> 12516.13 | P268: =IF(ROUND(L268*(1-H268),0)=ROUND(M268,0),"是","否") -> 否
C269: 电子设备 | D269: 01-04-0066 | E269: 小米电视机 | F269: 2023-09-28 | G269: 36 | H269: 0.05 | I269: 3779 | J269: =_xlfn.XLOOKUP(D269,'[7]K.01.1a FA list'!$D$22:$D$348,'[7]K.01.1a FA list'!$M$22:$M$348) -> 1495.8 | K269: =M269-J269 -> 1196.64 | L269: 3779 | M269: =_xlfn.XLOOKUP(D269,[8]新增资产!$C:$C,[8]新增资产!$L:$L) -> 2692.44 | N269: 0 | O269: =L269-M269 -> 1086.56 | P269: =IF(ROUND(L269*(1-H269),0)=ROUND(M269,0),"是","否") -> 否
C270: 电子设备 | D270: 01-04-0067 | E270: 电子计算机整机电脑 | F270: 2023-10-17 | G270: 36 | H270: 0.05 | I270: 17400 | J270: =_xlfn.XLOOKUP(D270,'[7]K.01.1a FA list'!$D$22:$D$348,'[7]K.01.1a FA list'!$M$22:$M$348) -> 6428.38 | K270: =M270-J270 -> 5510.04 | L270: 17400 | M270: =_xlfn.XLOOKUP(D270,[8]新增资产!$C:$C,[8]新增资产!$L:$L) -> 11938.42 | N270: 0 | O270: =L270-M270 -> 5461.58 | P270: =IF(ROUND(L270*(1-H270),0)=ROUND(M270,0),"是","否") -> 否
...

Sheet K.02.1 新增测试 
B1: 标准工作底稿: K1 SWP 不动产、厂房和设备及相关账户（PPE）
B2: K.02.1：详细测试 (新增)
B4: 返回汇总页
B6: 记录我们的详细测试所涵盖的总体（指引：纳入充分的描述，以使经验丰富且之前与该项审计无关的审计师能够理解样本是如何选择的，例如，总体的分类或筛选。）
B7: 我们将本年固定资产购置增加的明细作为测试的样本总体。
B12: 购置总金额 | F12: 866546.67
B13: Breakdown中购置金额 | F13: ='K.01 Agree SL to GL'!Z13 -> 866546.67 | G13: K.01
B14: 差异 | F14: =F12-F13 -> 0 | G14: Rx | H14: 差异是否需要进一步调查？ | J14: =IF(ABS(F14)>'K.00 Lead Sheet'!$C$6,"是","否") -> 否
B16: 减：测试的关键项目 | F16: 380,000.00
B17: 进行代表性抽样的剩余总体 | F17: =F12-F16 -> 486546.67
B19: 在下方描述选择关键项目的理由（请参阅Canvas指导工作流程的“关键项目”部分，包括信息图标）
B20: 1）我们将本年新增样本金额超过固定资产存在认定，计价认定及权利和义务认定的Threshold（人民币241,890元）的样本，设定为关键项；
B21: 2）同时，我们将本年新增样本性质异常的单项资产，设定为关键项；
B22: 3）如果没有充分的关键项以支持我们得出结论，我们将测试延伸至剩余总体中的代表性抽样，选择随机抽样方法确定代表性样本。
B23: 基于对被审计单位和重大交易流程的了解，我们没有确定任何相关的定性标准。我们利用抽样工具评估已获得审计证据的充分性和适当性，按照评估结果，我们计划测试1个关键项样本。
B25: EY 测试属性解释:
B26: 对于每个被选中进行测试的项目，我们检查了相关的第三方证据以及相关的会计分录，并确定：
B27: 1) 测试样本于恰当的日期被正确资本化为固定资产（即，不应该费用化）。
B28: 2) 历史成本已根据适用的财务报告框架进行记录。
B29: 3) 管理层对测试项目采用的使用寿命和折旧方法是适当的（符合实体的会计政策和适用的财务报告框架）。
B30: 4) 该资产已被归入适当的固定资产类别。
N32: |------- Rx -------| | O32: EY Works
B33: 样本类型 | C33: 固定资产类别 | D33: 总账账户代码 | E33: 固定资产编号 | F33: 固定资产名称 | G33: 资产原价 | H33: 资本化日期 | I33: 使用寿命(月) | J33: 残值率 | K33: 折旧方法 | L33: 资产原价（通过审计证据/支持性文件取得） | M33: 获得的证据/支持的描述（例如，我们检查的控制权转移时点的单据/销售发票/合同/订单等） | N33: 资产原价差异 | O33: 1 | P33: 2 | Q33: 3 | R33: 4
B34: 关键项（key item） | C34: 仪器设备 | D34: 1601 | E34: 01-05-0116 | F34: 皮秒Nd:YAG激光治疗仪（半岛白极光） | G34: 380,000.00 | H34: 2025-10-31 | I34: 60 | J34: 0.05 | K34: 直线法 | L34: 300000 | M34: 合同编号:XSHT-20250915-0003； | N34: =G34-L34 -> 80000 | O34: Y | P34: Y | Q34: Y | R34: Y
M35: 验收单编号10300002129； | N35: =G35-L35 -> 0
N36: =G36-L36 -> 0
B38: 标记图例: 记录已识别的异常情况以及如何解决这些异常情况的详细信息，包括执行的其他实质性程序（指南：包括足够的描述，以使之前与审计无关的经验丰富的审计师能够理解执行的程序）。
B39: NA

Sheet 新增清单
B4: 固定资产类别 | C4: 固定资产编号 | D4: 固定资产名称 | E4: 入账开始日期 | F4: 使用寿命(月) | G4: 残值率 | H4: 期初原值 | I4: 期初累计折旧 | J4: 本期计提折旧 | K4: 期末原值 | L4: 新增方式
B5: 电子设备 | C5: 01-04-0083 | D5: 飞利浦音响 | E5: 2025-02-25 | F5: 36 | G5: 0.05 | H5: 0 | I5: 0 | J5: 382.4 | K5: 1449 | L5: 购置
B6: 电子设备 | C6: 01-04-0084 | D6: 小米手机 | E6: 2025-03-11 | F6: 36 | G6: 0.05 | H6: 0 | I6: 0 | J6: 499.5 | K6: 2103 | L6: 购置
B7: 电子设备 | C7: 01-04-0085 | D7: 电脑主机 | E7: 2025-04-11 | F7: 36 | G7: 0.05 | H7: 0 | I7: 0 | J7: 1583.36 | K7: 7500 | L7: 购置
B8: 电子设备 | C8: 01-04-0086 | D8: 兼容机(特配) | E8: 2025-07-30 | F8: 36 | G8: 0.05 | H8: 0 | I8: 0 | J8: 626.75 | K8: 4750 | L8: 购置
B9: 电子设备 | C9: 01-04-0087 | D9: 组装电脑 | E9: 2025-08-31 | F9: 36 | G9: 0.049998583 | H9: 0 | I9: 0 | J9: 260.68 | K9: 2469.67 | L9: 购置
B10: 电子设备 | C10: 01-04-0088 | D10: 组装机/主机 | E10: 2025-10-28 | F10: 36 | G10: 0.05 | H10: 0 | I10: 0 | J10: 150.42 | K10: 2850 | L10: 购置
B11: 电子设备 | C11: 01-04-0089 | D11: 华为荣耀80手机 | E11: 2025-11-11 | F11: 36 | G11: 0.05 | H11: 0 | I11: 0 | J11: 102.84 | K11: 3897 | L11: 购置
B12: 电子设备 | C12: 01-04-0090 | D12: AUX奥克斯冰箱 | E12: 2025-11-26 | F12: 36 | G12: 0.05 | H12: 0 | I12: 0 | J12: 19.21 | K12: 728 | L12: 购置
B13: 仪器设备 | C13: 01-05-0107 | D13: 3D智能面部扫描仪 | E13: 2025-03-10 | F13: 60 | G13: 0.05 | H13: 0 | I13: 0 | J13: 8977.5 | K13: 63000 | L13: 购置
B14: 仪器设备 | C14: 01-05-0108 | D14: 电子注射器控制助推装置 | E14: 2025-04-30 | F14: 60 | G14: 0.05 | H14: 0 | I14: 0 | J14: 2128 | K14: 16800 | L14: 购置
B15: 仪器设备 | C15: 01-05-0109 | D15: 高频电灼仪（燃脂炮） | E15: 2025-05-26 | F15: 60 | G15: 0.05 | H15: 0 | I15: 0 | J15: 20836.69 | K15: 188000 | L15: 购置
B16: 仪器设备 | C16: 01-05-0110 | D16: 牙科综合治疗机 | E16: 2025-08-31 | F16: 60 | G16: 0.05 | H16: 0 | I16: 0 | J16: 2337 | K16: 36900 | L16: 购置
... B24: 运输工具 | C24: 01-07-0004 | D24: 浙AN311V别克汽车 | E24: 2025-03-20 | F24: 48 | G24: 0.05 | H24: 0 | I24: 0 | J24: 10687.5 | K24: 60000 | L24: 购置
B25: 合计 | H25: =SUM(H5:H24) -> 0 | I25: =SUM(I5:I24) -> 0 | J25: =SUM(J5:J24) -> 66690.44 | K25: =SUM(K5:K24) -> 866546.67 | L25: 购置

Sheet K.02.1a 新增选样输出
B1: Skywind-TOD | G1: 抽样策略工作底稿
A2: 客户名称 | D2: B医疗公司
A3: 截止日期 | D3: 2025/12/31
A4: Canvas ID | D4: 1800255374
A6: 抽样项目基础信息
A8: 版本号 | F8: V2.0.0
A9: Skywind TOD 抽样记录 | F9: 7E8787F21DAC4BD78A7F000930A5AC17
A10: 测试类型 | F10: 详细测试
A11: 重大账户类型 | F11: 资产
A12: 抽样科目 | F12: K.固定资产
A13: 审计期间 | F13: 期末
A14: 是否已执行利润表中期抽样 | F14: 否
A15: 可容忍误差 （TE） | F15: 241,890.00
A16: 测试涵盖的认定 | F16: 存在/发生, 计量/计价, 权利与义务
A17: 是否存在与上述认定相关的舞弊或特别风险？ | F17: 否
A18: 综合风险评估 | F18: 最低
A19: 是否为PCAOB审计？ | F19: 否
... A22: 是否适用于非复杂方法？ | F22: 否
A24: 源数据汇总
A26: 导入的数据文件
A27: 文件名 | E27: 文件类型 | G27: sheet | H27: 上传日期
A28: 02-杭州瑞丽 新增.xlsx | E28: xlsx | G28: Sheet1 | H28: 2026/01/27
A30: 匹配详细信息
A31: 抽样单位列： | F31: 制单日期, 凭证字号, 凭证本币总金额, 审核人, 制单人, 摘要, 科目编码, 科目名称, 辅助项
A32: 抽样单位货币列： | F32: 借方(本币)
A33: 抽样单位详情：
A35: 样本池汇总
A37: 数据上传转换步骤
A38: 已上传数据 | F38: 866,546.67
A39: 必要的数据排除项 | F39: 0.00
A40: 必要的数据排除项类型
A41: 样本池总体金额 | F41: 866,546.67
A42: 排除项总量 | F42: 0
A43: 已删除零余额（行数） | F43: 0
A44: 已删除空余额（行数） | F44: 0
A45: 已删除负余额（行数） | F45: 0
A46: 已删除正余额（行数） | F46: 0
A47: 关键项
A48: 关键项数量 | F48: 1
A49: 定量关键项金额（金额大于241,890.00 ) | F49: 380,000.00
...

Sheet K.02.2 处置测试
B1: 标准工作底稿: K1 SWP 不动产、厂房和设备及相关账户（PPE）
B2: K.02.2：详细测试 (处置/报废)
B4: 返回汇总页
B6: 记录我们的详细测试所涵盖的总体（指引：纳入充分的描述，以使经验丰富且之前与该项审计无关的审计师能够理解样本是如何选择的，例如，总体的分类或筛选。）
E12: |------- Rx -------|
E13: 账面净值 | G13: 原值 | I13: 累计折旧 | K13: 减值准备
B14: 处置/报废总金额 | E14: =G14-I14-K14 -> 0
B15: Breakdown中处置/报废金额 | E15: =G15-I15-K15 -> 73447.66 | F15: K.01 | G15: =-'K.01 Agree SL to GL'!Z15 -> 159633 | H15: K.01 | I15: =-'K.01 Agree SL to GL'!Z21 -> 86185.34 | J15: K.01 | K15: =-'K.01 Agree SL to GL'!Z27 -> 0 | L15: K.01
B16: 差异 | E16: =E14-E15 -> -73447.66 | F16: Rx | G16: =G14-G15 -> -159633 | H16: Rx | I16: =I14-I15 -> -86185.34 | J16: Rx | K16: =K14-K15 -> 0 | L16: Rx
B17: 差异是否需要进一步调查？ | E17: =IF(ABS(E16)>'K.00 Lead Sheet'!$C$6,"是","否") -> 是 | G17: =IF(ABS(G16)>'K.00 Lead Sheet'!$C$6,"是","否") -> 是 | I17: =IF(ABS(I16)>'K.00 Lead Sheet'!$C$6,"是","否") -> 是 | K17: =IF(ABS(K16)>'K.00 Lead Sheet'!$C$6,"是","否") -> 否
B19: 减：测试的关键项目
B20: 进行代表性抽样的剩余总体 | E20: =E14-E19 -> 0
B22: 在下方描述选择关键项目的理由（请参阅Canvas指导工作流程的“关键项目”部分，包括信息图标）
B28: EY 测试属性解释:
B29: 对于每个被选中进行测试的项目，我们检查了相关的第三方证据以及相关的会计分录，并确定：
B30: 1) 测试样本（原值和累计折旧余额）已从固定资产明细账和总账中正确移除。
B31: 2) 重新计算资产处置时点的账面净值，并计算处置损益。确认处置损益已按照适用的财务报告框架正确记录和分类。
B32: 3) 如果适用，正确记录处置收入金额。如果资产被出售（即收到收益），则获得发票或付款证明等，并确认与日记账分录中记录的收益金额一致。
B34: 固定资产处置/报废测试 | L34: |------- Rx -------| | O34: |------- Rx -------| | Q34: |------- Rx -------| | S34: EY Works
B35: 样本序号 | C35: 样本类型 | D35: 固定资产类别 | E35: 总账账户 | F35: 固定资产编号 | G35: 固定资产名称 | H35: 处置/报废日 | I35: 原值 | J35: 累计折旧 | K35: 减值准备 | L35: 净值 | M35: 出售价格 | N35: 处置交易凭证号 | O35: 处置损益 | P35: 出售价格（通过审计证据/支持性文件取得） | Q35: 出售价格差异 | R35: 获得的证据/支持的描述（例如，我们检查的具体销售发票/合同/订单/审批文件等） | S35: 1 | T35: 2 | U35: 3
B36: 1 | L36: =I36-J36-K36 -> 0 | O36: =M36-L36 -> 0 | Q36: =P36-M36 -> 0
B37: 2 | L37: =I37-J37-K37 -> 0 | O37: =M37-L37 -> 0 | Q37: =P37-M37 -> 0
B38: 3 | L38: =I38-J38-K38 -> 0 | O38: =M38-L38 -> 0 | Q38: =P38-M38 -> 0
B40: 标记图例: 记录已识别的异常情况以及如何解决这些异常情况的详细信息，包括执行的其他实质性程序（指南：包括足够的描述，以使之前与审计无关的经验丰富的审计师能够理解执行的程序）。

Sheet SkywindSettingSheet
A1: db9ce45c-b5c9-4e6d-be28-967b500f20b6
A3: {"Id":"2120100351","IsProject":false,"ProjectId":"2006602268","TempProjectName":"云端天风测试","TempType":2,"Upload":"上传","Download":"下载"}
A4: TRUE
