Workbook

Sheet Comments【归档前删除】
A1: EY Ref. | B1: Tab Ref. | C1: Cell Ref. | D1: Question/Comment | E1: Answer/Comment | F1: Closed?
A2: 1 | B2: K.00 Lead Sheet | C2: $C$5 | D2: Dana D Li: 199.2万，请确认 | F2: No
A3: 2 | B3: K.00 Lead Sheet | C3: $C$6 | D3: Dana D Li: 23.4万，请确认 | F3: No
A4: 3 | B4: K.00 Lead Sheet | C4: $B$67 | D4: Dana D Li: 补充索引 | F4: No
A5: 4 | B5: K****gree SL to GL | C5: $R$10 | D5: Dana D Li: 电子设备为什么要分两列列示？补充note | F5: No
A6: 5 | B6: BKD-成都力积 | C6: $L$10 | D6: Dana D Li: 同前，为什么电子设备分两列 | F6: No
A7: 6 | B7: BKD-成都力积 | C7: $B$52 | D7: Dana D Li: 无形资产？ | F7: No
A8: 7 | B8: K.02.1 新增测试 | C8: $O$34 | D8: Dana D Li: 这两个样本问下客户，我看签收日期是25年6月，发票日期是25年10月，其他资料也都是25年的，让客户不从26年才入账的依据，比如转固验收单？之类的 | F8: No
A9: 8 | B9: K.03.3 折旧政策复核 | C9: $B$17 | D9: Dana D Li: 同前，这个1和2到底啥区别呀/有必要分开列嘛 | F9: No

Sheet 汇总 
A1: V6 SWP
B2: 该科目涉及OSP底稿可参考此链接 | F2: O****x
F3: O****x
B5: K.00 | C5: K.00 Lead Sheet | F5: 程序页 | G5: 执行 | H5: 不执行的原因 | I5: 注意事项
B6: 1 | C6: 获取和编制固定资产两期变动的引导表，并与试算平衡表和上年底稿核对一致。对固定资产变动建立预期并说明理由，对不符合预期的变动以及异常变动进行调查和分析。 | F6: K.00 Lead Sheet | G6: 是
B7: K.01 | C7: K****gree SL to GL（认定：BS：E、V、C IS：M、C） | F7: 程序页 | G7: 执行 | H7: 不执行的原因 | I7: 注意事项
B8: 1 | C8: 获取固定资产后推明细表，并将其与试算平衡表和固定资产清单核对一致。 | F8: K****gree SL to GL | G8: 是
B9: K.02 | C9: K.02.1 新增测试（认定：BS：E、V、C、R&O、P&D IS：M,P&D） | F9: 程序页 | G9: 执行 | H9: 不执行的原因 | I9: 注意事项
B10: 1 | C10: 获取当期按类别划分的所有固定资产新增清单，并将该清单与固定资产后推核对一致，调查超过SAD名义金额的差额。 | F10: 新增清单 | G10: 是 | I10: K.02.1a skywind抽样页面日期选择错误，但样本池仅资产名称及对应本期新增金额，抽样过程不受该时间影响，不影响随机抽样结果，特补充说明
B11: 2 | C11: 对本年新增资产执行关键性样本测试和代表性样本测试（如需要）。 | F11: K.02.1 新增测试 | G11: 是
F12: K.02.1a 新增选样输出
B13: K.02 | C13: K.02.2 处置测试（认定：BS：E、V、C、R&O、P&D IS：M,P&D） | F13: 程序页 | G13: 执行 | H13: 不执行的原因 | I13: 注意事项
B14: 1 | C14: 获取当期按类别划分的所有固定资产处置清单，包括记录的处置的损益，并将该清单与固定资产后推核对一致，我们调查超过SAD名义金额的差额。 | F14: 处置清单 | G14: 是
B15: 2 | C15: 对本年处置资产执行关键性样本测试和代表性样本测试（如需要）。 | F15: K.02.2 处置测试 | G15: 否
F16: K.02.2a 处置选样输出
B17: K.03 | C17: K.03 折旧测试（认定：BS：V IS:O、M、P&D） | F17: 程序页 | G17: 执行 | H17: 不执行的原因 | I17: 注意事项
B18: 1 | C18: 执行实质性分析程序(SAP)测试折旧费用，可参考264 GL 或K****AP模板执行。如不执行，可直接执行K.03.2 折旧测试TOD。 | F18: K****AP | G18: 否 | H18: 选择TOD方法1:by item测算
B19: 2 | C19: 如选择执行详细测试，可使用该底稿记录。 | F19: K.03.2 折旧测试TOD | G19: 是
B20: 3 | C20: 检查固定资产各项目的折旧政策是否符合有关规定，是否与上期一致，评价其合理性。若改变折旧政策，检查其依据是否充分。 | F20: K.03.3 折旧政策复核 | G20: 是
B21: K.04 | C21: K.04 固定资产的减值（认定：BS：V IS：M） | F21: 程序页 | G21: 执行 | H21: 不执行的原因 | I21: 注意事项
B22: 1 | C22: 1.使用在审计过程中所获得的信息来确定管理层是否已识别适当的减值迹象；可使用PSP Canvas form K.04：识别减值迹象，也可使用 <SWP减值迹象识别> 对减值迹象进行评估，并根据指引要求获取相关支持性文件。 2.如有减值迹象的，评价管理层假设、未来现金流等减值评估的合理性，核实并测算减值金额。 3.检查是否存在转回固定资产减值准备的情况，确定减值准备在以后会计期间没有转回。 | F22: 程序4_商誉减值测试明细-VIU | G22: 是

Sheet K.00 Lead Sheet
B1: 标准工作底稿: K1 SWP 不动产、厂房和设备及相关账户（PPE）
B2: 客户名称 | C2: 浙****积 | D2: 此工作底稿需要与以下 Canvas PSP guided workflow forms一起使用： •K.00 PPE引导表 •K.01 将明细账与总账核对一致 •K.02 增加和处置 •K.03 折旧、损耗和摊销 •K.04 固定资产减值 •账户结论
B3: 期末 | C3: 46142
B4: 分析日期 | C4: 46181
B5: 可容忍误差（TE） | C5: =[3]审计范围2026430!$H$256 -> 1992000
B6: 名义金额（SAD） | C6: =[3]审计范围2026430!$H$257 -> 234000
B7: 适用会计准则（GAAP） | C7: HKFRS
B8: 记账本位币 | C8: CNY
B9: K.00 编制引导表并比较余额
B11: 返回汇总页
D13: Threshold(s) | J13: 安永标记
B14: 认定 | C14: CRA | D14: 各项认定1 | E14: 所有相关认定 2 | H14: TB | I14: 已与科目余额表核对无误
B15: 完整性（C） | C15: Minimal | D15: =IF(C15="Minimal",$C$5*100%,IF(C15="Low",$C$5*75%,IF(C15="Moderate",$C$5*50%,IF(C15="High",$C$5*25%,IF(C15="N/A","-",))))) -> 1992000 | E15: =MIN($D$15:$D$19) -> 1992000 | H15: PY | I15: 与上年最终审定数核对一致
B16: 存在性/发生 (E/O) | C16: Minimal | D16: =IF(C16="Minimal",$C$5*100%,IF(C16="Low",$C$5*75%,IF(C16="Moderate",$C$5*50%,IF(C16="High",$C$5*25%,IF(C16="N/A","-",))))) -> 1992000 | H16: A3 | I16: 与未审数、审定数核对一致
B17: 计价/计量（V/M） | C17: Minimal | D17: =IF(C17="Minimal",$C$5*100%,IF(C17="Low",$C$5*75%,IF(C17="Moderate",$C$5*50%,IF(C17="High",$C$5*25%,IF(C17="N/A","-",))))) -> 1992000 | H17: A5 | I17: 与审计调整核对一致
B18: 权利和义务（R&O） | C18: Minimal | D18: =IF(C18="Minimal",$C$5*100%,IF(C18="Low",$C$5*75%,IF(C18="Moderate",$C$5*50%,IF(C18="High",$C$5*25%,IF(C18="N/A","-",))))) -> 1992000 | H18: FS | I18: 与FS.0x与财务报表核对无误
B19: 列报和披露（P&D） | C19: N/A | D19: =IF(C19="Minimal",$C$5*100%,IF(C19="Low",$C$5*75%,IF(C19="Moderate",$C$5*50%,IF(C19="High",$C$5*25%,IF(C19="N/A","-",))))) -> - | H19: w | I19: 低于SAD的金额——放弃进一步调查
B20: 1 各项认定的测试阈值，是根据EY GAM SUBSTANTIVE DESIGN 2.2.1 | H20: Rx | I20: 重新计算，无异常
B21: 中的示例测试阈值（用占TE的百分比表示）在相应风险等级（CRA）区间的上限计算得出的。 | H21: m | I21: 余额/活动不符合测试范围–无需进一步调查
B22: 除负债/费用类别账户的完整性认定应当使用负债/费用账户表之外，其他类别账户和认定均可使用资产/收入账户表。 | H22: SL | I22: 已与明细账核对无误
B23: 2 所有相关认定的测试阈值，是所有有效认定对应之测试阈值的最小值。我们在
B24: Lead中使用该测试阈值：（a）作为选取总账账户进行测试的起点；（b）作为（需要进一步调查的）金额波动范围的起点。
B27: 在下文中描述我们对固定资产在此期间的相关账户余额和相关波动的预期，以及我们对这些预期的依据和理由。
B28: 账户变更 | C28: 预期及额外考虑
B29: 新增 | C29: 被审计单位为了满足不断增长的客户需求，购买新的设备和生产用具等资产，以取代已折旧和处置的资产和/或维护资本支出支持其现有的生产经营活动；因此，我们预计本期固定资产的原值将存在新增的变动。
B30: 减少 | C30: 随****备，我们预计本期固定资产的原值将存在较小的处置变动。
B31: 在建工程转入（如适用） | C31: 需要安装的固定资产预计本期达到使用状态而转固。
B32: 转让、外汇和其他调整 | C32: 被审计单位本期不涉及其他资产的转让、外汇业务等事项。
B33: 折旧方法 | C33: 直线法，我们预计本年较上年无变化。
B34: 折旧费用 | C34: 因为被审计单位折旧方法和使用寿命没有变化，将与往年一样正常计提折旧；同时，本年新增的机器设备将在全年投入使用，且无重大处置资产。因此，我们预计本年度累计折旧较上年增加。
B35: 使用寿命变化 | C35: 由于本年度被审计单位的折旧政策未发生变化，我们预计被审计单位固定资产的使用寿命也不会发生变化。
B38: 波动范围
B39: ="波动幅度 ("&C8&"):" -> 波动幅度 (CNY): | C39: =$E$15 -> 1992000
B40: 波动幅度 (%): | C40: 0.1
B42: 我们获取或编制了与上期对比的重大账户（固定资产）引导表。我们将本期余额与试算平衡表核对一致，并将上期余额与上期审定数核对一致（如适用）。
B43: 我们将期末余额与上期余额进行对比。调查超出测试阈值（金额和百分比）的波动，以及代表异常或预期外变动或未发生预期中变动的波动，并确定其对我们计划实质性程序的影响 (如有)。
E46: |------- TB -------| | J46: |------- PY -------|
E47: ="货币/单位: "&C8 -> 货币/单位: CNY
E48: =$C$3 -> 46142 | J48: =DATE(YEAR($C$3)-1,12,31) -> 46022 | K48: 本期和上期期末余额 | N48: 基于波动幅度判断，是否进一步调查？ | O48: 基于定性考虑判断，是否进一步调查？
B49: 总账科目编码 | C49: 科目名称 | D49: 索引号 | E49: 期末账面数 | F49: 账表调整数 | G49: 期末未审数 | H49: 审计调整数 | I49: 期末审定数 | J49: 上期末审定数 | K49: 变动金额 | L49: 变动% | M49: Notes
...

Sheet K.01 Agree SL to GL
B1: 标准工作底稿: K1 SWP 不动产、厂房和设备及相关账户（PPE）
B2: K.01 将明细账与总账核对一致
B4: 返回汇总页
B6: 获取上期末至本期末（或中期，如适用）固定资产及相关新增、处置、转让和折旧的后推明细表。（原值、累计折旧、减值均为正数填列，本期减少以负数填列，账表调整、审计调整数据均直接链接至K.00 Lead。）
B7: 我们将期初固定资产余额与上期审定数核对一致，将期末固定资产余额与固定资产明细账和试算表核对一致。我们调查了大于SAD的差异。我们将利润表金额（如，折旧费用）与试算表核对一致（如适用）。
B8: 我们选择了超过测试阈值的后推活动（如，新增、处置、固定资产转入、转移和折旧费用），以执行K.02和K.03的实质性程序。对于未包含在本程序表范围内的程序，我们交叉索引至完成该程序的单独程序表。我们评估了固定资产的转移和其他调整，以了解调整的性质，并确定是否需要执行额外程序。
B9: 表1 | Z9: |--------------------------- Rx ------------------------------|
D10: 固定资产类别 | F10: 房屋建筑物 | I10: 生产设备 | L10: 家具工具 | O10: 运输工具 | R10: 电子设备1 | U10: 电子设备2 | X10: 【…】 | AA10: 合计
E11: 账面数 | F11: 账表调整/审计调整 | G11: 审定数 | H11: 账面数 | I11: 账表调整/审计调整 | J11: 审定数 | K11: 账面数 | L11: 账表调整/审计调整 | M11: 审定数 | N11: 账面数 | O11: 账表调整/审计调整 | P11: 审定数 | Q11: 账面数 | R11: 账表调整/审计调整 | S11: 审定数 | T11: 账面数 | U11: 账表调整/审计调整 | V11: 审定数 | W11: 账面数 | X11: 账表调整/审计调整 | Y11: 审定数 | Z11: 账面数 | AA11: 账表调整/审计调整 | AB11: 审定数 | AC11: CHECK
C12: 年初余额 | D12: PY | E12: 23791564 | G12: =SUM(E12:F12) -> 23791564 | H12: 55495051 | I12: ='K.00 Lead Sheet'!E71 -> -2309027.5 | J12: =SUM(H12:I12) -> 53186023 | K12: 827014.13 | M12: =SUM(K12:L12) -> 827014.13 | N12: 115247.79 | P12: =SUM(N12:O12) -> 115247.79 | Q12: 1510708.2 | S12: =SUM(Q12:R12) -> 1510708.2 | T12: 6414640.2 | V12: =SUM(T12:U12) -> 6414640.2 | Y12: =SUM(W12:X12) -> 0 | Z12: =SUM(E12,H12,K12,N12,Q12,T12,W12) -> 88154225 | AA12: =SUM(F12,I12,L12,O12,R12,U12,X12) -> -2309027.5 | AB12: =SUM(G12,J12,M12,P12,S12,V12,Y12) -> 85845197 | AC12: =AB12-'K.00 Lead Sheet'!J50 -> 0
C13: 购置 | D13: K.02.1 | E13: 0 | G13: =SUM(E13:F13) -> 0 | H13: 9928664.4 | J13: =SUM(H13:I13) -> 9928664.4 | K13: 22283.18 | M13: =SUM(K13:L13) -> 22283.18 | N13: 0 | P13: =SUM(N13:O13) -> 0 | Q13: 95951.3 | S13: =SUM(Q13:R13) -> 95951.3 | T13: 268805.3 | V13: =SUM(T13:U13) -> 268805.3 | Y13: =SUM(W13:X13) -> 0 | Z13: =SUM(E13,H13,K13,N13,Q13,T13,W13) -> 10315704 | AA13: =SUM(F13,I13,L13,O13,R13,U13,X13) -> 0 | AB13: =SUM(G13,J13,M13,P13,S13,V13,Y13) -> 10315704
C14: 在建工程转入 | D14: J1.02 | E14: 0 | G14: =SUM(E14:F14) -> 0 | H14: 0 | J14: =SUM(H14:I14) -> 0 | K14: 0 | M14: =SUM(K14:L14) -> 0 | N14: 0 | P14: =SUM(N14:O14) -> 0 | Q14: 0 | S14: =SUM(Q14:R14) -> 0 | T14: 254328.68 | V14: =SUM(T14:U14) -> 254328.68 | Y14: =SUM(W14:X14) -> 0 | Z14: =SUM(E14,H14,K14,N14,Q14,T14,W14) -> 254328.68 | AA14: =SUM(F14,I14,L14,O14,R14,U14,X14) -> 0 | AB14: =SUM(G14,J14,M14,P14,S14,V14,Y14) -> 254328.68
B15: 原值 | C15: 处置或报废 | D15: K.02.2 | E15: 0 | G15: =SUM(E15:F15) -> 0 | H15: -2809645.2 | I15: ='K.00 Lead Sheet'!$E$76 -> 1724074.1 | J15: =SUM(H15:I15) -> -1085571.1 | K15: 0 | M15: =SUM(K15:L15) -> 0 | N15: 0 | P15: =SUM(N15:O15) -> 0 | Q15: -30714.81 | S15: =SUM(Q15:R15) -> -30714.81 | T15: -280710.66 | V15: =SUM(T15:U15) -> -280710.66 | Y15: =SUM(W15:X15) -> 0 | Z15: =SUM(E15,H15,K15,N15,Q15,T15,W15) -> -3121070.6 | AA15: =SUM(F15,I15,L15,O15,R15,U15,X15) -> 1724074.1 | AB15: =SUM(G15,J15,M15,P15,S15,V15,Y15) -> -1396996.5
C16: 内部重分类 | E16: 0 | G16: =SUM(E16:F16) -> 0 | H16: 0 | J16: =SUM(H16:I16) -> 0 | K16: 0 | M16: =SUM(K16:L16) -> 0 | N16: 0 | P16: =SUM(N16:O16) -> 0 | Q16: 0 | S16: =SUM(Q16:R16) -> 0 | T16: 0 | V16: =SUM(T16:U16) -> 0 | Y16: =SUM(W16:X16) -> 0 | Z16: =SUM(E16,H16,K16,N16,Q16,T16,W16) -> 0 | AA16: =SUM(F16,I16,L16,O16,R16,U16,X16) -> 0 | AB16: =SUM(G16,J16,M16,P16,S16,V16,Y16) -> 0
C17: […] | E17: 0 | G17: =SUM(E17:F17) -> 0 | H17: 0 | J17: =SUM(H17:I17) -> 0 | K17: 0 | M17: =SUM(K17:L17) -> 0 | N17: 0 | P17: =SUM(N17:O17) -> 0 | Q17: 0 | S17: =SUM(Q17:R17) -> 0 | T17: 0 | V17: =SUM(T17:U17) -> 0 | Y17: =SUM(W17:X17) -> 0 | Z17: =SUM(E17,H17,K17,N17,Q17,T17,W17) -> 0 | AA17: =SUM(F17,I17,L17,O17,R17,U17,X17) -> 0 | AB17: =SUM(G17,J17,M17,P17,S17,V17,Y17) -> 0
C18: 年末余额 | D18: Rx | E18: =E12+E13+E14+E15+E16+E17 -> 23791564 | F18: =F12+F13+F14+F15+F16+F17 -> 0 | G18: =G12+G13+G14+G15+G16+G17 -> 23791564 | H18: =H12+H13+H14+H15+H16+H17 -> 62614070 | I18: =I12+I13+I14+I15+I16+I17 -> -584953.4 | J18: =J12+J13+J14+J15+J16+J17 -> 62029116 | K18: =K12+K13+K14+K15+K16+K17 -> 849297.31 | L18: =L12+L13+L14+L15+L16+L17 -> 0 | ... Y18: =Y12+Y13+Y14+Y15+Y16+Y17 -> 0 | Z18: =Z12+Z13+Z14+Z16+Z17+Z15 -> 95603187 | AA18: =AA12+AA13+AA14+AA15+AA16+AA17 -> -584953.4 | AB18: =AB12+AB13+AB14+AB15+AB16+AB17 -> 95018234 | AC18: =AB18-'K.00 Lead Sheet'!I50 -> 0
C19: 年初余额 | D19: PY | E19: 1176556.9 | G19: =SUM(E19:F19) -> 1176556.9 | H19: 10276671 | I19: =('K.00 Lead Sheet'!E69+'K.00 Lead Sheet'!E81+'K.00 Lead Sheet'!E80)*-1 -> -1645181.4 | J19: =SUM(H19:I19) -> 8631489.5 | K19: 411822.41 | M19: =SUM(K19:L19) -> 411822.41 | N19: 70873.76 | P19: =SUM(N19:O19) -> 70873.76 | Q19: 986572.04 | S19: =SUM(Q19:R19) -> 986572.04 | T19: 2366209.9 | V19: =SUM(T19:U19) -> 2366209.9 | Y19: =SUM(W19:X19) -> 0 | Z19: =SUM(E19,H19,K19,N19,Q19,T19,W19) -> 15288706 | AA19: =SUM(F19,I19,L19,O19,R19,U19,X19) -> -1645181.4 | AB19: =SUM(G19,J19,M19,P19,S19,V19,Y19) -> 13643525 | AC19: =AB19-'K.00 Lead Sheet'!J51 -> 0
C20: 计提 | D20: K.03.2 | E20: 412149.2 | G20: =SUM(E20:F20) -> 412149.2 | H20: 2505797.5 | I20: ='K.00 Lead Sheet'!E80 -> -146238.29 | J20: =SUM(H20:I20) -> 2359559.2 | K20: 48080.5 | M20: =SUM(K20:L20) -> 48080.5 | N20: 9102.08 | P20: =SUM(N20:O20) -> 9102.08 | Q20: 95420.29 | S20: =SUM(Q20:R20) -> 95420.29 | T20: 399890.71 | V20: =SUM(T20:U20) -> 399890.71 | Y20: =SUM(W20:X20) -> 0 | Z20: =SUM(E20,H20,K20,N20,Q20,T20,W20) -> 3470440.2 | AA20: =SUM(F20,I20,L20,O20,R20,U20,X20) -> -146238.29 | AB20: =SUM(G20,J20,M20,P20,S20,V20,Y20) -> 3324201.9 | AC20: <K.03 折旧测试>
B21: 累计折旧 | C21: 处置或报废 | D21: K.02.2 | E21: 0 | G21: =SUM(E21:F21) -> 0 | H21: =-711776.44-1468039.01 -> -2179815.5 | I21: =('K.00 Lead Sheet'!E75)*-1 -> 1206466.3 | J21: =SUM(H21:I21) -> -973349.18 | K21: 0 | M21: =SUM(K21:L21) -> 0 | N21: 0 | P21: =SUM(N21:O21) -> 0 | Q21: -29179.08 | S21: =SUM(Q21:R21) -> -29179.08 | T21: -262136.69 | V21: =SUM(T21:U21) -> -262136.69 | Y21: =SUM(W21:X21) -> 0 | Z21: =SUM(E21,H21,K21,N21,Q21,T21,W21) -> -2471131.2 | AA21: =SUM(F21,I21,L21,O21,R21,U21,X21) -> 1206466.3 | AB21: =SUM(G21,J21,M21,P21,S21,V21,Y21) -> -1264664.9
C22: 内部重分类 | E22: 0 | G22: =SUM(E22:F22) -> 0 | H22: 0 | J22: =SUM(H22:I22) -> 0 | K22: 0 | M22: =SUM(K22:L22) -> 0 | N22: 0 | P22: =SUM(N22:O22) -> 0 | Q22: 0 | S22: =SUM(Q22:R22) -> 0 | T22: 0 | V22: =SUM(T22:U22) -> 0 | Y22: =SUM(W22:X22) -> 0 | Z22: =SUM(E22,H22,K22,N22,Q22,T22,W22) -> 0 | AA22: =SUM(F22,I22,L22,O22,R22,U22,X22) -> 0 | AB22: =SUM(G22,J22,M22,P22,S22,V22,Y22) -> 0
C23: […] | E23: 0 | G23: =SUM(E23:F23) -> 0 | H23: 0 | J23: =SUM(H23:I23) -> 0 | K23: 0 | M23: =SUM(K23:L23) -> 0 | N23: 0 | P23: =SUM(N23:O23) -> 0 | Q23: 0 | S23: =SUM(Q23:R23) -> 0 | T23: 0 | V23: =SUM(T23:U23) -> 0 | Y23: =SUM(W23:X23) -> 0 | Z23: =SUM(E23,H23,K23,N23,Q23,T23,W23) -> 0 | AA23: =SUM(F23,I23,L23,O23,R23,U23,X23) -> 0 | AB23: =SUM(G23,J23,M23,P23,S23,V23,Y23) -> 0
C24: 年末余额 | D24: Rx | E24: =E19+E20+E21+E22+E23 -> 1588706.1 | F24: =F19+F20+F21+F22+F23 -> 0 | G24: =G19+G20+G21+G22+G23 -> 1588706.1 | H24: =H19+H20+H21+H22+H23 -> 10602653 | I24: =I19+I20+I21+I22+I23 -> -584953.4 | J24: =J19+J20+J21+J22+J23 -> 10017699 | K24: =K19+K20+K21+K22+K23 -> 459902.91 | L24: =L19+L20+L21+L22+L23 -> 0 | ... AB24: =AB19+AB20+AB21+AB22+AB23 -> 15703062 | AC24: =AB24-'K.00 Lead Sheet'!I51 -> 0
C25: 年初余额 | D25: PY | E25: 0 | G25: =SUM(E25:F25) -> 0 | H25: 0 | J25: =SUM(H25:I25) -> 0 | K25: 0 | M25: =SUM(K25:L25) -> 0 | N25: 0 | P25: =SUM(N25:O25) -> 0 | Q25: 0 | S25: =SUM(Q25:R25) -> 0 | T25: 0 | V25: =SUM(T25:U25) -> 0 | Y25: =SUM(W25:X25) -> 0 | Z25: =SUM(E25,H25,K25,N25,Q25,T25,W25) -> 0 | AA25: =SUM(F25,I25,L25,O25,R25,U25,X25) -> 0 | AB25: =SUM(G25,J25,M25,P25,S25,V25,Y25) -> 0 | AC25: =AB25-'K.00 Lead Sheet'!J52 -> 0
C26: 计提 | D26: SWP 减值 | E26: 0 | G26: =SUM(E26:F26) -> 0 | H26: 0 | J26: =SUM(H26:I26) -> 0 | K26: 0 | M26: =SUM(K26:L26) -> 0 | N26: 0 | P26: =SUM(N26:O26) -> 0 | Q26: 0 | S26: =SUM(Q26:R26) -> 0 | T26: 0 | V26: =SUM(T26:U26) -> 0 | Y26: =SUM(W26:X26) -> 0 | Z26: =SUM(E26,H26,K26,N26,Q26,T26,W26) -> 0 | AA26: =SUM(F26,I26,L26,O26,R26,U26,X26) -> 0 | AB26: =SUM(G26,J26,M26,P26,S26,V26,Y26) -> 0
B27: 减值准备 | C27: 处置或报废 | D27: K.02.2 | E27: 0 | G27: =SUM(E27:F27) -> 0 | H27: 0 | J27: =SUM(H27:I27) -> 0 | K27: 0 | M27: =SUM(K27:L27) -> 0 | N27: 0 | P27: =SUM(N27:O27) -> 0 | Q27: 0 | S27: =SUM(Q27:R27) -> 0 | T27: 0 | V27: =SUM(T27:U27) -> 0 | Y27: =SUM(W27:X27) -> 0 | Z27: =SUM(E27,H27,K27,N27,Q27,T27,W27) -> 0 | AA27: =SUM(F27,I27,L27,O27,R27,U27,X27) -> 0 | AB27: =SUM(G27,J27,M27,P27,S27,V27,Y27) -> 0
C28: 内部重分类 | E28: 0 | G28: =SUM(E28:F28) -> 0 | H28: 0 | J28: =SUM(H28:I28) -> 0 | K28: 0 | M28: =SUM(K28:L28) -> 0 | N28: 0 | P28: =SUM(N28:O28) -> 0 | Q28: 0 | S28: =SUM(Q28:R28) -> 0 | T28: 0 | V28: =SUM(T28:U28) -> 0 | Y28: =SUM(W28:X28) -> 0 | Z28: =SUM(E28,H28,K28,N28,Q28,T28,W28) -> 0 | AA28: =SUM(F28,I28,L28,O28,R28,U28,X28) -> 0 | AB28: =SUM(G28,J28,M28,P28,S28,V28,Y28) -> 0
C29: […] | E29: 0 | G29: =SUM(E29:F29) -> 0 | H29: 0 | J29: =SUM(H29:I29) -> 0 | K29: 0 | M29: =SUM(K29:L29) -> 0 | N29: 0 | P29: =SUM(N29:O29) -> 0 | Q29: 0 | S29: =SUM(Q29:R29) -> 0 | T29: 0 | V29: =SUM(T29:U29) -> 0 | Y29: =SUM(W29:X29) -> 0 | Z29: =SUM(E29,H29,K29,N29,Q29,T29,W29) -> 0 | AA29: =SUM(F29,I29,L29,O29,R29,U29,X29) -> 0 | AB29: =SUM(G29,J29,M29,P29,S29,V29,Y29) -> 0
C30: 年末余额 | D30: Rx | E30: =E25+E26+E27+E28+E29 -> 0 | F30: =F25+F26+F27+F28+F29 -> 0 | G30: =G25+G26+G27+G28+G29 -> 0 | H30: =H25+H26+H27+H28+H29 -> 0 | I30: =I25+I26+I27+I28+I29 -> 0 | J30: =J25+J26+J27+J28+J29 -> 0 | K30: =K25+K26+K27+K28+K29 -> 0 | L30: =L25+L26+L27+L28+L29 -> 0 | ... AB30: =AB25+AB26+AB27+AB28+AB29 -> 0 | AC30: =AB30-'K.00 Lead Sheet'!I52 -> 0
B31: 净值 (NBV) | C31: 年初余额 | D31: Rx | E31: =E12-E19-E25 -> 22615007 | F31: =F12-F19-F25 -> 0 | G31: =G12-G19-G25 -> 22615007 | H31: =H12-H19-H25 -> 45218380 | I31: =I12-I19-I25 -> -663846.14 | J31: =J12-J19-J25 -> 44554534 | K31: =K12-K19-K25 -> 415191.72 | L31: =L12-L19-L25 -> 0 | ... AB31: =AB12-AB19-AB25 -> 72201673 | AC31: =AB31-'K.00 Lead Sheet'!J56 -> 0
C32: 年末余额 | D32: Rx | E32: =E18-E24-E30 -> 22202858 | F32: =F18-F24-F30 -> 0 | G32: =G18-G24-G30 -> 22202858 | H32: =H18-H24-H30 -> 52011417 | I32: =I18-I24-I30 -> 0 | J32: =J18-J24-J30 -> 52011417 | K32: =K18-K24-K30 -> 389394.4 | L32: =L18-L24-L30 -> 0 | ... AB32: =AB18-AB24-AB30 -> 79315172 | AC32: =AB32-'K.00 Lead Sheet'!I56 -> 0
B33: 变动 | C33: 原值变动金额 | D33: 本年VS上年 | E33: =E18-E12 -> 0 | G33: =G18-G12 -> 0 | H33: =H18-H12 -> 7119019.2 | J33: =J18-J12 -> 8843093.3 | K33: =K18-K12 -> 22283.18 | M33: =M18-M12 -> 22283.18 | N33: =N18-N12 -> 0 | P33: =P18-P12 -> 0 | Q33: =Q18-Q12 -> 65236.49 | S33: =S18-S12 -> 65236.49 | T33: =T18-T12 -> 242423.32 | V33: =V18-V12 -> 242423.32 | W33: =W18-W12 -> 0 | Y33: =Y18-Y12 -> 0 | Z33: =Z18-Z12 -> 7448962.2 | AA33: =AA18-AA12 -> 1724074.1 | AB33: =AB18-AB12 -> 9173036.3
C34: 原值变动比例 | D34: % | E34: =IFERROR(E33/E12,1) -> 0 | G34: =IFERROR(G33/G12,1) -> 0 | H34: =IFERROR(H33/H12,1) -> 0.12828206 | J34: =IFERROR(J33/J12,1) -> 0.16626724 | K34: =IFERROR(K33/K12,1) -> 0.026944135 | M34: =IFERROR(M33/M12,1) -> 0.026944135 | N34: =IFERROR(N33/N12,1) -> 0 | P34: =IFERROR(P33/P12,1) -> 0 | Q34: =IFERROR(Q33/Q12,1) -> 0.04318272 | S34: =IFERROR(S33/S12,1) -> 0.04318272 | T34: =IFERROR(T33/T12,1) -> 0.037792193 | V34: =IFERROR(V33/V12,1) -> 0.037792193 | W34: =IFERROR(W33/W12,1) -> 1 | Y34: =IFERROR(Y33/Y12,1) -> 1 | Z34: =IFERROR(Z33/Z12,1) -> 0.084499208 | AA34: =IFERROR(AA33/AA12,1) -> -0.74666677 | AB34: =IFERROR(AB33/AB12,1) -> 0.10685556
C35: 累计折旧变动金额 | D35: 本年VS上年 | E35: =E24-E19 -> 412149.2 | G35: =G24-G19 -> 412149.2 | H35: =H24-H19 -> 325982 | J35: =J24-J19 -> 1386210 | K35: =K24-K19 -> 48080.5 | M35: =M24-M19 -> 48080.5 | N35: =N24-N19 -> 9102.08 | P35: =P24-P19 -> 9102.08 | Q35: =Q24-Q19 -> 66241.21 | S35: =S24-S19 -> 66241.21 | T35: =T24-T19 -> 137754.02 | V35: =V24-V19 -> 137754.02 | W35: =W24-W19 -> 0 | Y35: =Y24-Y19 -> 0 | Z35: =Z24-Z19 -> 999309.01 | AA35: =AA24-AA19 -> 1060228 | AB35: =AB24-AB19 -> 2059537
C36: 累计折旧变动比例 | D36: % | E36: =IFERROR(E35/E19,1) -> 0.35030111 | G36: =IFERROR(G35/G19,1) -> 0.35030111 | H36: =IFERROR(H35/H19,1) -> 0.031720584 | J36: =IFERROR(J35/J19,1) -> 0.16059916 | K36: =IFERROR(K35/K19,1) -> 0.11675057 | M36: =IFERROR(M35/M19,1) -> 0.11675057 | N36: =IFERROR(N35/N19,1) -> 0.12842666 | P36: =IFERROR(P35/P19,1) -> 0.12842666 | Q36: =IFERROR(Q35/Q19,1) -> 0.067142801 | S36: =IFERROR(S35/S19,1) -> 0.067142801 | T36: =IFERROR(T35/T19,1) -> 0.058217159 | V36: =IFERROR(V35/V19,1) -> 0.058217159 | W36: =IFERROR(W35/W19,1) -> 1 | Y36: =IFERROR(Y35/Y19,1) -> 1 | Z36: =IFERROR(Z35/Z19,1) -> 0.065362563 | AA36: =IFERROR(AA35/AA19,1) -> -0.64444443 | AB36: =IFERROR(AB35/AB19,1) -> 0.15095344
C37: 减值准备变动金额 | D37: 本年VS上年 | E37: =E30-E25 -> 0 | G37: =G30-G25 -> 0 | H37: =H30-H25 -> 0 | J37: =J30-J25 -> 0 | K37: =K30-K25 -> 0 | M37: =M30-M25 -> 0 | N37: =N30-N25 -> 0 | P37: =P30-P25 -> 0 | Q37: =Q30-Q25 -> 0 | S37: =S30-S25 -> 0 | T37: =T30-T25 -> 0 | V37: =V30-V25 -> 0 | W37: =W30-W25 -> 0 | Y37: =Y30-Y25 -> 0 | Z37: =Z30-Z25 -> 0 | AA37: =AA30-AA25 -> 0 | AB37: =AB30-AB25 -> 0
C38: 减值准备变动比例 | D38: % | E38: =IFERROR(E37/E25,1) -> 1 | G38: =IFERROR(G37/G25,1) -> 1 | H38: =IFERROR(H37/H25,1) -> 1 | J38: =IFERROR(J37/J25,1) -> 1 | K38: =IFERROR(K37/K25,1) -> 1 | M38: =IFERROR(M37/M25,1) -> 1 | N38: =IFERROR(N37/N25,1) -> 1 | P38: =IFERROR(P37/P25,1) -> 1 | Q38: =IFERROR(Q37/Q25,1) -> 1 | S38: =IFERROR(S37/S25,1) -> 1 | T38: =IFERROR(T37/T25,1) -> 1 | V38: =IFERROR(V37/V25,1) -> 1 | W38: =IFERROR(W37/W25,1) -> 1 | Y38: =IFERROR(Y37/Y25,1) -> 1 | Z38: =IFERROR(Z37/Z25,1) -> 1 | AA38: =IFERROR(AA37/AA25,1) -> 1 | AB38: =IFERROR(AB37/AB25,1) -> 1
C39: 净值变动金额 | D39: 本年VS上年 | E39: =E32-E31 -> -412149.2 | G39: =G32-G31 -> -412149.2 | H39: =H32-H31 -> 6793037.2 | J39: =J32-J31 -> 7456883.3 | K39: =K32-K31 -> -25797.32 | M39: =M32-M31 -> -25797.32 | N39: =N32-N31 -> -9102.08 | P39: =P32-P31 -> -9102.08 | Q39: =Q32-Q31 -> -1004.72 | S39: =S32-S31 -> -1004.72 | T39: =T32-T31 -> 104669.3 | V39: =V32-V31 -> 104669.3 | W39: =W32-W31 -> 0 | Y39: =Y32-Y31 -> 0 | Z39: =Z32-Z31 -> 6449653.2 | AA39: =AA32-AA31 -> 663846.14 | AB39: =AB32-AB31 -> 7113499.3
C40: 净值变动比例 | D40: % | E40: =IFERROR(E39/E31,1) -> -0.018224589 | G40: =IFERROR(G39/G31,1) -> -0.018224589 | H40: =IFERROR(H39/H31,1) -> 0.15022735 | J40: =IFERROR(J39/J31,1) -> 0.16736531 | K40: =IFERROR(K39/K31,1) -> -0.062133513 | M40: =IFERROR(M39/M31,1) -> -0.062133513 | N40: =IFERROR(N39/N31,1) -> -0.20512178 | P40: =IFERROR(P39/P31,1) -> -0.20512178 | Q40: =IFERROR(Q39/Q31,1) -> -0.0019169064 | S40: =IFERROR(S39/S31,1) -> -0.0019169064 | T40: =IFERROR(T39/T31,1) -> 0.025854293 | V40: =IFERROR(V39/V31,1) -> 0.025854293 | W40: =IFERROR(W39/W31,1) -> 1 | Y40: =IFERROR(Y39/Y31,1) -> 1 | Z40: =IFERROR(Z39/Z31,1) -> 0.088514475 | AA40: =IFERROR(AA39/AA31,1) -> -1 | AB40: =IFERROR(AB39/AB31,1) -> 0.098522639
B42: TB-原值 | E42: 23791564 | H42: 62614070 | K42: 849297.31 | N42: 115247.79 | Q42: 1575944.7 | T42: 6657063.5 | Z42: =SUM(E42,H42,K42,N42,Q42,T42,W42) -> 95603187
B43: 差异 | E43: =E18-E42 -> 0 | H43: =H18-H42 -> 0 | K43: =K18-K42 -> 0 | N43: =N18-N42 -> 0 | Q43: =Q18-Q42 -> 0 | T43: =T18-T42 -> 0 | W43: =W18-W42 -> 0 | Z43: =Z18-Z42 -> 0
...

Sheet FA list
A1: 资产分类名称 | B1: 财产编号 | C1: 中文名称 | D1: 数量 | E1: 规格型号 | F1: 取得日期 | G1: 入帐日期 | H1: 开始折旧 | I1: 年限 | J1: 未用年限 | K1: 期初账面原值 | L1: 本期增加 | M1: 本期减少 | N1: 期末账面原值 | O1: 本年折旧 | P1: 期末累计折旧（含加速） | Q1: 帐面价值 | R1: 减值准备 | S1: 资产净额 | T1: 存放位置 | U1: 折旧科目 | V1: 序列号
A2: 生产设备 | B2: 400202 | C2: 手动调试工具 | D2: 1 | E2: C220077-1 | F2: 45657 | G2: 45657 | H2: 202501 | I2: 120 | J2: 104 | K2: 9500 | N2: =K2+L2-M2 -> 9500 | O2: 300.84 | P2: 1203.36 | Q2: 8296.64 | R2: 0 | S2: 8296.64 | T2: 金华厂房 | U2: 66021204
A3: 生产设备 | B3: 400203 | C3: 手动调试工具 | D3: 1 | E3: C220077-1 | F3: 45657 | G3: 45657 | H3: 202501 | I3: 120 | J3: 104 | K3: 9500 | N3: =K3+L3-M3 -> 9500 | O3: 300.84 | P3: 1203.36 | Q3: 8296.64 | R3: 0 | S3: 8296.64 | T3: 金华厂房 | U3: 66021204
A4: 生产设备 | B4: 400204 | C4: 手动调试工具 | D4: 1 | E4: C220077-1 | F4: 45657 | G4: 45657 | H4: 202501 | I4: 120 | J4: 104 | K4: 9500 | N4: =K4+L4-M4 -> 9500 | O4: 300.84 | P4: 1203.36 | Q4: 8296.64 | R4: 0 | S4: 8296.64 | T4: 金华厂房 | U4: 66021204
A5: 生产设备 | B5: 400205 | C5: 手动调试工具 | D5: 1 | E5: C220077-1 | F5: 45657 | G5: 45657 | H5: 202501 | I5: 120 | J5: 104 | K5: 9500 | N5: =K5+L5-M5 -> 9500 | O5: 300.84 | P5: 1203.36 | Q5: 8296.64 | R5: 0 | S5: 8296.64 | T5: 金华厂房 | U5: 66021204
A6: 生产设备 | B6: 400206 | C6: 手动调试工具 | D6: 1 | E6: C220077-1 | F6: 45657 | G6: 45657 | H6: 202501 | I6: 120 | J6: 104 | K6: 9500 | N6: =K6+L6-M6 -> 9500 | O6: 300.84 | P6: 1203.36 | Q6: 8296.64 | R6: 0 | S6: 8296.64 | T6: 金华厂房 | U6: 66021204
A7: 生产设备 | B7: 400207 | C7: F25 512M DDR2探针卡 | D7: 1 | E7: 458DUT_T5377_3FB | F7: 45747 | G7: 45747 | H7: 202504 | I7: 60 | J7: 47 | K7: 1069334.7 | N7: =K7+L7-M7 -> 1069334.7 | O7: 67724.52 | P7: 220104.69 | Q7: 849230.01 | R7: 0 | S7: 849230.01 | T7: 台湾 | U7: 510102 | V7: S/N:SAU2400217*1
A8: 生产设备 | B8: 400208 | C8: F25 512M DDR2探针卡 | D8: 1 | E8: 458DUT_T5377_3FB | F8: 45747 | G8: 45747 | H8: 202504 | I8: 60 | J8: 47 | K8: 807839.55 | N8: =K8+L8-M8 -> 807839.55 | O8: 51163.16 | P8: 166280.27 | Q8: 641559.28 | R8: 0 | S8: 641559.28 | T8: 台湾 | U8: 510102 | V8: S/N:SAU2400218*1
A9: 生产设备 | B9: 400209 | C9: F25 2G DDR3光罩 | D9: 47 | E9: 一整套47片40万美金 | F9: 45790 | G9: 45790 | H9: 202506 | I9: 60 | J9: 49 | K9: 2880320 | N9: =K9+L9-M9 -> 2880320 | O9: 182420.28 | P9: 501655.77 | Q9: 2378664.2 | R9: 0 | S9: 2378664.2 | T9: 台湾力晶晶圆厂 | U9: 5301010301
A10: 生产设备 | B10: 400210 | C10: F25 2G DDR3探针卡 | D10: 1 | E10: F25 2G DDR3 | F10: 45827 | G10: 45827 | H10: 202507 | I10: 60 | J10: 50 | K10: 633884.58 | N10: =K10+L10-M10 -> 633884.58 | O10: 40146.04 | P10: 100365.1 | Q10: 533519.48 | R10: 0 | S10: 533519.48 | T10: 台湾 | U10: 5301010301 | V10: 1套
A11: 生产设备 | B11: 400211 | C11: DDR4*16颗粒烧测治具 | D11: 20 | E11: BGA96 DDR4 *16 DEDICATED BURN | F11: 45824 | G11: 45824 | H11: 202507 | I11: 120 | J11: 110 | K11: 574952 | N11: =K11+L11-M11 -> 574952 | O11: 18206.8 | P11: 45517 | Q11: 529435 | R11: 0 | S11: 529435 | T11: 金华厂房 | U11: 66021204
A12: 生产设备 | B12: 400212 | C12: 温度记录仪 | D12: 1 | E12: DIAF8862 | F12: 45875 | G12: 45875 | H12: 202509 | I12: 120 | J12: 112 | K12: 23008.85 | N12: =K12+L12-M12 -> 23008.85 | O12: 728.6 | P12: 1457.2 | Q12: 21551.65 | R12: 0 | S12: 21551.65 | T12: 金华厂房 | U12: 66021204 | V12: GL260A-CN/B-563SL-30
A13: 生产设备 | B13: 400213 | C13: 温度记录仪 | D13: 1 | E13: M6242 | F13: 45875 | G13: 45875 | H13: 202509 | I13: 120 | J13: 112 | K13: 31858.4 | N13: =K13+L13-M13 -> 31858.4 | O13: 1008.84 | P13: 2017.68 | Q13: 29840.72 | R13: 0 | S13: 29840.72 | T13: 金华厂房 | U13: 66021204 | V13: GL860A
A14: 生产设备 | B14: 400214 | C14: 帕捷双联体高温项箱 | D14: 1 | E14: STC3503-D | F14: 45923 | G14: 45923 | H14: 202510 | I14: 120 | J14: 113 | K14: 107180.49 | N14: =K14+L14-M14 -> 107180.49 | O14: 3394.04 | P14: 5939.57 | Q14: 101240.92 | R14: 0 | S14: 101240.92 | T14: 金华厂房 | U14: 66021204
A15: 生产设备 | B15: 400215 | C15: IC装载/分选机 Sorter上卸板机(7件) | D15: 1 | E15: WFD-3000 | F15: 45950 | G15: 45950 | H15: 202511 | I15: 120 | J15: 114 | K15: 1741906.7 | N15: =K15+L15-M15 -> 1741906.7 | O15: 55160.38 | P15: 82740.57 | Q15: 1659166.2 | R15: 0 | S15: 1659166.2 | T15: 金华厂房 | U15: 66021204 | V15: ZF91-25100602
A16: 生产设备 | B16: 400216 | C16: Lead Scan外观锡球检验机 | D16: 1 | E16: P5000 | F16: 45959 | G16: 45959 | H16: 202511 | I16: 120 | J16: 114 | K16: 1241895.4 | N16: =K16+L16-M16 -> 1241895.4 | O16: 39326.68 | P16: 58990.02 | Q16: 1182905.4 | R16: 0 | S16: 1182905.4 | T16: 金华厂房 | U16: 66021204 | V16: ZF91-25100603
A17: 生产设备 | B17: 400217 | C17: 镭射盖印机（全自动激光打标机） | D17: 1 | E17: TM612G | F17: 45982 | G17: 45982 | H17: 202512 | I17: 120 | J17: 115 | K17: 1755498.4 | N17: =K17+L17-M17 -> 1755498.4 | O17: 55590.8 | P17: 69488.5 | Q17: 1686009.9 | R17: 0 | S17: 1686009.9 | T17: 金华厂房 | U17: 66021204 | V17: ZF91-25110160（金额=设备+运费）
A18: 生产设备 | B18: 400218 | C18: 杰锐思1*8拾取头快换模组 | D18: 2 | E18: 1*8 | F18: 46006 | G18: 46006 | H18: 202601 | I18: 120 | J18: 116 | K18: 16637.17 | N18: =K18+L18-M18 -> 16637.17 | O18: 526.84 | P18: 526.84 | Q18: 16110.33 | R18: 0 | S18: 16110.33 | T18: 金华厂房 | U18: 66021204 | V18: ZF91-25120411
A19: 生产设备 | B19: 400219 | C19: 512M DDR2 F25探针卡 | D19: 1 | E19: F25_512MDDR2_458DUT _T5377_3FB | F19: 46035 | G19: 46035 | H19: 202602 | I19: 120 | J19: 117 | K19: 0 | L19: 840303.95 | N19: =K19+L19-M19 -> 840303.95 | O19: 19957.23 | P19: 19957.23 | Q19: 820346.72 | R19: 0 | S19: 820346.72 | T19: 台湾 | U19: 510102 | V19: ZF91-26010551
A20: 生产设备 | B20: 400220 | C20: HSM1光罩 | D20: 8 | E20: SASAPTKSD1DP | F20: 46051 | G20: 46051 | H20: 202602 | I20: 120 | J20: 117 | K20: 0 | L20: 260065.6 | N20: =K20+L20-M20 -> 260065.6 | O20: 6176.55 | P20: 6176.55 | Q20: 253889.05 | R20: 0 | S20: 253889.05 | T20: 台湾力晶晶圆厂 | U20: 5301010301 | V20: ZF91-26010555
A21: 生产设备 | B21: 400221 | C21: HSM1光罩 | D21: 12 | E21: SASAPTHDD1FP | F21: 46051 | G21: 46051 | H21: 202602 | I21: 120 | J21: 117 | K21: 0 | L21: 309970.08 | N21: =K21+L21-M21 -> 309970.08 | O21: 7361.79 | P21: 7361.79 | Q21: 302608.29 | R21: 0 | S21: 302608.29 | T21: 台湾力晶晶圆厂 | U21: 5301010301 | V21: ZF91-26010556
A22: 生产设备 | B22: 400222 | C22: HSM1光罩 | D22: 47 | E22: SASAPTH8D1DP | F22: 46051 | G22: 46051 | H22: 202602 | I22: 120 | J22: 117 | K22: 0 | L22: 2757398.2 | N22: =K22+L22-M22 -> 2757398.2 | O22: 65488.2 | P22: 65488.2 | Q22: 2691910 | R22: 0 | S22: 2691910 | T22: 台湾力晶晶圆厂 | U22: 5301010301 | V22: ZF91-26010557
A23: 生产设备 | B23: 400223 | C23: HSM1光罩 | D23: 47 | E23: SASAPTKRD1DP | F23: 46051 | G23: 46051 | H23: 202602 | I23: 120 | J23: 117 | K23: 0 | L23: 2757398.2 | N23: =K23+L23-M23 -> 2757398.2 | O23: 65488.2 | P23: 65488.2 | Q23: 2691910 | R23: 0 | S23: 2691910 | T23: 台湾力晶晶圆厂 | U23: 5301010301 | V23: ZF91-26010558
A24: 生产设备 | B24: 400224 | C24: DDR3 96BGA DSA治具 | D24: 1 | E24: T5588 M6242 | F24: 46056 | G24: 46056 | H24: 202603 | I24: 120 | J24: 118 | K24: 0 | L24: 908210.92 | N24: =K24+L24-M24 -> 908210.92 | O24: 14380 | P24: 14380 | Q24: 893830.92 | R24: 0 | S24: 893830.92 | T24: 台湾 | U24: 510102 | V24: ZF91-26020389
A25: 生产设备 | B25: 400225 | C25: F25_4GD3探针卡 | D25: 1 | E25: S/N:SAU2402692 | F25: 46142 | G25: 46142 | H25: 202605 | I25: 120 | J25: 120 | K25: 0 | L25: 1298078.6 | N25: =K25+L25-M25 -> 1298078.6 | O25: 0 | P25: 0 | Q25: 1298078.6 | R25: 0 | S25: 1298078.6 | T25: 台湾 | U25: 510102 | V25: ZF91-26040522
A26: 生产设备 | B26: 400226 | C26: F25_HSM1探针卡 | D26: 1 | E26: S/N:TW259003 | F26: 46142 | G26: 46142 | H26: 202605 | I26: 120 | J26: 120 | K26: 0 | L26: 797238.75 | N26: =K26+L26-M26 -> 797238.75 | O26: 0 | P26: 0 | Q26: 797238.75 | R26: 0 | S26: 797238.75 | T26: 台湾力晶晶圆厂 | U26: 5301010301 | V26: ZF91-26040521
A27: 运输工具 | B27: 500001 | C27: 诺力电动搬运车 | D27: 1 | F27: 44855 | G27: 44855 | H27: 202211 | I27: 48 | J27: 6 | K27: 20092.92 | N27: =K27+L27-M27 -> 20092.92 | O27: 1590.7 | P27: 16702.22 | Q27: 3390.7 | R27: 0 | S27: 3390.7 | T27: 金华厂房 | U27: 66021205
A28: 运输工具 | B28: 500002 | C28: 诺力电池叉车 | D28: 1 | F28: 44855 | G28: 44855 | H28: 202211 | I28: 48 | J28: 6 | K28: 72721.24 | N28: =K28+L28-M28 -> 72721.24 | O28: 5757.1 | P28: 60449.53 | Q28: 12271.71 | R28: 0 | S28: 12271.71 | T28: 金华厂房 | U28: 66021205
A29: 运输工具 | B29: 500003 | C29: 搬运车 | D29: 1 | E29: 3T685*1220 | F29: 45657 | G29: 45657 | H29: 202501 | I29: 60 | J29: 44 | K29: 1371.68 | N29: =K29+L29-M29 -> 1371.68 | O29: 86.88 | P29: 347.52 | Q29: 1024.16 | R29: 0 | S29: 1024.16 | T29: 金华厂房 | U29: 66021205
A30: 运输工具 | B30: 500004 | C30: 杜瓦罐防倾倒气瓶推车 | D30: 1 | E30: 上海仓捷 | F30: 45742 | G30: 45742 | H30: 202504 | I30: 48 | J30: 35 | K30: 2477.88 | N30: =K30+L30-M30 -> 2477.88 | O30: 196.16 | P30: 637.52 | Q30: 1840.36 | R30: 0 | S30: 1840.36 | T30: 金华厂房 | U30: 66021205
A31: 运输工具 | B31: 500005 | C31: 不锈钢移动小推车 | D31: 2 | E31: 不锈钢移动小推车B | F31: 45964 | G31: 45964 | H31: 202512 | I31: 48 | J31: 43 | K31: 18584.07 | N31: =K31+L31-M31 -> 18584.07 | O31: 1471.24 | P31: 1839.05 | Q31: 16745.02 | R31: 0 | S31: 16745.02 | T31: 金华厂房 | U31: 66021205 | V31: ZF91-25110143
A32: 房屋建筑物 | B32: 600001 | C32: 洁净车间 | D32: 1 | F32: 45657 | G32: 45657 | H32: 202501 | I32: 120 | J32: 104 | K32: 2238913.8 | N32: =K32+L32-M32 -> 2238913.8 | O32: 70898.92 | P32: 283595.68 | Q32: 1955318.1 | R32: 0 | S32: 1955318.1 | T32: 金华厂房 | U32: 66021206
A33: 房屋建筑物 | B33: 600002 | C33: 金华厂房 | D33: 1 | F33: 45657 | G33: 45657 | H33: 202501 | I33: 240 | J33: 224 | K33: 19391182 | N33: =K33+L33-M33 -> 19391182 | O33: 307027.04 | P33: 1228108.2 | Q33: 18163074 | R33: 0 | S33: 18163074 | T33: 金华厂房 | U33: 66021206
A34: 房屋建筑物 | B34: 600003 | C34: 金华工厂二楼电子生产净化车间 | D34: 1 | F34: 45889 | G34: 45889 | H34: 202508 | I34: 240 | J34: 231 | K34: 2161467.9 | N34: =K34+L34-M34 -> 2161467.9 | O34: 34223.24 | P34: 77002.29 | Q34: 2084465.6 | R34: 0 | S34: 2084465.6 | T34: 金华厂房 | U34: 66021206
A35: 家具工具 | B35: 300095 | C35: 钢制文件柜 | D35: 5 | F35: 45320 | G35: 45320 | H35: 202402 | I35: 60 | J35: 33 | K35: 7566.37 | N35: =K35+L35-M35 -> 7566.37 | O35: 479.2 | P35: 3234.6 | Q35: 4331.77 | R35: 0 | S35: 4331.77 | T35: 杭州办公室 | U35: 66021203
A36: 家具工具 | B36: 300096 | C36: 艾思培训桌 | D36: 10 | F36: 45320 | G36: 45320 | H36: 202402 | I36: 60 | J36: 33 | K36: 9831.86 | N36: =K36+L36-M36 -> 9831.86 | O36: 622.68 | P36: 4203.09 | Q36: 5628.77 | R36: 0 | S36: 5628.77 | T36: 杭州办公室 | U36: 66021203
A37: 家具工具 | B37: 300097 | C37: 艾思演讲台 | D37: 1 | F37: 45320 | G37: 45320 | H37: 202402 | I37: 60 | J37: 33 | K37: 1250.44 | N37: =K37+L37-M37 -> 1250.44 | O37: 79.2 | P37: 534.6 | Q37: 715.84 | R37: 0 | S37: 715.84 | T37: 杭州办公室 | U37: 66021203
A38: 家具工具 | B38: 300098 | C38: 艾文培训椅 | D38: 20 | F38: 45320 | G38: 45320 | H38: 202402 | I38: 60 | J38: 33 | K38: 8761.06 | N38: =K38+L38-M38 -> 8761.06 | O38: 554.86 | P38: 3745.42 | Q38: 5015.64 | R38: 0 | S38: 5015.64 | T38: 杭州办公室 | U38: 66021203
A39: 家具工具 | B39: 300099 | C39: 吧台 | D39: 1 | F39: 45320 | G39: 45320 | H39: 202402 | I39: 60 | J39: 33 | K39: 2389.38 | N39: =K39+L39-M39 -> 2389.38 | O39: 151.32 | P39: 1021.41 | Q39: 1367.97 | R39: 0 | S39: 1367.97 | T39: 杭州办公室 | U39: 66021203
A40: 家具工具 | B40: 300100 | C40: 班前椅 | D40: 25 | F40: 45320 | G40: 45320 | H40: 202402 | I40: 60 | J40: 33 | K40: 5796.46 | N40: =K40+L40-M40 -> 5796.46 | O40: 367.12 | P40: 2478.06 | Q40: 3318.4 | R40: 0 | S40: 3318.4 | T40: 杭州办公室 | U40: 66021203
...

Sheet K.02.1 新增测试 
B1: 标准工作底稿: K1 SWP 不动产、厂房和设备及相关账户（PPE）
B2: K.02.1：详细测试 (新增)
B4: 返回汇总页
B6: 记录我们的详细测试所涵盖的总体（指引：纳入充分的描述，以使经验丰富且之前与该项审计无关的审计师能够理解样本是如何选择的，例如，总体的分类或筛选。）
B7: 我们将本年固定资产购置增加的明细作为测试的样本总体。
B12: 购置总金额 | F12: =SUMIFS(新增清单!H:H,新增清单!I:I,"购置") -> 10315704
B13: Breakdown中购置金额 | F13: ='K.01 Agree SL to GL'!Z13 -> 10315704 | G13: K.01
B14: 差异 | F14: =F12-F13 -> 0 | G14: Rx | H14: 差异是否需要进一步调查？ | J14: =IF(ABS(F14)>'K.00 Lead Sheet'!$C$6,"是","否") -> 否
B16: 减：测试的关键项目 | F16: 0
B17: 进行代表性抽样的剩余总体 | F17: =F12-F16 -> 10315704
B19: 在下方描述选择关键项目的理由（请参阅Canvas指导工作流程的“关键项目”部分，包括信息图标）
B20: 1）我们将本年新增样本金额超过固定资产存在认定，计价认定及权利和义务认定的Threshold的样本，设定为关键项； 2）同时，我们将本年新增样本性质异常的单项资产，设定为关键项； 3）如果没有充分的关键项以支持我们得出结论，我们将测试延伸至剩余总体中的代表性抽样，选择随机抽样方法确定代表性样本。 基于对被审计单位和重大交易流程的了解，我们没有确定任何相关的定性标准。我们识别出金额超过TT的2个关键项。我们利用抽样工具评估已获得审计证据的充分性和适当性，按照评估结果，我们计划测试0个代表性样本。
B25: EY 测试属性解释:
B26: 对于每个被选中进行测试的项目，我们检查了相关的第三方证据以及相关的会计分录，并确定：
B27: 1) 测试样本于恰当的日期被正确资本化为固定资产（即，不应该费用化）。
B28: 2) 历史成本已根据适用的财务报告框架进行记录。
B29: 3) 管理层对测试项目采用的使用寿命和折旧方法是适当的（符合实体的会计政策和适用的财务报告框架）。
B30: 4) 该资产已被归入适当的固定资产类别。
N32: |------- Rx -------| | O32: EY Works
B33: 样本类型 | C33: 固定资产类别 | D33: 总账账户代码 | E33: 固定资产编号 | F33: 固定资产名称 | G33: 资产原价 | H33: 资本化日期 | I33: 使用寿命(月) | J33: 残值率 | K33: 折旧方法 | L33: 资产原价（通过审计证据/支持性文件取得） | M33: 获得的证据/支持的描述（例如，我们检查的控制权转移时点的单据/销售发票/合同/订单等） | N33: 资产原价差异 | O33: 1 | P33: 2 | Q33: 3 | R33: 4
B34: 关键项 | C34: 生产设备 | D34: 160104 | E34: 400222 | F34: HSM1光罩 | G34: 2757398.2 | H34: 2026/1/29 0:00:00 | I34: 120 | J34: 0.05 | K34: 直线法 | L34: 2757398.2 | M34: 采购单、运货签收单、入库单、发票、固定资产事前审批单 | N34: =G34-L34 -> 0 | O34: Y | P34: Y | Q34: Y | R34: Y
B35: 关键项 | C35: 生产设备 | D35: 160104 | E35: 400223 | F35: HSM1光罩 | G35: 2757398.2 | H35: 2026/1/29 0:00:00 | I35: 120 | J35: 0.05 | K35: 直线法 | L35: 2757398.2 | M35: 采购单、运货签收单、入库单、发票、固定资产事前审批单 | N35: =G35-L35 -> 0 | O35: Y | P35: Y | Q35: Y | R35: Y
B37: 标记图例: 记录已识别的异常情况以及如何解决这些异常情况的详细信息，包括执行的其他实质性程序
B38: 我们根据固定资产新增测试属性检查了样本对应的支持性证据，无异常情况。

Sheet Skywind抽样底稿
B1: Skywind-TOD | G1: 抽样策略工作底稿
A2: 客户名称 | D2: Z****d.
A3: 截止日期 | D3: 2026/04/30
A4: Canvas ID | D4: 1800235289
A6: 抽样项目基础信息
A8: 版本号 | F8: V2.0.0
A9: Skywind TOD 抽样记录 | F9: 19C1D96F78DF447F851C5D4AFA1BE10A
A10: 测试类型 | F10: 详细测试
A11: 重大账户类型 | F11: 资产
A12: 抽样科目 | F12: K.固定资产
A13: 审计期间 | F13: 期末
A14: 是否已执行利润表中期抽样 | F14: 否
A15: 可容忍误差 （TE） | F15: 1,995,000.00
A16: 测试涵盖的认定 | F16: 完整性, 存在/发生, 计量/计价, 权利与义务
A17: 是否存在与上述认定相关的舞弊或特别风险？ | F17: 否
A18: 综合风险评估 | F18: 最低
A19: 是否为PCAOB审计？ | F19: 否
... A22: 是否适用于非复杂方法？ | F22: 否
A24: 源数据汇总
A26: 导入的数据文件
A27: 文件名 | E27: 文件类型 | G27: sheet | H27: 上传日期
A28: K1 SWP 固定资产 2026430 浙江力积.xlsx | E28: xlsx | H28: 2026/06/09
A30: 匹配详细信息
A31: 抽样单位列：
A32: 抽样单位货币列： | F32: 原值
A33: 抽样单位详情：
A35: 样本池汇总
A37: 数据上传转换步骤
A38: 已上传数据 | F38: 10,315,704.16
A39: 必要的数据排除项 | F39: 0.00
A40: 必要的数据排除项类型
A41: 样本池总体金额 | F41: 10,315,704.16
A42: 排除项总量 | F42: 0
A43: 已删除零余额（行数） | F43: 0
A44: 已删除空余额（行数） | F44: 0
A45: 已删除负余额（行数） | F45: 0
A46: 已删除正余额（行数） | F46: 0
A47: 关键项
A48: 关键项数量 | F48: 2
A49: 定量关键项金额（金额大于1,995,000.00 ) | F49: 5,514,796.48
...

Sheet 新增清单
O2: 返回汇总页
B4: 固定资产新增明细清单
B5: 固定资产类别 | C5: 固定资产编号 | D5: 固定资产名称 | E5: 入账开始日期 | F5: 使用寿命(月) | G5: 残值率 | H5: 原值 | I5: 新增方式
B6: 生产设备 | C6: 400219 | D6: 512M DDR2 F25探针卡 | E6: 46035 | F6: 120 | G6: 0.05 | H6: 840303.95 | I6: 购置
B7: 生产设备 | C7: 400220 | D7: HSM1光罩 | E7: 46051 | F7: 120 | G7: 0.05 | H7: 260065.6 | I7: 购置
B8: 生产设备 | C8: 400221 | D8: HSM1光罩 | E8: 46051 | F8: 120 | G8: 0.05 | H8: 309970.08 | I8: 购置
B9: 生产设备 | C9: 400222 | D9: HSM1光罩 | E9: 46051 | F9: 120 | G9: 0.05 | H9: 2757398.2 | I9: 购置
B10: 生产设备 | C10: 400223 | D10: HSM1光罩 | E10: 46051 | F10: 120 | G10: 0.05 | H10: 2757398.2 | I10: 购置
B11: 生产设备 | C11: 400224 | D11: DDR3 96BGA DSA治具 | E11: 46056 | F11: 120 | G11: 0.05 | H11: 908210.92 | I11: 购置
B12: 生产设备 | C12: 400225 | D12: F25_4GD3探针卡 | E12: 46142 | F12: 120 | G12: 0.05 | H12: 1298078.6 | I12: 购置
B13: 生产设备 | C13: 400226 | D13: F25_HSM1探针卡 | E13: 46142 | F13: 120 | G13: 0.05 | H13: 797238.75 | I13: 购置
B14: 家具工具 | C14: 300182 | D14: 测试架 | E14: 46055 | F14: 60 | G14: 0.05 | H14: 17946.9 | I14: 购置
B15: 家具工具 | C15: 300183 | D15: 测试架 | E15: 46115 | F15: 60 | G15: 0.05 | H15: 4336.28 | I15: 购置
B16: 电子设备1 | C16: 100734 | D16: 液晶显示器 | E16: 46135 | F16: 36 | G16: 0.05 | H16: 851.62 | I16: 购置
B17: 电子设备1 | C17: 100735 | D17: 液晶显示器 | E17: 46135 | F17: 36 | G17: 0.05 | H17: 851.62 | I17: 购置
... B57: 电子设备1 | C57: 100733 | D57: 台式机电脑 | E57: 46135 | F57: 36 | G57: 0.05 | H57: 3503.54 | I57: 购置
B58: 合计 | H58: =SUM(H5:H57) -> 10570033
H59: Rx
H60: =H58-'K.01 Agree SL to GL'!Z13-'K.01 Agree SL to GL'!Z14 -> -4.0163286e-09

Sheet SkywindSettingSheet
A1: db9ce45c-b5c9-4e6d-be28-967b500f20b6
A3: {"Id":"2120100351","IsProject":false,"ProjectId":"2006602268","TempProjectName":"云端天风测试","TempType":2,"Upload":"上传","Download":"下载"}
A4: TRUE
