Workbook

Sheet Comments【归档前删除】
A1: EY Ref. | B1: Tab Ref. | C1: Cell Ref. | D1: Question/Comment | E1: Answer/Comment | F1: Closed?
A2: 1 | B2: 汇总 | C2: $G$18 | D2: Ruby YR Li: 未执行SAP，这里选否，下一行TOD测试选是。我直接改了。 | E2: Jayla Zhang: 已知悉 | F2: No
A3: 2 | B3: K.02.1 新增测试 | C3: $F$16 | D3: Dana D Li: 更新，下表并没有关键项样本 | E3: Jayla Zhang: 已修改 | F3: No
A4: 3 | B4: K.02.1 新增测试 | C4: $B$20 | D4: Dana D Li: 参考SOP更新 | E4: Jayla Zhang: 已修改 | F4: No
A5: 4 | B5: K.02.1 新增测试 | C5: $M$33 | D5: Dana D Li: 你放在one drive的压缩包，打不开，也解压不了 | F5: No
A6: 5 | B6: K.02.2 处置测试 | C6: $R$36 | D6: Dana D Li: 这还有用吗，没用删掉 | E6: Jayla Zhang: 已修改 | F6: No
A7: 6 | B7: K.02.2 处置测试 | C7: $B$41 | D7: Dana D Li: 更新 | E7: Jayla Zhang: 已更新 | F7: No
A8: 7 | B8: 处置清单 | C8: $E$8 | D8: user: M: 制造类 IS: 信息类 R&D:研发类 H: 管理类
A9: 8 | B9: 处置清单 | C9: $F$8 | D9: user: 1、设备 2、车辆 3、房屋、建筑物
A10: 9 | B10: 处置清单 | C10: $O$8 | D10: 1、毁损或使用状态差 2、战略性投资涉及报废 3、通常性投资涉及报废 4、维持性投资涉及报废 5、工艺变更、产品转型、工厂布局调整 6、已到使用寿命，正常报废
A11: 10 | B11: 处置清单 | C11: $P$8 | D11: user: 1、废旧金属； 2、整机变卖
A12: 11 | B12: 处置清单 | C12: $Q$8 | D12: 1.原值≥10M美元或重大资产如生产线等，向公司经营委员会提案；
A13: 12 | B13: 处置清单 | C13: $R$8 | D13: user: 涉及到因投资项目需要报废更新的项目，需要说明2021年战略、通常投资项目
A14: 13 | B14: K.03.2 折旧测试TOD-by item测试 | C14: $L$3260 | D14: Dana D Li: 差异更新 | E14: Jayla Zhang: 已修改 | F14: No

Sheet 汇总 
A1: V6 SWP
B2: 该科目涉及OSP底稿可参考此链接 | F2: OSP K1 SWP 固定资产及在建工程盘点 202YMMDD XYZ公司.xlsx
F3: OSP K1 SWP 固定资产权属检查 202YMMDD XYZ公司.xlsx
B5: K.00 | C5: K.00 Lead Sheet | F5: 程序页 | G5: 执行 | H5: 不执行的原因 | I5: 注意事项
B6: 1 | C6: 获取和编制固定资产两期变动的引导表，并与试算平衡表和上年底稿核对一致。对固定资产变动建立预期并说明理由，对不符合预期的变动以及异常变动进行调查和分析。 | F6: K.00 Lead Sheet | G6: 是
B7: K.01 | C7: K.01 Agree SL to GL（认定：IS：E、V、C、M） | F7: 程序页 | G7: 执行 | H7: 不执行的原因 | I7: 注意事项
B8: 1 | C8: 获取固定资产后推明细表，并将其与试算平衡表和固定资产清单核对一致。 | F8: K.01 Agree SL to GL | G8: 是
B9: K.02 | C9: K.02.1 新增测试（认定：E、V、C、P&D） | F9: 程序页 | G9: 执行 | H9: 不执行的原因 | I9: 注意事项
B10: 1 | C10: 获取当期按类别划分的所有固定资产新增清单，并将该清单与固定资产后推核对一致，调查超过SAD名义金额的差额。 | F10: 新增清单 | G10: 是 | I10: 若在建工程为不重大账户未开底稿，则项目组需要在K1 SWP中核对在建工程转入与转出金额是否一致，并按照<J.02.2 CIP transfer (ToD)>的测试属性执行该程序。
B11: 2 | C11: 对本年新增资产执行关键性样本测试和代表性样本测试（如需要）。 | F11: K.02.1 新增测试 | G11: 否
F12: K.02.1a 新增选样输出
B13: K.02 | C13: K.02.2 处置测试（认定：E、V、R&O） | F13: 程序页 | G13: 执行 | H13: 不执行的原因 | I13: 注意事项
B14: 1 | C14: 获取当期按类别划分的所有固定资产处置清单，包括记录的处置的损益，并将该清单与固定资产后推核对一致，我们调查超过SAD名义金额的差额。 | F14: 处置清单 | G14: 是
B15: 2 | C15: 对本年处置资产执行关键性样本测试和代表性样本测试（如需要）。 | F15: K.02.2 处置测试 | G15: 是
F16: K.02.2a 处置选样输出
B17: K.03 | C17: K.03 折旧测试（认定：IS:V、O、M、P&D） | F17: 程序页 | G17: 执行 | H17: 不执行的原因 | I17: 注意事项
B18: 1 | C18: 执行实质性分析程序(SAP)测试折旧费用，可参考264 GL 或K.03.1 SAP模板执行。如不执行，可直接执行K.03.2 折旧测试TOD。 | F18: K.03.1 SAP | G18: 否
B19: 2 | C19: 如选择执行详细测试，可使用该底稿记录。 | F19: K.03.2 折旧测试TOD | G19: 否
B20: 3 | C20: 检查固定资产各项目的折旧政策是否符合有关规定，是否与上期一致，评价其合理性。若改变折旧政策，检查其依据是否充分。 | F20: K.03.3 折旧政策复核 | G20: 是
B21: K.04 | C21: K.04 固定资产的减值（认定：BS：V IS：M） | F21: 程序页 | G21: 执行 | H21: 不执行的原因 | I21: 注意事项
B22: 1 | C22: 1.使用在审计过程中所获得的信息来确定管理层是否已识别适当的减值迹象；可使用PSP Canvas form K.04：识别减值迹象，也可使用 <SWP减值迹象识别> 对减值迹象进行评估，并根据指引要求获取相关支持性文件。 2.如有减值迹象的，评价管理层假设、未来现金流等减值评估的合理性，核实并测算减值金额。 3.检查是否存在转回固定资产减值准备的情况，确定减值准备在以后会计期间没有转回。 | F22: 项目组自行填写底稿索引 | G22: 是

Sheet K.00 Lead Sheet
B1: 标准工作底稿: K1 SWP 不动产、厂房和设备及相关账户（PPE）
B2: 客户名称 | D2: 此工作底稿需要与以下 Canvas PSP guided workflow forms一起使用： •K.00 PPE引导表 •K.01 将明细账与总账核对一致 •K.02 增加和处置 •K.03 折旧、损耗和摊销 •K.04 固定资产减值 •账户结论
B3: 期末
B4: 分析日期
B5: 可容忍误差（TE） | C5: 10000000
B6: 名义金额（SAD） | C6: 500000
B7: 适用会计准则（GAAP） | C7: PRC
B8: 记账本位币 | C8: CNY
B9: K.00 编制引导表并比较余额
B11: 返回汇总页
D13: Threshold(s) | J13: 安永标记
B14: 认定 | C14: CRA | D14: 各项认定1 | E14: 所有相关认定 2 | H14: TB | I14: 已与科目余额表核对无误
B15: 完整性（C） | C15: N/A | D15: =IF(C15="Minimal",$C$5*100%,IF(C15="Low",$C$5*75%,IF(C15="Moderate",$C$5*50%,IF(C15="High",$C$5*25%,IF(C15="N/A","-",))))) -> - | E15: =MIN($D$15:$D$19) -> 10000000 | H15: PY | I15: 与上年最终审定数核对一致
B16: 存在性/发生 (E/O) | C16: Minimal | D16: =IF(C16="Minimal",$C$5*100%,IF(C16="Low",$C$5*75%,IF(C16="Moderate",$C$5*50%,IF(C16="High",$C$5*25%,IF(C16="N/A","-",))))) -> 10000000 | H16: A3 | I16: 与未审数、审定数核对一致
B17: 计价/计量（V/M） | C17: Minimal | D17: =IF(C17="Minimal",$C$5*100%,IF(C17="Low",$C$5*75%,IF(C17="Moderate",$C$5*50%,IF(C17="High",$C$5*25%,IF(C17="N/A","-",))))) -> 10000000 | H17: A5 | I17: 与审计调整核对一致
B18: 权利和义务（R&O） | C18: N/A | D18: =IF(C18="Minimal",$C$5*100%,IF(C18="Low",$C$5*75%,IF(C18="Moderate",$C$5*50%,IF(C18="High",$C$5*25%,IF(C18="N/A","-",))))) -> - | H18: FS | I18: 与FS.0x与财务报表核对无误
B19: 列报和披露（P&D） | C19: N/A | D19: =IF(C19="Minimal",$C$5*100%,IF(C19="Low",$C$5*75%,IF(C19="Moderate",$C$5*50%,IF(C19="High",$C$5*25%,IF(C19="N/A","-",))))) -> - | H19: w | I19: 低于SAD的金额——放弃进一步调查
B20: 1 各项认定的测试阈值，是根据EY GAM SUBSTANTIVE DESIGN 2.2.1 | H20: Rx | I20: 重新计算，无异常
B21: 中的示例测试阈值（用占TE的百分比表示）在相应风险等级（CRA）区间的上限计算得出的。 | H21: m | I21: 余额/活动不符合测试范围–无需进一步调查
B22: 除负债/费用类别账户的完整性认定应当使用负债/费用账户表之外，其他类别账户和认定均可使用资产/收入账户表。 | H22: SL | I22: 已与明细账核对无误
B23: 2 所有相关认定的测试阈值，是所有有效认定对应之测试阈值的最小值。我们在
B24: Lead中使用该测试阈值：（a）作为选取总账账户进行测试的起点；（b）作为（需要进一步调查的）金额波动范围的起点。
B26: 在下文中描述我们对固定资产在此期间的相关账户余额和相关波动的预期，以及我们对这些预期的依据和理由。
B27: 账户变更 | C27: 预期及额外考虑
B28: 新增 | C28: 被审计单位为了满足不断增长的客户需求，购买新的设备和生产用具等资产，以取代已折旧和处置的资产支持其现有的生产经营活动；因此，我们预计本期固定资产的原值将存在新增的变动。
B29: 减少 | C29: 本期实际为24年减少，24年13期调表不调账，已获取该部分清单。
B30: 在建工程转入（如适用） | C30: 以前年度购买的需要安装的固定资产预计本期达到使用状态而转固。
B31: 转让、外汇和其他调整 | C31: 被审计单位本期不涉及其他资产的转让、外汇业务等事项。
B32: 折旧方法 | C32: 直线法，我们预计本年较上年无变化。
B33: 折旧费用 | C33: 因为被审计单位折旧方法和使用寿命没有变化，将与往年一样正常计提折旧；因此，我们预计本年度累计折旧较上年增加。
B34: 使用寿命变化 | C34: 由于本年度被审计单位的折旧政策未发生变化，我们预计被审计单位固定资产的使用寿命也不会发生变化。
B37: 波动范围
B38: ="波动幅度 ("&C8&"):" -> 波动幅度 (CNY): | C38: =$E$15 -> 10000000
B39: 波动幅度 (%): | C39: 0.1
B41: 我们获取或编制了与上期对比的重大账户（固定资产）引导表。我们将本期余额与试算平衡表核对一致，并将上期余额与上期审定数核对一致（如适用）。
B42: 我们将期末余额与上期余额进行对比。调查超出测试阈值（金额和百分比）的波动，以及代表异常或预期外变动或未发生预期中变动的波动，并确定其对我们计划实质性程序的影响 (如有)。
E45: |------- TB -------| | J45: |------- PY -------|
E46: ="货币/单位: "&C8 -> 货币/单位: CNY
E47: =$C$3 -> 0 | J47: =DATE(YEAR($C$3)-1,12,31) -> 693962 | K47: 本期和上期期末余额 | N47: 基于波动幅度判断，是否进一步调查？ | O47: 基于定性考虑判断，是否进一步调查？
B48: 总账科目编码 | C48: 科目名称 | D48: 索引号 | E48: 期末账面数 | F48: 账表调整数 | G48: 期末未审数 | H48: 审计调整数 | I48: 期末审定数 | J48: 上期末审定数 | K48: 变动金额 | L48: 变动% | M48: Notes
...

Sheet K.01 Agree SL to GL
B1: 标准工作底稿: K1 SWP 不动产、厂房和设备及相关账户（PPE）
B2: K.01 将明细账与总账核对一致
B4: 返回汇总页
B6: 获取上期末至本期末（或中期，如适用）固定资产及相关新增、处置、转让和折旧的后推明细表。（原值、累计折旧、减值均为正数填列，本期减少以负数填列，账表调整、审计调整数据均直接链接至K.00 Lead。）
B7: 我们将期初固定资产余额与上期审定数核对一致，将期末固定资产余额与固定资产明细账和试算表核对一致。我们调查了大于SAD的差异。我们将利润表金额（如，折旧费用）与试算表核对一致（如适用）。
B8: 我们选择了超过测试阈值的后推活动（如，新增、处置、固定资产转入、转移和折旧费用），以执行K.02和K.03的实质性程序。对于未包含在本程序表范围内的程序，我们交叉索引至完成该程序的单独程序表。我们评估了固定资产的转移和其他调整，以了解调整的性质，并确定是否需要执行额外程序。
B9: 表1 | Q9: 模具及工装 | T9: 其他 | Z9: |--------------------------- Rx ------------------------------|
Q10: 0 | T10: 27282584 | Z10: =N10+K10+H10+E10+Q10+T10 -> 27282584
Q11: =Q22-Q10 -> 25792832 | T11: =T22-T10 -> -25818767 | Z11: =Z22-Z10 -> 3.140594e+08
Q12: =Q10+Q11-Q22 -> 0 | T12: =T10+T11-T22 -> 0 | Z12: =Z10+Z11-Z22 -> 0
Q13: 0 | T13: 21804000 | Z13: =N13+K13+H13+E13+Q13+T13 -> 21804000
Q14: =Q29-Q13 -> 20357850 | T14: =T29-T13 -> -20383785 | Z14: =Z29-Z13 -> 2.201851e+08
Q15: =Q13+Q14-Q29 -> 0 | T15: =T13+T14-T29 -> 0 | Z15: =Z13+Z14-Z29 -> 0
Q16: 0 | T16: 0 | Z16: =N16+K16+H16+E16+Q16+T16 -> 0
Q17: =Q35-Q16 -> 0 | T17: =T35-T16 -> 0 | Z17: =Z35-Z16 -> 4695422.6
Q18: =Q16+Q17-Q35 -> 0 | T18: =T16+T17-T35 -> 0 | Z18: =Z16+Z17-Z35 -> 0
D20: 固定资产类别 | F20: 房屋建筑物 | I20: 机器设备 | L20: 运输设备 | O20: 电子产品及通讯设备 | R20: 模具及工装 | U20: 其他（办公用品） | X20: 【…】 | AA20: 合计
E21: 账面数 | F21: 账表调整/审计调整 | G21: 审定数 | H21: 账面数 | I21: 账表调整/审计调整 | J21: 审定数 | K21: 账面数 | L21: 账表调整/审计调整 | M21: 审定数 | N21: 账面数 | O21: 账表调整/审计调整 | P21: 审定数 | Q21: 账面数 | R21: 账表调整/审计调整 | S21: 审定数 | T21: 账面数 | U21: 账表调整/审计调整 | V21: 审定数 | W21: 账面数 | X21: 账表调整/审计调整 | Y21: 审定数 | Z21: 账面数 | AA21: 账表调整/审计调整 | AB21: 审定数 | AC21: CHECK
C22: 年初余额 | D22: PY | E22: 64532168 | G22: =SUM(E22:F22) -> 64532168 | H22: 233973775 | J22: =SUM(H22:I22) -> 233973775 | K22: 2132979.6 | M22: =SUM(K22:L22) -> 2132979.6 | N22: 13446411 | P22: =SUM(N22:O22) -> 13446411 | Q22: 25792832 | S22: =SUM(Q22:R22) -> 25792832 | T22: 1463816.9 | V22: =SUM(T22:U22) -> 1463816.9 | Y22: =SUM(W22:X22) -> 0 | Z22: =SUM(E22,H22,K22,N22,Q22,T22,W22) -> 3.4134198e+08 | AA22: =SUM(F22,I22,L22,O22,R22,U22,X22) -> 0 | AB22: =SUM(G22,J22,M22,P22,S22,V22,Y22) -> 3.4134198e+08 | AC22: =AB22-'K.00 Lead Sheet'!J49 -> 0
C23: 购置 | D23: K.02.1 | E23: 0 | G23: =SUM(E23:F23) -> 0 | H23: 0 | J23: =SUM(H23:I23) -> 0 | K23: 0 | M23: =SUM(K23:L23) -> 0 | N23: 0 | P23: =SUM(N23:O23) -> 0 | Q23: 0 | S23: =SUM(Q23:R23) -> 0 | T23: 0 | V23: =SUM(T23:U23) -> 0 | Y23: =SUM(W23:X23) -> 0 | Z23: =SUM(E23,H23,K23,N23,Q23,T23,W23) -> 0 | AA23: =SUM(F23,I23,L23,O23,R23,U23,X23) -> 0 | AB23: =SUM(G23,J23,M23,P23,S23,V23,Y23) -> 0
C24: 在建工程转入 | D24: J1.02 | E24: 0 | G24: =SUM(E24:F24) -> 0 | H24: -8679430.1 | J24: =SUM(H24:I24) -> -8679430.1 | K24: 0 | M24: =SUM(K24:L24) -> 0 | N24: 232399.14 | P24: =SUM(N24:O24) -> 232399.14 | Q24: 554038.09 | S24: =SUM(Q24:R24) -> 554038.09 | T24: 0 | V24: =SUM(T24:U24) -> 0 | Y24: =SUM(W24:X24) -> 0 | Z24: =SUM(E24,H24,K24,N24,Q24,T24,W24) -> -7892992.9 | AA24: =SUM(F24,I24,L24,O24,R24,U24,X24) -> 0 | AB24: =SUM(G24,J24,M24,P24,S24,V24,Y24) -> -7892992.9
B25: 原值 | C25: 处置或报废 | D25: K.02.2 | E25: 0 | G25: =SUM(E25:F25) -> 0 | H25: -13845172 | J25: =SUM(H25:I25) -> -13845172 | K25: 0 | M25: =SUM(K25:L25) -> 0 | N25: -154822.35 | P25: =SUM(N25:O25) -> -154822.35 | Q25: 0 | S25: =SUM(Q25:R25) -> 0 | T25: 0 | V25: =SUM(T25:U25) -> 0 | Y25: =SUM(W25:X25) -> 0 | Z25: =SUM(E25,H25,K25,N25,Q25,T25,W25) -> -13999994 | AA25: =SUM(F25,I25,L25,O25,R25,U25,X25) -> 0 | AB25: =SUM(G25,J25,M25,P25,S25,V25,Y25) -> -13999994
C26: 内部重分类 | E26: 100000 | G26: =SUM(E26:F26) -> 100000 | H26: 0 | J26: =SUM(H26:I26) -> 0 | K26: 0 | M26: =SUM(K26:L26) -> 0 | N26: 0 | P26: =SUM(N26:O26) -> 0 | Q26: 0 | S26: =SUM(Q26:R26) -> 0 | T26: 0 | V26: =SUM(T26:U26) -> 0 | Y26: =SUM(W26:X26) -> 0 | Z26: =SUM(E26,H26,K26,N26,Q26,T26,W26) -> 100000 | AA26: =SUM(F26,I26,L26,O26,R26,U26,X26) -> 0 | AB26: =SUM(G26,J26,M26,P26,S26,V26,Y26) -> 100000
C27: […] | E27: 0 | G27: =SUM(E27:F27) -> 0 | H27: 0 | J27: =SUM(H27:I27) -> 0 | K27: 0 | M27: =SUM(K27:L27) -> 0 | N27: 0 | P27: =SUM(N27:O27) -> 0 | Q27: 0 | S27: =SUM(Q27:R27) -> 0 | T27: 0 | V27: =SUM(T27:U27) -> 0 | Y27: =SUM(W27:X27) -> 0 | Z27: =SUM(E27,H27,K27,N27,Q27,T27,W27) -> 0 | AA27: =SUM(F27,I27,L27,O27,R27,U27,X27) -> 0 | AB27: =SUM(G27,J27,M27,P27,S27,V27,Y27) -> 0
C28: 年末余额 | D28: Rx | E28: =E22+E23+E24+E25+E26+E27 -> 64632168 | F28: =F22+F23+F24+F25+F26+F27 -> 0 | G28: =G22+G23+G24+G25+G26+G27 -> 64632168 | H28: =H22+H23+H24+H25+H26+H27 -> 2.1144917e+08 | I28: =I22+I23+I24+I25+I26+I27 -> 0 | J28: =J22+J23+J24+J25+J26+J27 -> 2.1144917e+08 | K28: =K22+K23+K24+K25+K26+K27 -> 2132979.6 | L28: =L22+L23+L24+L25+L26+L27 -> 0 | ... AB28: =AB22+AB23+AB24+AB25+AB26+AB27 -> 3.19549e+08 | AC28: =AB28-'K.00 Lead Sheet'!I49 -> -17358860
C29: 年初余额 | D29: PY | E29: 51909604 | G29: =SUM(E29:F29) -> 51909604 | H29: 1.5564889e+08 | J29: =SUM(H29:I29) -> 1.5564889e+08 | K29: 1618999.9 | M29: =SUM(K29:L29) -> 1618999.9 | N29: 11033543 | P29: =SUM(N29:O29) -> 11033543 | Q29: 20357850 | S29: =SUM(Q29:R29) -> 20357850 | T29: 1420215.2 | V29: =SUM(T29:U29) -> 1420215.2 | Y29: =SUM(W29:X29) -> 0 | Z29: =SUM(E29,H29,K29,N29,Q29,T29,W29) -> 2.419891e+08 | AA29: =SUM(F29,I29,L29,O29,R29,U29,X29) -> 0 | AB29: =SUM(G29,J29,M29,P29,S29,V29,Y29) -> 2.419891e+08 | AC29: =AB29-'K.00 Lead Sheet'!J50 -> 0
C30: 计提 | D30: K.03.2 | E30: 1241531.9 | G30: =SUM(E30:F30) -> 1241531.9 | H30: 15795304 | J30: =SUM(H30:I30) -> 15795304 | K30: 184110.39 | M30: =SUM(K30:L30) -> 184110.39 | N30: 886739.05 | P30: =SUM(N30:O30) -> 886739.05 | Q30: 1758895.4 | S30: =SUM(Q30:R30) -> 1758895.4 | T30: 29912.57 | V30: =SUM(T30:U30) -> 29912.57 | Y30: =SUM(W30:X30) -> 0 | Z30: =SUM(E30,H30,K30,N30,Q30,T30,W30) -> 19896494 | AA30: =SUM(F30,I30,L30,O30,R30,U30,X30) -> 0 | AB30: =SUM(G30,J30,M30,P30,S30,V30,Y30) -> 19896494 | AC30: <K.03 折旧测试>
B31: 累计折旧 | C31: 处置或报废 | D31: K.02.2 | E31: 0 | G31: =SUM(E31:F31) -> 0 | H31: 13638095 | J31: =SUM(H31:I31) -> 13638095 | K31: 0 | M31: =SUM(K31:L31) -> 0 | N31: -154822.35 | P31: =SUM(N31:O31) -> -154822.35 | Q31: 0 | S31: =SUM(Q31:R31) -> 0 | T31: 0 | V31: =SUM(T31:U31) -> 0 | Y31: =SUM(W31:X31) -> 0 | Z31: =SUM(E31,H31,K31,N31,Q31,T31,W31) -> 13483273 | AA31: =SUM(F31,I31,L31,O31,R31,U31,X31) -> 0 | AB31: =SUM(G31,J31,M31,P31,S31,V31,Y31) -> 13483273
C32: 内部重分类 | E32: 0 | G32: =SUM(E32:F32) -> 0 | H32: 0 | J32: =SUM(H32:I32) -> 0 | K32: 0 | M32: =SUM(K32:L32) -> 0 | N32: 0 | P32: =SUM(N32:O32) -> 0 | Q32: 0 | S32: =SUM(Q32:R32) -> 0 | T32: 0 | V32: =SUM(T32:U32) -> 0 | Y32: =SUM(W32:X32) -> 0 | Z32: =SUM(E32,H32,K32,N32,Q32,T32,W32) -> 0 | AA32: =SUM(F32,I32,L32,O32,R32,U32,X32) -> 0 | AB32: =SUM(G32,J32,M32,P32,S32,V32,Y32) -> 0
C33: […] | E33: 0 | G33: =SUM(E33:F33) -> 0 | H33: 0 | J33: =SUM(H33:I33) -> 0 | K33: 0 | M33: =SUM(K33:L33) -> 0 | N33: 0 | P33: =SUM(N33:O33) -> 0 | Q33: 0 | S33: =SUM(Q33:R33) -> 0 | T33: 0 | V33: =SUM(T33:U33) -> 0 | Y33: =SUM(W33:X33) -> 0 | Z33: =SUM(E33,H33,K33,N33,Q33,T33,W33) -> 0 | AA33: =SUM(F33,I33,L33,O33,R33,U33,X33) -> 0 | AB33: =SUM(G33,J33,M33,P33,S33,V33,Y33) -> 0
C34: 年末余额 | D34: Rx | E34: =E29+E30+E31+E32+E33 -> 53151136 | F34: =F29+F30+F31+F32+F33 -> 0 | G34: =G29+G30+G31+G32+G33 -> 53151136 | H34: =H29+H30+H31+H32+H33 -> 1.8508229e+08 | I34: =I29+I30+I31+I32+I33 -> 0 | J34: =J29+J30+J31+J32+J33 -> 1.8508229e+08 | K34: =K29+K30+K31+K32+K33 -> 1803110.2 | L34: =L29+L30+L31+L32+L33 -> 0 | ... AB34: =AB29+AB30+AB31+AB32+AB33 -> 2.7536887e+08 | AC34: =AB34-'K.00 Lead Sheet'!I50 -> 27276191
C35: 年初余额 | D35: PY | E35: 4162931.9 | G35: =SUM(E35:F35) -> 4162931.9 | H35: 510864.36 | J35: =SUM(H35:I35) -> 510864.36 | K35: 0 | M35: =SUM(K35:L35) -> 0 | N35: 21626.38 | P35: =SUM(N35:O35) -> 21626.38 | Q35: 0 | S35: =SUM(Q35:R35) -> 0 | T35: 0 | V35: =SUM(T35:U35) -> 0 | Y35: =SUM(W35:X35) -> 0 | Z35: =SUM(E35,H35,K35,N35,Q35,T35,W35) -> 4695422.6 | AA35: =SUM(F35,I35,L35,O35,R35,U35,X35) -> 0 | AB35: =SUM(G35,J35,M35,P35,S35,V35,Y35) -> 4695422.6 | AC35: =AB35-'K.00 Lead Sheet'!J51 -> 0
C36: 计提 | D36: SWP 减值 | E36: 0 | G36: =SUM(E36:F36) -> 0 | H36: 5902.72 | J36: =SUM(H36:I36) -> 5902.72 | K36: 0 | M36: =SUM(K36:L36) -> 0 | N36: 0 | P36: =SUM(N36:O36) -> 0 | Q36: 0 | S36: =SUM(Q36:R36) -> 0 | T36: 0 | V36: =SUM(T36:U36) -> 0 | Y36: =SUM(W36:X36) -> 0 | Z36: =SUM(E36,H36,K36,N36,Q36,T36,W36) -> 5902.72 | AA36: =SUM(F36,I36,L36,O36,R36,U36,X36) -> 0 | AB36: =SUM(G36,J36,M36,P36,S36,V36,Y36) -> 5902.72
B37: 减值准备 | C37: 处置或报废 | D37: K.02.2 | E37: 0 | G37: =SUM(E37:F37) -> 0 | H37: -207076.54 | J37: =SUM(H37:I37) -> -207076.54 | K37: 0 | M37: =SUM(K37:L37) -> 0 | N37: 0 | P37: =SUM(N37:O37) -> 0 | Q37: 0 | S37: =SUM(Q37:R37) -> 0 | T37: 0 | V37: =SUM(T37:U37) -> 0 | Y37: =SUM(W37:X37) -> 0 | Z37: =SUM(E37,H37,K37,N37,Q37,T37,W37) -> -207076.54 | AA37: =SUM(F37,I37,L37,O37,R37,U37,X37) -> 0 | AB37: =SUM(G37,J37,M37,P37,S37,V37,Y37) -> -207076.54
C38: 内部重分类 | E38: 0 | G38: =SUM(E38:F38) -> 0 | H38: 0 | J38: =SUM(H38:I38) -> 0 | K38: 0 | M38: =SUM(K38:L38) -> 0 | N38: 0 | P38: =SUM(N38:O38) -> 0 | Q38: 0 | S38: =SUM(Q38:R38) -> 0 | T38: 0 | V38: =SUM(T38:U38) -> 0 | Y38: =SUM(W38:X38) -> 0 | Z38: =SUM(E38,H38,K38,N38,Q38,T38,W38) -> 0 | AA38: =SUM(F38,I38,L38,O38,R38,U38,X38) -> 0 | AB38: =SUM(G38,J38,M38,P38,S38,V38,Y38) -> 0
C39: […] | E39: 0 | G39: =SUM(E39:F39) -> 0 | H39: 0 | J39: =SUM(H39:I39) -> 0 | K39: 0 | M39: =SUM(K39:L39) -> 0 | N39: 0 | P39: =SUM(N39:O39) -> 0 | Q39: 0 | S39: =SUM(Q39:R39) -> 0 | T39: 0 | V39: =SUM(T39:U39) -> 0 | Y39: =SUM(W39:X39) -> 0 | Z39: =SUM(E39,H39,K39,N39,Q39,T39,W39) -> 0 | AA39: =SUM(F39,I39,L39,O39,R39,U39,X39) -> 0 | AB39: =SUM(G39,J39,M39,P39,S39,V39,Y39) -> 0
C40: 年末余额 | D40: Rx | E40: =E35+E36+E37+E38+E39 -> 4162931.9 | F40: =F35+F36+F37+F38+F39 -> 0 | G40: =G35+G36+G37+G38+G39 -> 4162931.9 | H40: =H35+H36+H37+H38+H39 -> 309690.54 | I40: =I35+I36+I37+I38+I39 -> 0 | J40: =J35+J36+J37+J38+J39 -> 309690.54 | K40: =K35+K36+K37+K38+K39 -> 0 | L40: =L35+L36+L37+L38+L39 -> 0 | ... AB40: =AB35+AB36+AB37+AB38+AB39 -> 4494248.8 | AC40: =AB40-'K.00 Lead Sheet'!I51 -> 0
B41: 净值 (NBV) | C41: 年初余额 | D41: Rx | E41: =E22-E29-E35 -> 8459631.6 | F41: =F22-F29-F35 -> 0 | G41: =G22-G29-G35 -> 8459631.6 | H41: =H22-H29-H35 -> 77814018 | I41: =I22-I29-I35 -> 0 | J41: =J22-J29-J35 -> 77814018 | K41: =K22-K29-K35 -> 513979.72 | L41: =L22-L29-L35 -> 0 | ... AB41: =AB22-AB29-AB35 -> 94657455 | AC41: =AB41-'K.00 Lead Sheet'!J55 -> -1.6391277e-07
C42: 年末余额 | D42: Rx | E42: =E28-E34-E40 -> 7318099.7 | F42: =F28-F34-F40 -> 0 | G42: =G28-G34-G40 -> 7318099.7 | H42: =H28-H34-H40 -> 26057190 | I42: =I28-I34-I40 -> 0 | J42: =J28-J34-J40 -> 26057190 | K42: =K28-K34-K40 -> 329869.33 | L42: =L28-L34-L40 -> 0 | ... AB42: =AB28-AB34-AB40 -> 39685875 | AC42: =AB42-'K.00 Lead Sheet'!I55 -> -44535051
B43: 变动 | C43: 原值变动金额 | D43: 本年VS上年 | E43: =E28-E22 -> 100000 | G43: =G28-G22 -> 100000 | H43: =H28-H22 -> -22524602 | J43: =J28-J22 -> -22524602 | K43: =K28-K22 -> 0 | M43: =M28-M22 -> 0 | N43: =N28-N22 -> 77576.79 | P43: =P28-P22 -> 77576.79 | Q43: =Q28-Q22 -> 554038.09 | S43: =S28-S22 -> 554038.09 | T43: =T28-T22 -> 0 | V43: =V28-V22 -> 0 | W43: =W28-W22 -> 0 | Y43: =Y28-Y22 -> 0 | Z43: =Z28-Z22 -> -21792987 | AA43: =AA28-AA22 -> 0 | AB43: =AB28-AB22 -> -21792987
...

Sheet FA list
B1: 1.项目组可以自定义固定资产清单表格，也可直接使用系统导出的固定资产清单，但必须确保必需字段（固定资产类别、编号、名称、开始入账日期、使用寿命、残值率、原值、累计折旧、净值）完整。可参考链接： | W1: 返回汇总页
B2: 2.获取期末的固定资产明细清单，将固定资产明细清单的金额与K.01 Agree SL to GL 表1的金额进行核对，核对结果详见K.01 Agree SL to GL 表2，并调查大于SAD的差异。
B3: 3.固定资产的类别：请使用被审计单位的台账，无需对资产的类别添加自己的重分类修改。
B4: 4.如果折旧测试较难执行实质性分析程序或从实质性分析程序中获得的证据水平不足以得出审计结论，我们可在<FA List>中执行全量折旧测试，底稿形式可参考：
A7: 类别 | B7: 资产分类 | C7: 资产类别描述 | D7: 资产编号 | E7: 资本化日期 | F7: 资产次级编号 | G7: 存货号 | H7: 资产描述 | I7: 序列号 | J7: 原值 | K7: 本月折旧 | L7: 累计折旧 | M7: 本年累计折旧 | N7: 减值准备 | O7: 净值 | P7: 存货注记 | Q7: 报废日期 | R7: 资产类别编码 | S7: 用途 | T7: 使用地点 | U7: 使用人 | V7: 使用人(停用) | W7: 资产附加描述 | X7: 制造商 | Y7: 折旧方法 | Z7: 使用年限 | AA7: 使用年限（月） | AB7: 残值率 | AC7: 使用部门
A8: 机器设备 | B8: A0010 | C8: 固定资产-机械设备 | D8: 000010000001 | E8: 42333 | F8: 0000 | G8: 792A010110021911002 | H8: 精车机 | I8: 非标 | J8: 142177.38 | K8: 987.35 | L8: 119468.45 | M8: 11848.14 | N8: 0 | O8: 22708.93 | P8: 65-C-214 | R8: 20-制造 | S8: 01-制造 | T8: 100-起动机车间 | V8: 586-王西平、敖华卫 | W8: J14-791A-114 | X8: 长沙丹堡威自动化设备有限公司 | Y8: Z000 | Z8: 12 | AA8: =Z8*12 -> 144 | AB8: 0 | AC8: 3007030003起动机机加制造
A9: 机器设备 | B9: A0010 | C9: 固定资产-机械设备 | D9: 000010000002 | E9: 31747 | F9: 0000 | G9: 792A010110031911001 | H9: 普通车床 | I9: CM6125 | J9: 35934 | K9: 0 | L9: 35934 | M9: 0 | N9: 0 | O9: 0 | P9: 65-C-017 | R9: 20-制造 | S9: 01-制造 | T9: 101-发电机车间 | V9: 588-吕涛 | W9: . | X9: 济南一机 | Y9: Z000 | Z9: 36 | AA9: =Z9*12 -> 432 | AB9: 0 | AC9: 3006020003发电机转子制造
A10: 机器设备 | B10: A0010 | C10: 固定资产-机械设备 | D10: 000010000003 | E10: 38257 | F10: 0000 | G10: 792A010116020409001 | H10: 普通车床 | I10: C6140 | J10: 48080 | K10: 0 | L10: 48080 | M10: 0 | N10: 0 | O10: 0 | P10: 63-C121 | R10: 20-制造 | S10: 01-制造 | T10: 102-电子工厂设备保全科 | V10: 101-闫红卫 | W10: \ | X10: 上海第二机床厂 | Y10: Z000 | Z10: 12 | AA10: =Z10*12 -> 144 | AB10: 0 | AC10: 1016010000禁用工程技术制造组（制造一般费用）
A11: 机器设备 | B11: A0010 | C11: 固定资产-机械设备 | D11: 000010000007 | E11: 37955 | F11: 0000 | G11: 792A010120061911001 | H11: 二轴排钻 | I11: 65F200308 | J11: 9537.06 | K11: 0 | L11: 9537.06 | M11: 0 | N11: 0 | O11: 0 | P11: 65-Z-174 | R11: 20-制造 | S11: 01-制造 | T11: 101-发电机车间 | V11: 603-孟凡军 | W11: \ | X11: 电气公司 | Y11: Z000 | Z11: 12 | AA11: =Z11*12 -> 144 | AB11: 0 | AC11: 3006020003发电机转子制造
A12: 机器设备 | B12: A0010 | C12: 固定资产-机械设备 | D12: 000010000008 | E12: 33939 | F12: 0000 | G12: 792A010121081911001 | H12: 其它钻床、刨床和 | I12: ZXJ7016 | J12: 8100 | K12: 0 | L12: 8100 | M12: 0 | N12: 0 | O12: 0 | P12: 65-Z-123 | R12: 20-制造 | S12: 01-制造 | T12: 103-设备保全科 | W12: \ | X12: 杭州西湖台钻厂 | Y12: Z000 | Z12: 30 | AA12: =Z12*12 -> 360 | AB12: 0 | AC12: 1016010000禁用工程技术制造组（制造一般费用）
A13: 机器设备 | B13: A0010 | C13: 固定资产-机械设备 | D13: 000010000009 | E13: 33512 | F13: 0000 | G13: 792A010123019110002 | H13: 摇臂钻床 | I13: Z30 | J13: 44760 | K13: 0 | L13: 44760 | M13: 0 | N13: 0 | O13: 0 | P13: 63-Z017 | R13: 20-制造 | S13: 01-制造 | T13: 102-电子工厂设备保全科 | V13: 101-闫红卫 | W13: \ | X13: 沈阳中捷友谊厂 | Y13: Z000 | Z13: 31 | AA13: =Z13*12 -> 372 | AB13: 0 | AC13: 1016010000禁用工程技术制造组（制造一般费用）
A14: 机器设备 | B14: A0010 | C14: 固定资产-机械设备 | D14: 000010000010 | E14: 26238 | F14: 0000 | G14: 792A010124017111002 | H14: 单柱座标镗床 | I14: TS4132 | J14: 60810.56 | K14: 0 | L14: 60810.56 | M14: 0 | N14: 0 | O14: 0 | P14: 63-T001 | R14: 20-制造 | S14: 01-制造 | T14: 102-电子工厂设备保全科 | V14: 101-闫红卫 | W14: \ | X14: 北京机床厂 | Y14: Z000 | Z14: 51 | AA14: =Z14*12 -> 612 | AB14: 0 | AC14: 1016010000禁用工程技术制造组（制造一般费用）
A15: 机器设备 | B15: A0010 | C15: 固定资产-机械设备 | D15: 000010000011 | E15: 34304 | F15: 0000 | G15: 792A010124019312002 | H15: 坐标镗床（单柱） | I15: T4163C | J15: 520000 | K15: 0 | L15: 520000 | M15: 0 | N15: 0 | O15: 0 | P15: 63-T003 | R15: 20-制造 | S15: 01-制造 | T15: 102-电子工厂设备保全科 | V15: 101-闫红卫 | W15: \ | X15: 昆明机床厂 | Y15: Z000 | Z15: 29 | AA15: =Z15*12 -> 348 | AB15: 0 | AC15: 1016010000禁用工程技术制造组（制造一般费用）
A16: 机器设备 | B16: A0010 | C16: 固定资产-机械设备 | D16: 000010000013 | E16: 35034 | F16: 0000 | G16: 792A010131041911001 | H16: 外圆磨床 | I16: ME1332A | J16: 94915.12 | K16: 0 | L16: 94915.12 | M16: 0 | N16: 0 | O16: 0 | P16: 65-M-087 | R16: 20-制造 | S16: 01-制造 | T16: 101-发电机车间 | V16: 588-吕涛 | W16: \ | X16: 陕西机床厂 | Y16: Z000 | Z16: 12 | AA16: =Z16*12 -> 144 | AB16: 0 | AC16: 3006020003发电机转子制造
A17: 机器设备 | B17: A0010 | C17: 固定资产-机械设备 | D17: 000010000014 | E17: 43081 | F17: 0000 | G17: 792A010133011911001 | H17: 砂轮机 | I17: MC3025B | J17: 3760.68 | K17: 26.11 | L17: 2507.16 | M17: 313.38 | N17: 0 | O17: 1253.52 | P17: 65-QT-520 | R17: 20-制造 | S17: 01-制造 | T17: 105-新能源车间 | V17: 560-张全 | W17: I/791AF17165/01 | X17: 杭州临安西湖砂轮机厂 | Y17: Z000 | Z17: 12 | AA17: =Z17*12 -> 144 | AB17: 0 | AC17: 4006020003新能源组件制造
A18: 机器设备 | B18: A0010 | C18: 固定资产-机械设备 | D18: 000010000015 | E18: 43081 | F18: 0000 | G18: 792A010133011911002 | H18: 砂轮机 | I18: MC3025B | J18: 3760.68 | K18: 26.11 | L18: 2507.16 | M18: 313.38 | N18: 0 | O18: 1253.52 | P18: 65-QT-521 | R18: 20-制造 | S18: 01-制造 | T18: 101-发电机车间 | V18: 603-孟凡军 | W18: I/791AF17165/01 | X18: 杭州临安西湖砂轮机厂 | Y18: Z000 | Z18: 12 | AA18: =Z18*12 -> 144 | AB18: 0 | AC18: 3006020003发电机转子制造
A19: 机器设备 | B19: A0010 | C19: 固定资产-机械设备 | D19: 000010000016 | E19: 43081 | F19: 0000 | G19: 792A010133011911003 | H19: 砂轮机 | I19: MC3025B | J19: 3760.69 | K19: 26.11 | L19: 2507.17 | M19: 313.38 | N19: 0 | O19: 1253.52 | P19: 65-QT-522 | R19: 20-制造 | S19: 01-制造 | T19: 100-起动机车间 | W19: I/791AF17165/01 | X19: 杭州临安西湖砂轮机厂 | Y19: Z000 | Z19: 12 | AA19: =Z19*12 -> 144 | AB19: 0 | AC19: 3007030003起动机机加制造
A20: 机器设备 | B20: A0010 | C20: 固定资产-机械设备 | D20: 000010000017 | E20: 41990 | F20: 0000 | G20: 792A010133091911001 | H20: 金相试验磨抛机 | I20: MP-2 | J20: 2991.46 | K20: 20.77 | L20: 2742.16 | M20: 249.3 | N20: 0 | O20: 249.3 | P20: 65-QT-503 | R20: 20-制造 | S20: 01-制造 | T20: 106-质量管理部 | V20: 597-龚平 | W20: J14-791A-111 | X20: 上海光相制样设备有限公司 | Y20: Z000 | Z20: 12 | AA20: =Z20*12 -> 144 | AB20: 0 | AC20: 1009010000质量制造组（制造一般费用）
A21: 机器设备 | B21: A0010 | C21: 固定资产-机械设备 | D21: 000010000018 | E21: 41990 | F21: 0000 | G21: 792A010133091911002 | H21: 金相试样抛光机 | I21: P-2 | J21: 2991.45 | K21: 20.77 | L21: 2742.15 | M21: 249.3 | N21: 0 | O21: 249.3 | P21: 65-QT-504 | R21: 20-制造 | S21: 01-制造 | T21: 106-质量管理部 | V21: 597-龚平 | W21: J14-791A-111 | X21: 上海光相制样设备有限公司 | Y21: Z000 | Z21: 12 | AA21: =Z21*12 -> 144 | AB21: 0 | AC21: 1009010000质量制造组（制造一般费用）
A22: 机器设备 | B22: A0010 | C22: 固定资产-机械设备 | D22: 000010000020 | E22: 37336 | F22: 0000 | G22: 792A010166010203002 | H22: 卧式升降台铣床 | I22: B1-400K | J22: 201986.79 | K22: 0 | L22: 201986.79 | M22: 0 | N22: 0 | O22: 0 | P22: 63-X021 | R22: 20-制造 | S22: 01-制造 | T22: 102-电子工厂设备保全科 | V22: 101-闫红卫 | W22: \ | X22: 北京第一机床厂 | Y22: Z000 | Z22: 12 | AA22: =Z22*12 -> 144 | AB22: 0 | AC22: 1016010000禁用工程技术制造组（制造一般费用）
A23: 机器设备 | B23: A0010 | C23: 固定资产-机械设备 | D23: 000010000021 | E23: 31199 | F23: 0000 | G23: 792A010166011911001 | H23: 卧式升降台铣床 | I23: X62W(X6BZ) | J23: 93280 | K23: 0 | L23: 93280 | M23: 0 | N23: 0 | O23: 0 | P23: 65-X-004 | R23: 20-制造 | S23: 01-制造 | T23: 106-质量管理部 | V23: 610-黄禅军 | W23: \ | X23: 齐齐哈尔二机 | Y23: Z000 | Z23: 37 | AA23: =Z23*12 -> 444 | AB23: 0 | AC23: 1009010000质量制造组（制造一般费用）
A24: 机器设备 | B24: A0010 | C24: 固定资产-机械设备 | D24: 000010000023 | E24: 38818 | F24: 0000 | G24: 792A010168011911001 | H24: 工具铣床 | I24: X8130 | J24: 59304 | K24: 0 | L24: 59304 | M24: 0 | N24: 0 | O24: 0 | P24: 65-X-056 | R24: 20-制造 | S24: 01-制造 | T24: 103-设备保全科 | W24: J05-791A-104 | X24: 北京京仪世纪自动化设备有限公司 | Y24: Z000 | Z24: 12 | AA24: =Z24*12 -> 144 | AB24: 0 | AC24: 1016010000禁用工程技术制造组（制造一般费用）
A25: 机器设备 | B25: A0010 | C25: 固定资产-机械设备 | D25: 000010000024 | E25: 40889 | F25: 0000 | G25: 792A010169071911001 | H25: 下刻机 | I25: XK-2E | J25: 86859.63 | K25: 0 | L25: 86859.63 | M25: 0 | N25: 0 | O25: 0 | P25: 65-X-064 | R25: 20-制造 | S25: 01-制造 | T25: 100-起动机车间 | V25: 697-周高辉、王毅 | W25: J09-791A-129 | X25: 长沙捷翔科技发展有限公司 | Y25: Z000 | Z25: 12 | AA25: =Z25*12 -> 144 | AB25: 0 | AC25: 3007020003起动机初装制造
A26: 机器设备 | B26: A0010 | C26: 固定资产-机械设备 | D26: 000010000025 | E26: 41990 | F26: 0000 | G26: 792A010169071911002 | H26: 全自动下刻机 | I26: 非标 | J26: 131052.94 | K26: 910.09 | L26: 120131.87 | M26: 10921.08 | N26: 0 | O26: 10921.07 | P26: 65-X-069 | R26: 20-制造 | S26: 01-制造 | T26: 100-起动机车间 | V26: 697-周高辉、王毅 | W26: J13-791A-105 | X26: 长沙丹堡威自动化设备有限公司 | Y26: Z000 | Z26: 12 | AA26: =Z26*12 -> 144 | AB26: 0 | AC26: 3007030003起动机机加制造
A27: 机器设备 | B27: A0010 | C27: 固定资产-机械设备 | D27: 000010000026 | E27: 42789 | F27: 0000 | G27: 792A010169071911003 | H27: 全自动下刻机 | I27: 非标 | J27: 74013.83 | K27: 513.98 | L27: 54482.4 | M27: 6167.82 | N27: 0 | O27: 19531.43 | P27: 65-X-070 | R27: 20-制造 | S27: 01-制造 | T27: 100-起动机车间 | V27: 697-周高辉、王毅 | W27: J15-791A-115 | X27: 东风汽车电气有限公司 | Y27: Z000 | Z27: 12 | AA27: =Z27*12 -> 144 | AB27: 0 | AC27: 3007030003起动机机加制造
A28: 机器设备 | B28: A0010 | C28: 固定资产-机械设备 | D28: 000010000030 | E28: 37784 | F28: 0000 | G28: 792A010221010206001 | H28: 气动压力机 | I28: SQR-10A | J28: 11800 | K28: 0 | L28: 11800 | M28: 0 | N28: 0 | O28: 0 | P28: 63-YJ174 | R28: 20-制造 | S28: 01-制造 | T28: 108-电子工厂仪装车间 | V28: 106-朱成东 | W28: \ | X28: 上海第二锻压机床厂 | Y28: Z000 | Z28: 12 | AA28: =Z28*12 -> 144 | AB28: 0 | AC28: 2006030003仪装模块班制造
A29: 机器设备 | B29: A0010 | C29: 固定资产-机械设备 | D29: 000010000031 | E29: 38286 | F29: 0000 | G29: 792A010221010410001 | H29: 液压机 | I29: Y41-2.5T | J29: 19500 | K29: 0 | L29: 19500 | M29: 0 | N29: 0 | O29: 0 | P29: 63-YJ177 | R29: 20-制造 | S29: 01-制造 | T29: 107-电子工厂传装车间 | V29: 107-殷艳 | W29: \ | X29: 上海邺丰液压设备有限公司 | Y29: Z000 | Z29: 12 | AA29: =Z29*12 -> 144 | AB29: 0 | AC29: 2007030003传装电子班制造
A30: 机器设备 | B30: A0010 | C30: 固定资产-机械设备 | D30: 000010000032 | E30: 38286 | F30: 0000 | G30: 792A010221010410002 | H30: 液压机 | I30: Y41-2.5T | J30: 19500 | K30: 0 | L30: 19500 | M30: 0 | N30: 0 | O30: 0 | P30: 63-YJ178 | R30: 20-制造 | S30: 01-制造 | T30: 100-起动机车间 | U30: 徐向荣 | W30: \ | X30: 上海邺丰液压设备有限公司 | Y30: Z000 | Z30: 12 | AA30: =Z30*12 -> 144 | AB30: 0 | AC30: 3007020003起动机初装制造
A31: 机器设备 | B31: A0010 | C31: 固定资产-机械设备 | D31: 000010000033 | E31: 38286 | F31: 0000 | G31: 792A010221010410003 | H31: 液压机 | I31: Y41-2.5T | J31: 19500 | K31: 0 | L31: 19500 | M31: 0 | N31: 0 | O31: 0 | P31: 63-YJ179 | R31: 20-制造 | S31: 01-制造 | T31: 107-电子工厂传装车间 | V31: 107-殷艳 | W31: \ | X31: 上海邺丰液压设备有限公司 | Y31: Z000 | Z31: 12 | AA31: =Z31*12 -> 144 | AB31: 0 | AC31: 2007030003传装电子班制造
A32: 机器设备 | B32: A0010 | C32: 固定资产-机械设备 | D32: 000010000034 | E32: 41211 | F32: 0000 | G32: 792A010221011210001 | H32: 铆合液压机 | I32: Y41C-10 | J32: 38222.23 | K32: 0 | L32: 38222.23 | M32: 0 | N32: 0 | O32: 0 | P32: 63-YJ187 | R32: 20-制造 | S32: 01-制造 | T32: 107-电子工厂传装车间 | V32: 324-张娇 | W32: J11-7920-199 | X32: 天津第二锻压机床厂 | Y32: Z000 | Z32: 12 | AA32: =Z32*12 -> 144 | AB32: 0 | AC32: 2007020003传装水浮班制造
A33: 机器设备 | B33: A0010 | C33: 固定资产-机械设备 | D33: 000010000035 | E33: 32721 | F33: 0000 | G33: 792A010221018908001 | H33: 开式压力机 | I33: J23-16 | J33: 14000 | K33: 0 | L33: 14000 | M33: 0 | N33: 0 | O33: 0 | P33: 63-YJ008 | R33: 20-制造 | S33: 01-制造 | T33: 107-电子工厂传装车间 | V33: 109-李密 | W33: \ | X33: 上海第二锻压机床厂 | Y33: Z000 | Z33: 33 | AA33: =Z33*12 -> 396 | AB33: 0 | AC33: 2007050003传装丝印班制造
A34: 机器设备 | B34: A0010 | C34: 固定资产-机械设备 | D34: 000010000036 | E34: 33543 | F34: 0000 | G34: 792A010221019111001 | H34: 精密压力机 | I34: J94-4A | J34: 11000 | K34: 0 | L34: 11000 | M34: 0 | N34: 0 | O34: 0 | P34: 63-YJ113 | R34: 20-制造 | S34: 01-制造 | T34: 108-电子工厂仪装车间 | V34: 106-朱成东 | W34: \ | X34: 国营建光机器厂 | Y34: Z000 | Z34: 31 | AA34: =Z34*12 -> 372 | AB34: 0 | AC34: 2006030003仪装模块班制造
A35: 机器设备 | B35: A0010 | C35: 固定资产-机械设备 | D35: 000010000038 | E35: 33695 | F35: 0000 | G35: 792A010221019204001 | H35: 气动压力机 | I35: J135GBWN | J35: 4500 | K35: 0 | L35: 4500 | M35: 0 | N35: 0 | O35: 0 | P35: 63-YJ120 | R35: 20-制造 | S35: 01-制造 | T35: 108-电子工厂仪装车间 | V35: 106-朱成东 | W35: \ | X35: 江苏宝应电子工艺设备厂 | Y35: Z000 | Z35: 31 | AA35: =Z35*12 -> 372 | AB35: 0 | AC35: 2006030003仪装模块班制造
A36: 机器设备 | B36: A0010 | C36: 固定资产-机械设备 | D36: 000010000040 | E36: 33878 | F36: 0000 | G36: 792A010221019210002 | H36: 气动压力机 | I36: J1310/BD | J36: 6500 | K36: 0 | L36: 6500 | M36: 0 | N36: 0 | O36: 0 | P36: 63-YJ124 | R36: 20-制造 | S36: 01-制造 | T36: 108-电子工厂仪装车间 | V36: 106-朱成东 | W36: \ | X36: 江苏宝应电子工艺设备厂 | Y36: Z000 | Z36: 30 | AA36: =Z36*12 -> 360 | AB36: 0 | AC36: 2006030003仪装模块班制造
A37: 机器设备 | B37: A0010 | C37: 固定资产-机械设备 | D37: 000010000043 | E37: 35158 | F37: 0000 | G37: 792A010221019604003 | H37: 气动压机 | I37: JB1310 | J37: 7545.77 | K37: 0 | L37: 7545.77 | M37: 0 | N37: 0 | O37: 0 | P37: 63-YJ146 | R37: 20-制造 | S37: 01-制造 | T37: 108-电子工厂仪装车间 | V37: 106-朱成东 | W37: \ | X37: 江苏宝应电子工艺装备厂 | Y37: Z000 | Z37: 27 | AA37: =Z37*12 -> 324 | AB37: 0 | AC37: 2006030003仪装模块班制造
A38: 机器设备 | B38: A0010 | C38: 固定资产-机械设备 | D38: 000010000044 | E38: 35158 | F38: 0000 | G38: 792A010221019604006 | H38: 气动压机 | I38: JB1310 | J38: 7545.77 | K38: 0 | L38: 7545.77 | M38: 0 | N38: 0 | O38: 0 | P38: 63-YJ149 | R38: 20-制造 | S38: 01-制造 | T38: 108-电子工厂仪装车间 | V38: 106-朱成东 | W38: \ | X38: 江苏宝应电子工艺装备厂 | Y38: Z000 | Z38: 27 | AA38: =Z38*12 -> 324 | AB38: 0 | AC38: 2006030003仪装模块班制造
A39: 机器设备 | B39: A0010 | C39: 固定资产-机械设备 | D39: 000010000045 | E39: 35158 | F39: 0000 | G39: 792A010221019604007 | H39: 气动压机 | I39: JB1310 | J39: 7545.77 | K39: 0 | L39: 7545.77 | M39: 0 | N39: 0 | O39: 0 | P39: 63-YJ150 | R39: 20-制造 | S39: 01-制造 | T39: 108-电子工厂仪装车间 | V39: 106-朱成东 | W39: \ | X39: 江苏宝应电子工艺装备厂 | Y39: Z000 | Z39: 27 | AA39: =Z39*12 -> 324 | AB39: 0 | AC39: 2006030003仪装模块班制造
A40: 机器设备 | B40: A0010 | C40: 固定资产-机械设备 | D40: 000010000046 | E40: 36885 | F40: 0000 | G40: 792A010221030012002 | H40: 可倾斜压力机 | I40: J23-25 | J40: 30591.8 | K40: 0 | L40: 30591.8 | M40: 0 | N40: 0 | O40: 0 | P40: 63-YJ167 | R40: 20-制造 | S40: 01-制造 | T40: 107-电子工厂传装车间 | V40: 109-李密 | W40: \ | X40: 上海第二锻压机床厂 | Y40: Z000 | Z40: 12 | AA40: =Z40*12 -> 144 | AB40: 0 | AC40: 2007050003传装丝印班制造
A41: 机器设备 | B41: A0010 | C41: 固定资产-机械设备 | D41: 000010000047 | E41: 37435 | F41: 0000 | G41: 792A010221030206002 | H41: 开式可倾压力机 | I41: J23-40A | J41: 41600 | K41: 0 | L41: 41600 | M41: 0 | N41: 0 | O41: 0 | P41: 63-YJ171 | R41: 20-制造 | S41: 01-制造 | T41: 107-电子工厂传装车间 | V41: 109-李密 | W41: \ | X41: 上海第二锻压机床厂 | Y41: Z000 | Z41: 12 | AA41: =Z41*12 -> 144 | AB41: 0 | AC41: 2007050003传装丝印班制造
A42: 机器设备 | B42: A0010 | C42: 固定资产-机械设备 | D42: 000010000051 | E42: 41211 | F42: 0000 | G42: 792A010222011210001 | H42: 摆碾铆接机 | I42: GM10 | J42: 18346.11 | K42: 0 | L42: 18346.11 | M42: 0 | N42: 0 | O42: 0 | P42: 63-YJ188 | R42: 20-制造 | S42: 01-制造 | T42: 107-电子工厂传装车间 | V42: 107-殷艳 | W42: J11-7920-211 | X42: 武汉长江铆接机有限公司 | Y42: Z000 | Z42: 12 | AA42: =Z42*12 -> 144 | AB42: 0 | AC42: 2007030003传装电子班制造
...

Sheet K.02.1 新增测试 
B1: 标准工作底稿: K1 SWP 不动产、厂房和设备及相关账户（PPE）
B2: K.02.1：详细测试 (新增)
B4: 返回汇总页
B6: 记录我们的详细测试所涵盖的总体（指引：纳入充分的描述，以使经验丰富且之前与该项审计无关的审计师能够理解样本是如何选择的，例如，总体的分类或筛选。）
B7: 本期固定资产新增9,465k均为在建工程转入，已于<J1 在建工程 20251231 电驱动>底稿内进行转出测试。
B12: 购置总金额 | F12: =SUM(新增清单!J:J) -> 9465867.4
B13: Breakdown中购置金额 | F13: ='K.01 Agree SL to GL'!Z24 -> -7892992.9 | G13: K.01
B14: 差异 | F14: =F12-F13 -> 17358860 | G14: Rx | H14: 差异是否需要进一步调查？ | J14: =IF(ABS(F14)>'K.00 Lead Sheet'!$C$6,"是","否") -> 是
B16: 减：测试的关键项目 | F16: 0
B17: 进行代表性抽样的剩余总体 | F17: =F12-F16 -> 9465867.4
B19: 在下方描述选择关键项目的理由（请参阅Canvas指导工作流程的“关键项目”部分，包括信息图标）
B25: EY 测试属性解释:
B26: 对于每个被选中进行测试的项目，我们检查了相关的第三方证据以及相关的会计分录，并确定：
B27: 1) 测试样本于恰当的日期被正确资本化为固定资产（即，不应该费用化）。
B28: 2) 历史成本已根据适用的财务报告框架进行记录。
B29: 3) 管理层对测试项目采用的使用寿命和折旧方法是适当的（符合实体的会计政策和适用的财务报告框架）。
B30: 4) 该资产已被归入适当的固定资产类别。
N32: |------- Rx -------| | O32: EY Works
B33: 样本类型 | C33: 固定资产类别 | D33: 总账账户代码 | E33: 固定资产编号 | F33: 固定资产名称 | G33: 资产原价 | H33: 资本化日期 | I33: 使用寿命(月) | J33: 残值率 | K33: 折旧方法 | L33: 资产原价（通过审计证据/支持性文件取得） | M33: 获得的证据/支持的描述（例如，我们检查的控制权转移时点的单据/销售发票/合同/订单等） | N33: 资产原价差异 | O33: 1 | P33: 2 | Q33: 3 | R33: 4
B34: N/A
B39: 标记图例: 记录已识别的异常情况以及如何解决这些异常情况的详细信息，包括执行的其他实质性程序（指南：包括足够的描述，以使之前与审计无关的经验丰富的审计师能够理解执行的程序）。
B40: 不适用。

Sheet 新增清单
B2: 获取当期按类别划分的所有固定资产新增清单，并将该清单与固定资产后推核对一致。调查超过SAD名义金额的差额（例如，新增清单和后推明细表之间未被解释的差额）。 | U2: 返回汇总页
B4: 注：项目组可以自定义固定资产新增清单表格，也可直接使用系统导出的固定资产新增清单，但必须确保必需字段（固定资产类别、编号、名称、入账开始日期、原值、新增方式）完整。
A8: 类别 | B8: 资产分类 | C8: 资产类别描述 | D8: 资产编号 | E8: 资本化日期 | F8: 资产次级编号 | G8: 存货号 | H8: 资产描述 | I8: 序列号 | J8: 原值 | K8: 本月折旧 | L8: 本年累计折旧 | M8: 累计折旧 | N8: 减值准备 | O8: 净值 | P8: 存货注记 | Q8: 报废日期 | R8: 资产类别编码 | S8: 用途 | T8: 使用地点 | U8: 使用人 | V8: 使用人(停用) | W8: 资产附加描述 | X8: 制造商 | Y8: 折旧方法 | Z8: 使用年限 | AA8: 使用年限（月） | AB8: 残值率 | AC8: 使用部门
A9: 机器设备 | B9: A0010 | C9: 固定资产-机械设备 | D9: 000010000416 | E9: 45863 | F9: 0000 | G9: 792A010790002508003 | H9: 真空包装机 | I9: DZW-500B 蓝莓 | J9: 2743.36 | K9: 19.05 | L9: 57.15 | M9: 57.15 | N9: 0 | O9: 2686.21 | P9: 63-QT980 | R9: 20-制造 | S9: 01-制造 | T9: 131-电子工厂生产管理科 | U9: 电子库杨万云 | W9: I/7927O23002/01 | X9: 上海义光包装设备制造有限公司 | Y9: Z000 | Z9: 12 | AA9: 144 | AB9: 0 | AC9: 2002010000电子SCM部制造一般组(制造一般费用)
A10: 机器设备 | B10: A0010 | C10: 固定资产-机械设备 | D10: 000010000417 | E10: 45923 | F10: 0000 | G10: 792A010220012509001 | H10: 自动总成压合机 | I10: 非标 | J10: 88615.16 | K10: 615.38 | L10: 615.38 | M10: 615.38 | N10: 0 | O10: 87999.78 | P10: 63-ZX040-6 | R10: 20-制造 | S10: 01-制造 | T10: 108-电子工厂仪装车间 | U10: 仪装模块朱成东 | V10: 106-朱成东 | W10: I/7927A23028/01 | X10: 江苏烁范智能装备有限公司 | Y10: Z000 | Z10: 12 | AA10: 144 | AB10: 0 | AC10: 2006030003仪装模块班制造
A11: 机器设备 | B11: A0010 | C11: 固定资产-机械设备 | D11: 000010000418 | E11: 45923 | F11: 0000 | G11: 792A010750002509002 | H11: 在线激光打标机 | I11: 非标 | J11: 22646.1 | K11: 157.26 | L11: 157.26 | M11: 157.26 | N11: 0 | O11: 22488.84 | P11: 63-ZX040-8 | R11: 20-制造 | S11: 01-制造 | T11: 108-电子工厂仪装车间 | U11: 仪装模块朱成东 | V11: 106-朱成东 | W11: I/7927A23028/01 | X11: 江苏烁范智能装备有限公司 | Y11: Z000 | Z11: 12 | AA11: 144 | AB11: 0 | AC11: 2006030003仪装模块班制造
A12: 机器设备 | B12: A0010 | C12: 固定资产-机械设备 | D12: 000010000419 | E12: 45924 | F12: 0000 | G12: 792A010750002509001 | H12: 在线激光打标机 | I12: 非标 | J12: 87363.66 | K12: 606.69 | L12: 606.69 | M12: 606.69 | N12: 0 | O12: 86756.97 | P12: 63-ZX041-7 | R12: 20-制造 | S12: 01-制造 | T12: 108-电子工厂仪装车间 | U12: 仪装仪表肖芃 | V12: 108-肖芃 | W12: I/7927D23016/01-01 | X12: 江苏烁范智能装备有限公司 | Y12: Z000 | Z12: 12 | AA12: 144 | AB12: 0 | AC12: 2006010003仪装仪表班制造
A13: 机器设备 | B13: A0030 | C13: 固定资产-动力设备-管道除外 | D13: 000030000149 | E13: 45733 | F13: 0000 | G13: 792A021116002503001 | H13: 清洁机 | I13: CGBF-300 | J13: 44053.1 | K13: 305.92 | L13: 2141.47 | M13: 2141.47 | N13: 0 | O13: 41911.63 | P13: 63-DH062-1 | R13: 20-制造 | S13: 01-制造 | T13: 108-电子工厂仪装车间 | U13: 肖芃 | V13: 108-肖芃 | W13: I/7927A24049/01 | X13: 苏州康贝尔电子设备有限公司 | Y13: Z000 | Z13: 12 | AA13: 144 | AB13: 0 | AC13: 2006010003仪装仪表班制造
A14: 机器设备 | B14: A0030 | C14: 固定资产-动力设备-管道除外 | D14: 000030000150 | E14: 45826 | F14: 0000 | G14: 792A021402002506001 | H14: 水泵机组 | J14: 84955.76 | K14: 589.97 | L14: 2359.88 | M14: 2359.88 | N14: 0 | O14: 82595.88 | P14: 63-DN1000 | R14: 20-制造 | S14: 01-制造 | T14: 102-电子工厂设备保全科 | U14: 唐磊 | W14: I/7927F25013/01 | X14: 湖北堰起新能源发展有限公司 | Y14: Z000 | Z14: 12 | AA14: 144 | AB14: 0 | AC14: 2001010000电子生产部制造组(制造一般费)
A15: 机器设备 | B15: A0030 | C15: 固定资产-动力设备-管道除外 | D15: 000030000151 | E15: 45958 | F15: 0000 | G15: 792A020711002510001 | H15: 潍柴WP14T63OE62发动机 | I15: WP14TG765E304 | J15: 146460.18 | K15: 0 | L15: 0 | M15: 0 | N15: 0 | O15: 146460.18 | P15: 63-QT985 | R15: 30-研发 | S15: 02-研发 | T15: 109-研发管理部 | U15: 试验中心陈刚 | V15: 435-陈刚 | W15: I/7927L25015/01 | X15: 潍柴（山东）动力总成有限公司 | Y15: Z000 | Z15: 12 | AA15: 144 | AB15: 0 | AC15: 1008010000研发管理部（研发费）
A16: 机器设备 | B16: A0030 | C16: 固定资产-动力设备-管道除外 | D16: 000030000152 | E16: 45958 | F16: 0000 | G16: 792A020810002510001 | H16: 东津新能源生产阵地尾气处理系统 | I16: SH-27K | J16: 698407.31 | K16: 0 | L16: 0 | M16: 0 | N16: 0 | O16: 698407.31 | P16: 65-DF-143 | R16: 20-制造 | S16: 01-制造 | T16: 105-新能源车间 | U16: 新能源东津定子班 | V16: 560-张全 | W16: I/7927H23003/01 | X16: 湖北胜豪智能科技有限公司 | Y16: Z000 | Z16: 12 | AA16: 144 | AB16: 0 | AC16: 4006010003新能源电机制造
A17: 机器设备 | B17: A0060 | C17: 固定资产-工业炉窑 | D17: 000060000025 | E17: 45923 | F17: 0000 | G17: 792A040519002509006 | H17: 老化测试炉 | I17: 非标 | J17: 72019.01 | K17: 600.16 | L17: 600.16 | M17: 600.16 | N17: 0 | O17: 71418.85 | P17: 63-ZX040-9 | R17: 20-制造 | S17: 01-制造 | T17: 108-电子工厂仪装车间 | U17: 仪装模块朱成东 | V17: 106-朱成东 | W17: I/7927A23028/01 | X17: 江苏烁范智能装备有限公司 | Y17: Z000 | Z17: 10 | AA17: 120 | AB17: 0 | AC17: 2006030003仪装模块班制造
A18: 机器设备 | B18: A0060 | C18: 固定资产-工业炉窑 | D18: 000060000026 | E18: 45923 | F18: 0000 | G18: 792A040519002509007 | H18: 老化测试炉 | I18: 非标 | J18: 72019.01 | K18: 600.16 | L18: 600.16 | M18: 600.16 | N18: 0 | O18: 71418.85 | P18: 63-ZX040-10 | R18: 20-制造 | S18: 01-制造 | T18: 108-电子工厂仪装车间 | U18: 仪装模块朱成东 | V18: 106-朱成东 | W18: I/7927A23028/01 | X18: 江苏烁范智能装备有限公司 | Y18: Z000 | Z18: 10 | AA18: 120 | AB18: 0 | AC18: 2006030003仪装模块班制造
A19: 机器设备 | B19: A0060 | C19: 固定资产-工业炉窑 | D19: 000060000027 | E19: 45923 | F19: 0000 | G19: 792A040519002509008 | H19: 老化测试炉 | I19: 非标 | J19: 72019.01 | K19: 600.16 | L19: 600.16 | M19: 600.16 | N19: 0 | O19: 71418.85 | P19: 63-ZX040-11 | R19: 20-制造 | S19: 01-制造 | T19: 108-电子工厂仪装车间 | U19: 仪装模块朱成东 | V19: 106-朱成东 | W19: I/7927A23028/01 | X19: 江苏烁范智能装备有限公司 | Y19: Z000 | Z19: 10 | AA19: 120 | AB19: 0 | AC19: 2006030003仪装模块班制造
A20: 机器设备 | B20: A0060 | C20: 固定资产-工业炉窑 | D20: 000060000028 | E20: 45923 | F20: 0000 | G20: 792A040519002509009 | H20: 老化测试炉 | I20: 非标 | J20: 72019.01 | K20: 600.16 | L20: 600.16 | M20: 600.16 | N20: 0 | O20: 71418.85 | P20: 63-ZX040-12 | R20: 20-制造 | S20: 01-制造 | T20: 108-电子工厂仪装车间 | U20: 仪装模块朱成东 | V20: 106-朱成东 | W20: I/7927A23028/01 | X20: 江苏烁范智能装备有限公司 | Y20: Z000 | Z20: 10 | AA20: 120 | AB20: 0 | AC20: 2006030003仪装模块班制造
A21: 机器设备 | B21: A0060 | C21: 固定资产-工业炉窑 | D21: 000060000029 | E21: 45923 | F21: 0000 | G21: 792A040519002509010 | H21: 老化测试炉 | I21: 非标 | J21: 72019.01 | K21: 600.16 | L21: 600.16 | M21: 600.16 | N21: 0 | O21: 71418.85 | P21: 63-ZX040-13 | R21: 20-制造 | S21: 01-制造 | T21: 108-电子工厂仪装车间 | U21: 仪装模块朱成东 | V21: 106-朱成东 | W21: I/7927A23028/01 | X21: 江苏烁范智能装备有限公司 | Y21: Z000 | Z21: 10 | AA21: 120 | AB21: 0 | AC21: 2006030003仪装模块班制造
A22: 机器设备 | B22: A0060 | C22: 固定资产-工业炉窑 | D22: 000060000030 | E22: 45924 | F22: 0000 | G22: 792A040519002509001 | H22: 老化测试炉 | I22: 非标 | J22: 99012.14 | K22: 825.1 | L22: 825.1 | M22: 825.1 | N22: 0 | O22: 98187.04 | P22: 63-ZX041-8 | R22: 20-制造 | S22: 01-制造 | T22: 108-电子工厂仪装车间 | U22: 仪装仪表肖芃 | V22: 108-肖芃 | W22: I/7927D23016/01-01 | X22: 江苏烁范智能装备有限公司 | Y22: Z000 | Z22: 10 | AA22: 120 | AB22: 0 | AC22: 2006010003仪装仪表班制造
A23: 机器设备 | B23: A0060 | C23: 固定资产-工业炉窑 | D23: 000060000031 | E23: 45924 | F23: 0000 | G23: 792A040519002509002 | H23: 老化测试炉 | I23: 非标 | J23: 99012.14 | K23: 825.1 | L23: 825.1 | M23: 825.1 | N23: 0 | O23: 98187.04 | P23: 63-ZX041-9 | R23: 20-制造 | S23: 01-制造 | T23: 108-电子工厂仪装车间 | U23: 仪装仪表肖芃 | V23: 108-肖芃 | W23: I/7927D23016/01-01 | X23: 江苏烁范智能装备有限公司 | Y23: Z000 | Z23: 10 | AA23: 120 | AB23: 0 | AC23: 2006010003仪装仪表班制造
A24: 机器设备 | B24: A0060 | C24: 固定资产-工业炉窑 | D24: 000060000032 | E24: 45924 | F24: 0000 | G24: 792A040519002509003 | H24: 老化测试炉 | I24: 非标 | J24: 99012.14 | K24: 825.1 | L24: 825.1 | M24: 825.1 | N24: 0 | O24: 98187.04 | P24: 63-ZX041-10 | R24: 20-制造 | S24: 01-制造 | T24: 108-电子工厂仪装车间 | U24: 仪装仪表肖芃 | V24: 108-肖芃 | W24: I/7927D23016/01-01 | X24: 江苏烁范智能装备有限公司 | Y24: Z000 | Z24: 10 | AA24: 120 | AB24: 0 | AC24: 2006010003仪装仪表班制造
A25: 机器设备 | B25: A0060 | C25: 固定资产-工业炉窑 | D25: 000060000033 | E25: 45924 | F25: 0000 | G25: 792A040519002509004 | H25: 老化测试炉 | I25: 非标 | J25: 99012.14 | K25: 825.1 | L25: 825.1 | M25: 825.1 | N25: 0 | O25: 98187.04 | P25: 63-ZX041-11 | R25: 20-制造 | S25: 01-制造 | T25: 108-电子工厂仪装车间 | U25: 仪装仪表肖芃 | V25: 108-肖芃 | W25: I/7927D23016/01-01 | X25: 江苏烁范智能装备有限公司 | Y25: Z000 | Z25: 10 | AA25: 120 | AB25: 0 | AC25: 2006010003仪装仪表班制造
A26: 机器设备 | B26: A0060 | C26: 固定资产-工业炉窑 | D26: 000060000034 | E26: 45924 | F26: 0000 | G26: 792A040519002509005 | H26: 老化测试炉 | I26: 非标 | J26: 99012.14 | K26: 825.1 | L26: 825.1 | M26: 825.1 | N26: 0 | O26: 98187.04 | P26: 63-ZX041-12 | R26: 20-制造 | S26: 01-制造 | T26: 108-电子工厂仪装车间 | U26: 仪装仪表肖芃 | V26: 108-肖芃 | W26: I/7927D23016/01-01 | X26: 江苏烁范智能装备有限公司 | Y26: Z000 | Z26: 10 | AA26: 120 | AB26: 0 | AC26: 2006010003仪装仪表班制造
... A45: 机器设备 | B45: A0070 | C45: 固定资产-自动化控制及汽车生产专用设备 | D45: 000070000117 | E45: 45924 | F45: 0000 | G45: 792A050430002509004 | H45: 老化上下料机械手 | I45: 非标 | J45: 174727.31 | K45: 1820.08 | L45: 1820.08 | M45: 1820.08 | N45: 0 | O45: 172907.23 | P45: 63-ZX041-14 | R45: 20-制造 | S45: 01-制造 | T45: 108-电子工厂仪装车间 | U45: 仪装仪表肖芃 | V45: 108-肖芃 | W45: I/7927D23016/01-01 | X45: 江苏烁范智能装备有限公司 | Y45: Z000 | Z45: 8 | AA45: 96 | AB45: 0 | AC45: 2006010003仪装仪表班制造
A46: 机器设备 | B46: A0090 | C46: 固定资产-检测设备 | D46: 000090000476 | E46: 45803 | F46: 0000 | G46: 792A070606992505001 | H46: 压力传感器校验设备 | I46: 非标 | J46: 51681.42 | K46: 717.8 | L46: 3588.99 | M46: 3588.99 | N46: 0 | O46: 48092.43 | P46: 63-CL1406 | R46: 20-制造 | S46: 01-制造 | T46: 107-电子工厂传装车间 | U46: 丁伦丽 | W46: I/7927A24017/01 | X46: 东风电驱动系统有限公司技术质量科装备技术室 | Y46: Z000 | Z46: 6 | AA46: 72 | AB46: 0 | AC46: 2007010003传装报警器制造
A47: 机器设备 | B47: A0090 | C47: 固定资产-检测设备 | D47: 000090000477 | E47: 45803 | F47: 0000 | G47: 792A070606992505002 | H47: 压力传感器检测设备 | I47: 非标 | J47: 51681.41 | K47: 717.8 | L47: 3588.99 | M47: 3588.99 | N47: 0 | O47: 48092.42 | P47: 63-CL1407 | R47: 20-制造 | S47: 01-制造 | T47: 107-电子工厂传装车间 | U47: 丁伦丽 | W47: I/7927A24017/01 | X47: 东风电驱动系统有限公司技术质量科装备技术室 | Y47: Z000 | Z47: 6 | AA47: 72 | AB47: 0 | AC47: 2007010003传装报警器制造
A48: 机器设备 | B48: A0090 | C48: 固定资产-检测设备 | D48: 000090000478 | E48: 45827 | F48: 0000 | G48: 792A070700002506001 | H48: 起动机齿轮照相防错设备 | I48: CLFC-A | J48: 100000 | K48: 1388.89 | L48: 5555.56 | M48: 5555.56 | N48: 0 | O48: 94444.44 | P48: 65-ZK-551 | R48: 20-制造 | S48: 01-制造 | T48: 100-起动机车间 | U48: 柴俊 | W48: I/7927D24001/01 | X48: 湖北匠达智能装备有限公司 | Y48: Z000 | Z48: 6 | AA48: 72 | AB48: 0 | AC48: 3007010003起动机装配制造
A49: 机器设备 | B49: A0090 | C49: 固定资产-检测设备 | D49: 000090000479 | E49: 45863 | F49: 0000 | G49: 792A070401042508003 | H49: 电子显微镜/工业锡锅 | I49: AO-HK830-0318 | J49: 9823.01 | K49: 136.43 | L49: 409.29 | M49: 409.29 | N49: 0 | O49: 9413.72 | P49: 63EP-070 | R49: 20-制造 | S49: 01-制造 | T49: 131-电子工厂生产管理科 | U49: 电子库杨万云 | W49: I/7927O23002/01 | X49: 奥斯微（AOSVI） | Y49: Z000 | Z49: 6 | AA49: 72 | AB49: 0 | AC49: 2002010000电子SCM部制造一般组(制造一般费用)
A50: 机器设备 | B50: A0090 | C50: 固定资产-检测设备 | D50: 000090000480 | E50: 45923 | F50: 0000 | G50: 792A070606992509004 | H50: 烧录/功能检测测试台 | I50: 非标 | J50: 113230.49 | K50: 1572.65 | L50: 1572.65 | M50: 1572.65 | N50: 0 | O50: 111657.84 | P50: 63-ZX040-2 | R50: 20-制造 | S50: 01-制造 | T50: 108-电子工厂仪装车间 | U50: 仪装模块朱成东 | V50: 106-朱成东 | W50: I/7927A23028/01 | X50: 江苏烁范智能装备有限公司 | Y50: Z000 | Z50: 6 | AA50: 72 | AB50: 0 | AC50: 2006030003仪装模块班制造
A51: 机器设备 | B51: A0090 | C51: 固定资产-检测设备 | D51: 000090000481 | E51: 45923 | F51: 0000 | G51: 792A070606992509005 | H51: 总成视觉检测设备 | I51: 非标 | J51: 142768.88 | K51: 1982.9 | L51: 1982.9 | M51: 1982.9 | N51: 0 | O51: 140785.98 | P51: 63-ZX040-16 | R51: 20-制造 | S51: 01-制造 | T51: 108-电子工厂仪装车间 | U51: 仪装模块朱成东 | V51: 106-朱成东 | W51: I/7927A23028/01 | X51: 江苏烁范智能装备有限公司 | Y51: Z000 | Z51: 6 | AA51: 72 | AB51: 0 | AC51: 2006030003仪装模块班制造
A52: 机器设备 | B52: A0090 | C52: 固定资产-检测设备 | D52: 000090000482 | E52: 45923 | F52: 0000 | G52: 792A070606992509006 | H52: 总成视觉检测设备 | I52: 非标 | J52: 142768.88 | K52: 1982.9 | L52: 1982.9 | M52: 1982.9 | N52: 0 | O52: 140785.98 | P52: 63-ZX040-17 | R52: 20-制造 | S52: 01-制造 | T52: 108-电子工厂仪装车间 | U52: 仪装模块朱成东 | V52: 106-朱成东 | W52: I/7927A23028/01 | X52: 江苏烁范智能装备有限公司 | Y52: Z000 | Z52: 6 | AA52: 72 | AB52: 0 | AC52: 2006030003仪装模块班制造
A53: 机器设备 | B53: A0090 | C53: 固定资产-检测设备 | D53: 000090000483 | E53: 45924 | F53: 0000 | G53: 792A070606992509001 | H53: 组合仪表程序烧录/功能检测测试台 | I53: 非标 | J53: 362073.81 | K53: 5028.8 | L53: 5028.8 | M53: 5028.8 | N53: 0 | O53: 357045.01 | P53: 63-ZX041-2 | R53: 20-制造 | S53: 01-制造 | T53: 108-电子工厂仪装车间 | U53: 仪装仪表肖芃 | V53: 108-肖芃 | W53: I/7927D23016/01-01 | X53: 江苏烁范智能装备有限公司 | Y53: Z000 | Z53: 6 | AA53: 72 | AB53: 0 | AC53: 2006010003仪装仪表班制造
A54: 机器设备 | B54: A0090 | C54: 固定资产-检测设备 | D54: 000090000484 | E54: 45924 | F54: 0000 | G54: 792A070606992509002 | H54: 组合仪表检测设备1 | I54: 非标 | J54: 184434.38 | K54: 2561.59 | L54: 2561.59 | M54: 2561.59 | N54: 0 | O54: 181872.79 | P54: 63-ZX041-21 | R54: 20-制造 | S54: 01-制造 | T54: 108-电子工厂仪装车间 | U54: 仪装仪表肖芃 | V54: 108-肖芃 | W54: I/7927D23016/01-01 | X54: 江苏烁范智能装备有限公司 | Y54: Z000 | Z54: 6 | AA54: 72 | AB54: 0 | AC54: 2006010003仪装仪表班制造
A55: 机器设备 | B55: A0090 | C55: 固定资产-检测设备 | D55: 000090000485 | E55: 45924 | F55: 0000 | G55: 792A070606992509003 | H55: 组合仪表检测设备2 | I55: 非标 | J55: 184434.38 | K55: 2561.59 | L55: 2561.59 | M55: 2561.59 | N55: 0 | O55: 181872.79 | P55: 63-ZX041-22 | R55: 20-制造 | S55: 01-制造 | T55: 108-电子工厂仪装车间 | U55: 仪装仪表肖芃 | V55: 108-肖芃 | W55: I/7927D23016/01-01 | X55: 江苏烁范智能装备有限公司 | Y55: Z000 | Z55: 6 | AA55: 72 | AB55: 0 | AC55: 2006010003仪装仪表班制造
A56: 机器设备 | B56: A0090 | C56: 固定资产-检测设备 | D56: 000090000486 | E56: 45958 | F56: 0000 | G56: 792A070301992510001 | H56: 同星12路CAN工具 | I56: 2EA75414A71F3374 | J56: 21017.7 | K56: 0 | L56: 0 | M56: 0 | N56: 0 | O56: 21017.7 | P56: 63-CL1417-1 | R56: 30-研发 | S56: 02-研发 | T56: 109-研发管理部 | U56: 办公楼407饶旭 | W56: I/7927L25014/01 | X56: 上海同星智能科技有限公司 | Y56: Z000 | Z56: 6 | AA56: 72 | AB56: 0 | AC56: 1008010000研发管理部（研发费）
A57: 机器设备 | B57: A0090 | C57: 固定资产-检测设备 | D57: 000090000487 | E57: 45958 | F57: 0000 | G57: 792A070301992510002 | H57: 同星12路CAN工具 | I57: 2EA75414A71F3374 | J57: 21017.7 | K57: 0 | L57: 0 | M57: 0 | N57: 0 | O57: 21017.7 | P57: 63-CL1417-1 | R57: 30-研发 | S57: 02-研发 | T57: 109-研发管理部 | U57: 办公楼407饶旭 | W57: I/7927L25014/01 | X57: 上海同星智能科技有限公司 | Y57: Z000 | Z57: 6 | AA57: 72 | AB57: 0 | AC57: 1008010000研发管理部（研发费）
A58: 机器设备 | B58: A0100 | C58: 固定资产-试验设备 | D58: 000100000458 | E58: 45733 | F58: 0000 | G58: 792A080601042503001 | H58: 快速温变湿热箱 | I58: SC7-1000/14 | J58: 277433.63 | K58: 3853.24 | L58: 26972.71 | M58: 26972.71 | N58: 0 | O58: 250460.92 | P58: 63-RH169 | R58: 30-研发 | S58: 02-研发 | T58: 109-研发管理部 | U58: 张贤杰 | V58: 168-张贤杰 | W58: I/7927L24009/01 | X58: 重庆银河试验仪器有限公司 | Y58: Z000 | Z58: 6 | AA58: 72 | AB58: 0 | AC58: 1008010000研发管理部（研发费）
A59: 机器设备 | B59: A0100 | C59: 固定资产-试验设备 | D59: 000100000459 | E59: 45733 | F59: 0000 | G59: 792A080601022503001 | H59: 高温箱 | I59: WG301 | J59: 43510.32 | K59: 604.31 | L59: 4230.17 | M59: 4230.17 | N59: 0 | O59: 39280.15 | P59: 63-RH170 | R59: 30-研发 | S59: 02-研发 | T59: 109-研发管理部 | U59: 张贤杰 | V59: 168-张贤杰 | W59: I/7927L24019/01 | X59: 重庆银河试验仪器有限公司 | Y59: Z000 | Z59: 6 | AA59: 72 | AB59: 0 | AC59: 1008010000研发管理部（研发费）
A60: 机器设备 | B60: A0100 | C60: 固定资产-试验设备 | D60: 000100000460 | E60: 45733 | F60: 0000 | G60: 792A080601022503002 | H60: 高温箱 | I60: WG301 | J60: 43510.32 | K60: 604.31 | L60: 4230.17 | M60: 4230.17 | N60: 0 | O60: 39280.15 | P60: 63-RH171 | R60: 30-研发 | S60: 02-研发 | T60: 109-研发管理部 | U60: 张贤杰 | V60: 168-张贤杰 | W60: I/7927L24019/01 | X60: 重庆银河试验仪器有限公司 | Y60: Z000 | Z60: 6 | AA60: 72 | AB60: 0 | AC60: 1008010000研发管理部（研发费）
A61: 机器设备 | B61: A0100 | C61: 固定资产-试验设备 | D61: 000100000461 | E61: 45733 | F61: 0000 | G61: 792A080601022503003 | H61: 高温箱 | I61: WG301 | J61: 43510.33 | K61: 604.31 | L61: 4230.17 | M61: 4230.17 | N61: 0 | O61: 39280.16 | P61: 63-RH172 | R61: 30-研发 | S61: 02-研发 | T61: 109-研发管理部 | U61: 张贤杰 | V61: 168-张贤杰 | W61: I/7927L24019/01 | X61: 重庆银河试验仪器有限公司 | Y61: Z000 | Z61: 6 | AA61: 72 | AB61: 0 | AC61: 1008010000研发管理部（研发费）
A62: 机器设备 | B62: A0100 | C62: 固定资产-试验设备 | D62: 000100000462 | E62: 45854 | F62: 0000 | G62: 792A080303072507002 | H62: 大功率直流电源 | I62: IT6005D-80-150 | J62: 35988.2 | K62: 499.84 | L62: 1499.51 | M62: 1499.51 | N62: 0 | O62: 34488.69 | P62: 63-ZK483 | R62: 30-研发 | S62: 02-研发 | T62: 109-研发管理部 | U62: 张贤杰 | W62: I/7927L25010/01 | X62: 艾德克斯电子有限公司 | Y62: Z000 | Z62: 6 | AA62: 72 | AB62: 0 | AC62: 1008010000研发管理部（研发费）
A63: 机器设备 | B63: A0100 | C63: 固定资产-试验设备 | D63: 000100000463 | E63: 45854 | F63: 0000 | G63: 792A080303072507001 | H63: 大功率直流电源 | I63: IT6005D-80-150 | J63: 35988.2 | K63: 499.84 | L63: 1499.51 | M63: 1499.51 | N63: 0 | O63: 34488.69 | P63: 63-ZK484 | R63: 30-研发 | S63: 02-研发 | T63: 109-研发管理部 | U63: 张贤杰 | W63: I/7927L25010/01 | X63: 艾德克斯电子有限公司 | Y63: Z000 | Z63: 6 | AA63: 72 | AB63: 0 | AC63: 1008010000研发管理部（研发费）
...

Sheet K.02.2 处置测试
B1: 标准工作底稿: K1 SWP 不动产、厂房和设备及相关账户（PPE）
B2: K.02.2：详细测试 (处置/报废)
B4: 返回汇总页
B6: 记录我们的详细测试所涵盖的总体（指引：纳入充分的描述，以使经验丰富且之前与该项审计无关的审计师能够理解样本是如何选择的，例如，总体的分类或筛选。）
B7: 对本期固定资产处置清单进行测试。
E12: |------- Rx -------|
E13: 账面净值 | G13: 原值 | I13: 累计折旧 | K13: 减值准备
B14: 处置/报废总金额 | E14: =G14-I14-K14 -> -4.6566129e-09 | G14: =处置清单!$I$182 -> 13999994 | I14: =处置清单!$J$182 -> 13792918 | K14: =处置清单!$K$182 -> 207076.54
B15: Breakdown中处置/报废金额 | E15: =G15-I15-K15 -> 27276190 | F15: K.01 | G15: =-'K.01 Agree SL to GL'!Z25 -> 13999994 | H15: K.01 | I15: =-'K.01 Agree SL to GL'!Z31 -> -13483273 | J15: K.01 | K15: =-'K.01 Agree SL to GL'!Z37 -> 207076.54 | L15: K.01
B16: 差异 | E16: =E14-E15 -> -27276190 | F16: Rx | G16: =G14-G15 -> 0 | H16: Rx | I16: =I14-I15 -> 27276190 | J16: Rx | K16: =K14-K15 -> 0 | L16: Rx
B17: 差异是否需要进一步调查？ | E17: =IF(ABS(E16)>'K.00 Lead Sheet'!$C$6,"是","否") -> 是 | G17: =IF(ABS(G16)>'K.00 Lead Sheet'!$C$6,"是","否") -> 否 | I17: =IF(ABS(I16)>'K.00 Lead Sheet'!$C$6,"是","否") -> 是 | K17: =IF(ABS(K16)>'K.00 Lead Sheet'!$C$6,"是","否") -> 否
B19: 减：测试的关键项目 | E19: =SUM(L36:L37) -> 0
B20: 进行代表性抽样的剩余总体 | E20: =E14-E19 -> -4.6566129e-09
B22: 在下方描述选择关键项目的理由（请参阅Canvas指导工作流程的“关键项目”部分，包括信息图标）
B23: 本期固定资产处置净值为0，不执行进一步审计程序。
B28: EY 测试属性解释:
B29: 对于每个被选中进行测试的项目，我们检查了相关的第三方证据以及相关的会计分录，并确定：
B30: 1) 测试样本（原值和累计折旧余额）已从固定资产明细账和总账中正确移除。
B31: 2) 重新计算资产处置时点的账面净值，并计算处置损益。确认处置损益已按照适用的财务报告框架正确记录和分类。
B32: 3) 如果适用，正确记录处置收入金额。如果资产被出售（即收到收益），则获得发票或付款证明等，并确认与日记账分录中记录的收益金额一致。
B34: 固定资产处置/报废测试 | L34: |------- Rx -------| | O34: |------- Rx -------| | Q34: |------- Rx -------| | S34: EY Works
B35: 样本序号 | C35: 样本类型 | D35: 固定资产类别 | E35: 总账账户 | F35: 固定资产编号 | G35: 固定资产名称 | H35: 处置/报废日 | I35: 原值 | J35: 累计折旧 | K35: 减值准备 | L35: 净值 | M35: 出售价格 | N35: 处置交易凭证号 | O35: 处置损益 | P35: 出售价格（通过审计证据/支持性文件取得） | Q35: 出售价格差异 | R35: 获得的证据/支持的描述（例如，我们检查的具体销售发票/合同/订单/审批文件等） | S35: 1 | T35: 2 | U35: 3
B36: 1
B37: 2
B38: 3
B40: 标记图例: 记录已识别的异常情况以及如何解决这些异常情况的详细信息，包括执行的其他实质性程序（指南：包括足够的描述，以使之前与审计无关的经验丰富的审计师能够理解执行的程序）。
B41: 不适用此程序。

Sheet K.02.2a 处置选样输出
B2: 将此选项页替换为安永智能选样工作文件中的“选样项目详细信息” | N2: 返回汇总页

Sheet SkywindSettingSheet
A1: db9ce45c-b5c9-4e6d-be28-967b500f20b6
A3: {"Id":"2120100351","IsProject":false,"ProjectId":"2006602268","TempProjectName":"云端天风测试","TempType":2,"Upload":"上传","Download":"下载"}
A4: TRUE
