Workbook
Name \0: #REF!
Name \0: #REF!
Name \0: #REF!
Name \A: #REF!
Name \B: #REF!
Name \BRE: #REF!
Name \C: #REF!
Name \CBS: #REF!
Name \d: #REF!
Name \E: #REF!
Name \E: #REF!
Name \E: #REF!
Name \F: #REF!
Name \G: #REF!
Name \H: #REF!
Name \I: #REF!
Name \I: #REF!
Name \I: #REF!
Name \J: #REF!
Name \K: #REF!
Name \L: #REF!
Name \M: #REF!
Name \M: #REF!
Name \M: #REF!
Name \O: #REF!
Name \O: #REF!
Name \O: #REF!
Name \P: #REF!
Name \P: #REF!
Name \P: #REF!
Name \Q: #REF!
Name \R: #REF!
Name \S: #REF!
Name \STAMPA: #REF!
Name \T: #REF!
Name \T: #REF!
Name \T: #REF!
Name \U: #REF!
Name \U: #REF!
Name \U: #REF!
Name \V: #REF!
Name \V: #REF!
Name \V: #REF!
Name \W: #REF!
Name \X: #REF!
Name \X: #REF!
Name \X: #REF!
Name \Z: #REF!
Name _: #REF!
Name _.xls: #REF!
Name __: #REF!
Name ___: #REF!
Name _____Jun206: #REF!
Name _____May206: #REF!
Name _____OS0103: #REF!
Name _____TB0103: #REF!
Name _____TB1: #REF!
Name _____TB10: #REF!
Name _____TB11: #REF!
Name _____TB12: #REF!

Sheet global差异对比
A1: 新版Global底稿与原Global底稿的差异比对结果_N
A2: 序号 | B2: sheet | C2: 位置/表/差异描述 | D2: 差异内容 | E2: 新版 | F2: 旧版 | G2: 备注
A3: 1 | B3: N.00 Lead sheet | C3: 此Excel工作底稿与以下列出的标准工作程序（以Canvas引导的工作流形式）结合使用： | D3: • N.IPE evaluation | E3: 无 | F3: 有 | G3: 内容无实质性差异
A4: 2 | B4: VD.00 Lead Sheet | C4: TOD样本明细增加索引 | D4: 增加"Ref. "列与GL accounts covered by test of details进行勾稽 | E4: 有 | F4: 无 | G4: 实质性差异
A5: 3 | B5: N.00 Lead sheet | C5: Threshold(s)的表头 | D5: 表头进行了优化设置 | E5: 有 | F5: 无 | G5: 内容无实质性差异
A6: 4 | B6: N.00 Lead sheet | C6: Threshold(s)的提示1 | D6: 1 The thresholds by assertion are calculated using the high end of the range for the respective CRA based on the Example testing thresholds (% of TE) in EY GAM SUBSTANTIVE DESIGN 2.2.1. The asset/income accounts table is used for all accounts and assertions, except for the completeness assertion of liability/expense accounts for which the liability/expense accounts table is used. | E6: 有 | F6: 无 | G6: 内容无实质性差异
A7: 5 | B7: N.00 Lead sheet | C7: Threshold(s)的提示2 | D7: 2 The threshold for all assertions is calculated to be the lowest threshold among all relevant assertions. We use it on the ‘Lead sheet’ tab: (a) as a starting point to select GL accounts for testing, (b) as the amount for our quantitative fluctuation scope. | E7: 有 | F7: 无 | G7: 红色字体部分为新版和旧版的差异
A8: 6 | B8: N.00 Lead sheet | C8: 波动范围增加了表头 | D8: Fluctuation scopes | E8: 有 | F8: 无 | G8: 内容无实质性差异
A9: 7 | B9: VD.01.2 Test of Details | C9: 选择关键性理由行增加注释 | D9: Refer to the ‘Key items’ section of the Canvas guided workflow, including the information icon | E9: 有 | F9: 无 | G9: 内容无实质性差异
A10: 8 | B10: VD.01.2 Test of Details | C10: 1) Obtained the expense supporting documentation (e.g., purchase order, invoice, vendor debit memo, calculation schedule) and agreed it to the expense recorded for the period. 2) Based on inspection of supporting documentation (e.g., purchase order, invoice, contract with supplier, calculation schedule) and on our understanding of the entity’s accounting policies, concluded the amount was properly classified (i.e., the amount was properly expensed and included in the proper income statement caption). 3) Inspected the journal entry and expense supporting documentation and concluded that the expense was coded to the appropriate account and proper period based on the nature of the expense. | D10: Obtained relevant supporting documentation (e.g., purchase order, invoice, delivery note, supplier contract, vendor debit memo, calculation schedule), inspected the journal entry and concluded that the recorded expense was: 1) properly measured by agreeing its amount to the supporting documentation. 2) recorded in the proper period. 3) properly classified (i.e., the amount was coded to the appropriate account and included in the proper income statement caption) based on the nature of the expense and our understanding of the entity’s accounting policies. | E10: 有 | F10: 有 | G10: 实质性差异
A11: 9 | B11: VD.01.2 Test of Details | C11: 抽样结果按照Key item(s)；Representative sample(s)列示； | D11: 抽样结果根据下拉框进行Selection type选择； | E11: 有 | F11: 无 | G11: 实质性差异
A12: 10 | B12: VD.01.2 Test of Details | C12: 增加样本检查内容 | D12: 增加"Difference between invoice (expense) amount and GL amount " | E12: 有 | F12: 无 | G12: 实质性差异
A13: 11 | B13: VD.01.2 Test of Details | C13: 增加样本检查内容 | D13: 增加“GL amount”列 | E13: 有 | F13: 无 | G13: 实质性差异

Sheet 汇报-修改记录表
A1: 序号 | B1: Sheet | C1: 修改内容 | D1: 属于加法还是减法，新 | E1: 修改原因 | F1: V5 table number | G1: V6 table number | H1: Global 新版底稿 table number | I1: 识别CI点 | J1: 是否需要field testing | K1: Comments
A2: 1 | B2: Uexp.00 Lead | C2: 将“Uexp.00 Lead”与“VC.00销售费用BKD”合并列示 | D2: 减法 | E2: 与Global底稿保持一致 | F2: VD.00 Lead sheet | G2: VD.00 Lead sheet | H2: NA | I2: 与BKD合并列示，提高效率 | J2: N
A3: 2 | B3: VC.00销售费用BKD/VD.00管理费用BKD | C3: 将"Notes：列由T列调整至Q列 | D3: 新 | E3: 与Global底稿保持一致 | F3: H33-H35 | G3: I列 | H3: I35-I37 | I3: 无 | J3: N
A4: 3 | B4: 汇总-1 | C4: 增加序号4“我们记录了我们对期间内账户波动的预期以及做出这些预期的基础和理由。” | D4: 加法 | E4: 与canvas form保持一致：We documented our expectations for account fluctuations during the period and basis and rationale for those expectations. 我们记录了我们对期间内账户波动的预期以及做出这些预期的基础和理由。 | F4: NA | G4: 第7行 | H4: NA | I4: N | J4: N | K4: 同上
A5: 4 | B5: VC.00销售费用BKD/VD.00管理费用BKD | C5: 删除"For X-ref" | D5: 减法 | E5: 与"Uexp.01 TOD年审-抽样策略-1.2剔除-执行审计工作底稿X-ref"重复 | F5: S列 | G5: NA | H5: NA | I5: Y | J5: N | K5: OK
A6: 5 | B6: VC.00销售费用BKD/VD.00管理费用BKD | C6: 删除“序号6-将费用科目中存在着勾稽关系的费用类型，同相应的其他科目金额进行核对X-ref“ | D6: 减法 | E6: 与底稿变动保持一致 | F6: 第15行 | G6: NA | H6: NA | I6: Y | J6: N | K6: OK
A7: 6 | B7: VC.00销售费用BKD/VD.00管理费用BKD | C7: 删除“详细测试涵盖的总账账户” | D7: 减法 | E7: 与"Uexp.01 TOD年审-抽样策略-1.2剔除-扣除剔除项后样本总体金额"重复 | F7: F39 | G7: NA | H7: VD.00 Lead Sheet-D46 | I7: Y | J7: N | K7: OK
A8: 7 | B8: 汇总-1-Uexp.02 Cutoff | C8: 修改序号3的描述，“如果关键项（key item）的检查不足以应对CRA的风险水平，项目组应当采取安永审计抽样工具抽取代表性样本”，为：“如果关键项（key item）的检查不足以应对CRA的风险水平，项目组应当通过判断性抽样方法抽取代表性样本” | D8: 减法 | E8: Cut off 程序不适合用使用sampling tool 抽样的方法 | F8: NA | G8: D22 | H8: NA | I8: Y | J8: N | K8: 这个应该是减法吧，不用那个工具抽了，省事了
A9: 8 | B9: Uexp.02 Cutoff | C9: 修改“表1.确定截止性测试的涵盖期间：（测试期间项目组要根据需要根据关账时间和发票入账频率进行判断，并在此记录。” 修改为费用报销政策和入账规则 | D9: 新 | E9: 检查点是交易凭据，发票入账不能客观判断测试期间 | F9: D16 | G9: D16 | H9: NA | I9: N | J9: N | K9: 不只是费用报销政策，还有费用入账时间，准确的描述应该是根据费用的报销政策和入账规律确定从费用发生到费用入账的期间-（费用报销政策即包括入账时间，如果都写上是否过于冗余）-报销政策是财务规定，入账是会计规定，是2个事情。

Sheet Canvas Form

Sheet 使用说明
B2: 销售费用、管理费用实操指引的使用说明
B4: 1、本实操指引仅适用于销售费用、管理费用科目评估为重大账户时使用； 2、本实操指引内容仅涉及PSP。 3、本实操指引的内容主要包括基础操作指引、进阶实操提示、易错点。“基础操作指引”旨在让使用者快速上手执行审计程序；“进阶实操提示”补充了不同业务场景下的相关考虑及理论依据；“易错点”归纳了审计程序执行过程中的常见错误。 4、本实操指引源于审计实务经验的归纳和总结，不能代替GAM及审计准则，审计项目组可结合审计项目的业务特征、风险评估结果、所处监管环境等因素参考使用。 5、审计过程中涉及到的职业判断需要由审计项目组完成，实操指引的内容不作为任何职业判断依据，仅供参考。 6、本实操指引仅涵盖SWP（excel）内容，审计项目组需确保在SWP中执行的审计程序与Canvas中对应的工作程序表（canvas form）内容一致。 | M4: 若在实操指引使用中有任何问题，欢迎大家踊跃扫描二维码或者点击链接提出意见和建议。
M7: SWP实操指引问题收集
B25: 目录
B27: 概述
B28: 会计基础知识与Q&A
B29: Review checklist
B30: 汇总
B31: Uexp.00 Lead
B32: VC.00 销售费用BKD
B33: VD.00 管理费用BKD
B34: VC&VD.01.2 TOD 年审
B35: VD.01.3 复核法律费用
B36: VC&VD.01.4 截止性测试

Sheet 概述
B2: 一、主要实质性程序明细表（仅供参考）
B3: 序号 | C3: 执行实质性程序 | D3: 程序描述 | E3: 对应的底稿sheet | F3: 预审建议可执行工作 | G3: 年审建议可执行工作 | H3: 备注
B4: 1 | C4: VC&VD.00 Lead | D4: 我们获取或编制了销售费用/管理费用重大账户的引导表，将本期金额与试算表核对一致，并将上期金额与最终的前期试算表核对一致（如适用）。 | E4: Uexp.00 Lead | F4: 核对上期审定数及上期调整事项是否需跟调 | G4: 核对本期账面数、本期审定数、上期审定数与财务报表一致
B5: 2 | C5: VC&VD.00 BKD | D5: 我们记录了我们对期间内账户波动的预期以及做出这些预期的基础和理由。 对比当期金额和上期金额，调查变动大于范围或与预期不符的变动情况。并就异常事项检查记账凭证、合同等支持性证据，评估其发生的合理性。 | E5: VC.00 销售费用BKD | F5: 1、填制按性质区分的费用明细，并与科目余额表及财务报表核对一致； 2、对费用建立预期，对异常波动的费用，调查原因、评估合理性、检查支持性文件； 3、识别需要执行实质性分析程序或详细测试的费用类型； 4、将费用科目中存在着勾稽关系的费用类型，同相应的其他科目金额进行核对X-ref。 | G5: 将程序延伸至全年
E6: VD.00 管理费用BKD
B7: 3 | C7: VC&VD.01.1 实质性分析程序SAP | D7: 如执行，则使用264GL完成相应记录。 | E7: 264GL | F7: 讨论是否适合执行，若执行则使用264GL完成相应记录。 | G7: 将程序延伸至全年
B8: 4 | C8: VC&VD.01.2 详细测试 TOD | D8: 若通过实质分析性复核程序取得的证据不足以就账户余额得出结论，则执行详细测试。 | E8: VC&VD.01.2 TOD | F8: 1、取得按类别划分费用的列表，剔除工资费用、租赁费、折旧等已在其他科目测试过的项目，将其设为样本总体，记录确定样本总体的过程和理由； 2、 按照<VC&VD.01.2 TOD 预审+剩余期间>抽取关键性及代表性样本； 3、 对关键项目和代表性样本，检查支持性证据。 | G8: 按照<VC&VD.01.2 TOD 预审+剩余期间>补充抽取关键性及代表性样本；查看剩余关键样本和代表性样本的相关支持性证据。
B9: 5 | C9: VD.01.03复核法律费用 | D9: 我们对金额大于测试阈值的法律费用相关账户进行复核（如有），查看其交易性质及发票金额是否与账面一致，同时对性质特殊（如诉讼等）的法律费用向律师发送审计询问函，对回函差异进行调查，对于未决诉讼应执行相关程序请检查勾稽到预期信用损失、预计负债等底稿。 | E9: VD.01.3 复核法律费用 | F9: 抽查大额或性质特殊的法律相关费用的合同、账单、发票 | G9: 将程序延伸至全年 执行律师函证（如适用）
B10: 6 | C10: VC&VD.01.4 截止性测试 | D10: 结合我们对于被审计单位费用确认时点的理解，考虑截止性测试的涵盖期间。记录确定截止性测试样本的策略。 | E10: VC&VD.01.4 截止性测试 | F10: 分析错报风险，确定截止性测试涵盖期间及抽样策略 | G10: 执行截止性测试
B13: 二、审计涉及的PBC情况及核对说明
B15: 序号 | C15: 资料分类 | D15: 所需PBC | E15: 获取阶段的核对注意事项 | H15: 资料样例
B16: 1 | C16: 基础性PBC | D16: 财务报表 | E16: 报表涵盖期间应与审计期间一致 | H16: Practical PSP_Uexp 利润表
B17: 2 | C17: 基础性PBC | D17: 科目余额表 | E17: 科目余额表涵盖期间与审计期间一致 | H17: Practical PSP_Uexp 科目余额表
B18: 3 | C18: 基础性PBC | D18: 序时账 | E18: 序时账涵盖期间与审计期间一致 | H18: Practical PSP_Uexp_XYZ公司_费用抽样样本池
B19: 4 | C19: 基础性PBC | D19: 费用辅助明细账 | E19: 涵盖期间应当与审计期间一致；发生额应当与报表、科目余额表核对一致。 | H19: Practical PSP_Uexp_费用明细账
B20: 5 | C20: 支持性PBC | D20: 市场推广服务费、商标使用费等费用相关的合同等支持性资料 | E20: 确保合同、发票及银行回单的内容与测试样本一致 | H20: 考虑到测试资料并无统一的样例，此处不适用
B21: 6 | C21: 支持性PBC | D21: 抽查样本相关的供应商合同、采购订单、交货单、结算单、发票、供应商借项通知单等支持性资料 | E21: 确保合同、发票及银行回单的内容与测试样本一致 | H21: 考虑到测试资料并无统一的样例，此处不适用
B22: 7 | C22: 支持性PBC | D22: 法律费用抽查样本的合同、账单、发票、传票、起诉状、判决资料等支持性资料 | E22: 确保合同、发票及银行回单的内容与测试样本一致 | H22: 考虑到测试资料并无统一的样例，此处不适用
B23: 8 | C23: 支持性PBC | D23: 抽查样本相关的合同/订单、交付确认单/交货单、结算单、发票、供应商借项通知单等支持性资料 | E23: 确保合同、发票及银行回单的内容与测试样本一致 | H23: 考虑到测试资料并无统一的样例，此处不适用
Q53: 抽样策略： ●主要审计问题为多计： 因为完整性认定的应对程序主要是search for，而TOD程序主要是应对发生和计量认定。 （该选项对样本量计算结果无影响。） ●问题4：从其他审计程序中获得的保证水平： 费用的抽样属于在为损益表(PL)科目确定代表性样本规模 1、质胜之道2024/12/18发布的《年终审计提醒》： 情景一：项目组评价并确定+S53+P53:Q109+O53:Q109

Sheet 会计基础知识与FAQ
A3: 一、 | B3: 相关的会计基础知识
B4: 以下管理费用和销售费用的科目描述及主要账务处理相关内容摘自财政部2006年发布的应用指南《附录-会计科目和主要账务处理》及2024年财政部发布的《企业会计准则应用指南汇编（2024）》。新准则生效后，财政部未系统修订《附录-会计科目和主要账务处理》，因此部分会计科目的账务处理说明未更新至新准则，使用时请注意。
B7: 销售费用：
B8: 一、本科目核算企业销售商品和材料、提供劳务的过程中发生的各种费用，包括保险费、包装费、展览费和广告费、商品维修费、预计产品质量保证损失、运输费、装卸费等以及为销售本企业商品而专设的销售机构(含销售网点、售后服务网点等)的职工薪酬、业务费、折旧费等经营费用。
B9: 企业发生的与专设销售机构相关的固定资产修理费用等后续支出，也在本科目核算。
B10: 企业（金融）应将本科目改为“6601业务及管理费”科目，核算企业（金融）在业务经营和管理过程中所发生的各项费用，包括折旧费、业务宣传费、业务招待费、电子设备运转费、钞币运送费、安全防范费、邮电费、劳动保护费、外事费、印刷费、低值易耗品摊销、职工工资及福利费、差旅费、水电费、职工教育经费、工会经费、会议费、诉讼费、公证费、咨询费、无形资产摊销、长期待摊费用摊销、取暖降温费、聘请中介机构费、技术转让费、绿化费、董事会费、财产保险费、劳动保险费、待业保险费、住房公积金、物业管理费、研究费用、提取保险保障基金等。
B11: 企业（金融）不应设置“管理费用”科目。
B13: 二、本科目可按费用项目进行明细核算。
B15: 三、销售费用的主要账务处理。
B16: （一）企业在销售商品过程中发生的包装费、保险费、展览费和广告费、运输费、装卸费等费用，借记本科目，贷记“库存现金”、“银行存款”等科目。
B17: （二）发生的为销售本企业商品而专设的销售机构的职工薪酬、业务费等经营费用，借记本科目，贷记“应付职工薪酬”、“银行存款”、“累计折旧”等科目。
B19: 四、期末，应将本科目余额转入“本年利润”科目，结转后本科目无余额。
B21: 管理费用：
... B35: 四、期末，应将本科目的余额转入“本年利润”科目，结转后本科目无余额。
A42: 二、 | B42: 相关网站
I43: 会计知识库与审计知识库的link点进去应为以下界面，会计知识库包含【费用相关的企业会计准则及应用指南汇编】、【进阶知识-相关问题解答-财政部、证监会及交易所、EY内部】、【国际会计准则及企业会计准则的对比】，审计知识库包含【EY 培训视频】
B44: EY 网站 | C44: 链接 | D44: 可查询内容 | I44: 1）费用相关的企业会计准则及应用指南汇编如下所示 | R44: 2）进阶知识-相关问题解答-财政部、证监会及交易所、EY内部 | AA44: 3）国际会计准则及企业会计准则的对比如下所示 | AJ44: 审计知识库中的培训视频界面如下所示
B45: GAM | C45: VC：销售和分销成本 | D45: 销售费用主要PSP/OSP
B46: GAM | C46: VD：管理和其他营业费用 | D46: 管理费用主要PSP/OSP
B47: GC knowledge center | C47: 会计知识库 | D47: 重点资源： 1）费用相关的企业会计准则及应用指南汇编； 2）实务问题-By topic解析； 3）国际会计准则及企业会计准则的对比；
D48: 1）费用相关的企业会计准则及应用指南汇编；
D49: 2）进阶知识-相关问题解答-财政部、证监会及交易所、EY内部
D50: 3）国际会计准则及企业会计准则的对比
C51: 审计知识库 | D51: 重点讲解视频： 确定费用TOD抽样总体需注意事项； VC&VD&财务费用实质性程序常见问题提示。
D52: 讲解视频 | Q52: 抽样策略： ●主要审计问题为多计： 因为完整性认定的应对程序主要是search for，而TOD程序主要是应对发生和计量认定。 （该选项对样本量计算结果无影响。） ●问题4：从其他审计程序中获得的保证水平： 费用的抽样属于在为损益表(PL)科目确定代表性样本规模 1、质胜之道2024/12/18发布的《年终审计提醒》： 情景一：项目组评价并确定+S53+P53:Q109+O53:Q109
A54: 三、 | B54: 相关Q&A
B56: FAQ | C56: 链接 | D56: 备注
B57: Firm 审计方法论FAQ | C57: Firm 审计方法论FAQ Link | D57: FAQ link需要点击两遍，第一次是登陆，第二次会跳转至FAQ，正确显示页面如下 操作方法： 1、如想搜索底稿相关问题，点击筛选，然后点击添加，在"字段"里选中问题分类，在"值"中输入"安永中国标准底稿模板"即可看到FAQ 2、如想搜索某一类问题，则在搜索栏输入关键字即可查阅相关答疑，如想查找关于"cutoff"相关问题，具体操作页面详见如下
B62: 来源5 | C62: GAM中各section程序执行指引
B63: 链接 | C63: EY Atlas

Sheet Review checklist
B2: 销售费用、管理费用科目底稿复核的主要检查点
B5: 序号 | C5: 检查部分 | D5: 检查描述 | E5: 问题类别
B6: 1 | C6: 审计证据充分、恰当 | D6: ◆PM/TE/SAD与Canvas中最终的结果一致； | E6: 底稿范围、程序设计
D7: ◆各认定CRA正确，TT取值正确；
D8: ◆底稿应执行PSP均得到执行，拒绝执行理由恰当、充分；
D9: ◆已对超过门槛、性质异常或与预期不符的变动进行调查，并对就原因执行的调查结果详细记录，分析合理；
D10: ◆底稿中不存在重大OS 事项，review notes均已解决并删除，底稿中无highlight;
D11: ◆底稿中索引至其他底稿的审计程序记录正确，相关底稿均已上传Canvas，如Canvas 中无对应底稿，交付团队已在canvas 中添加Note提醒项目组上传；
B12: 2 | C12: 会计处理潜在错报 | D12: ◆费用列报正确，确认费用列报正确，不存在分类错误。包括但不限于关注以下方面： | E12: 错报
D14: 销售费用中：不包含与合同履约成本相关的费用，如和合同履约相关的运费、装卸费、包装费等；不包含与应付客户对价/可变对价相关的费用，如支付给客户的推广费/销售服务费/返利等；不包含质量保证金费用；与合同取得成本相关的费用性质，如佣金，已确认恰当结转至销售费用且金额准确；
D16: 管理费用中：不包含与税金及附加相关的费用，如“四小税”；不包含应资本化的大修理费用，以及受益对象不在管理职能部门的维修费；不包含受益对象不在管理职能部门的停工损失；
D17: ◆对于管理层调整（CLA），底稿中进行恰当的测试（或索引至正确的测试底稿），并记录测试结果；对于审计调整（AA），底稿中清晰记录调整事项说明和调整数字的来源；所有调整的编号已和最终定稿的A3A5底稿中的调整编号一致。
B18: 3 | C18: 明细账与总账核对一致及异常波动分析 | D18: ◆底稿BKD本期账面数与TB核对一致，未审数与A3核对一致； | E18: 基础程序
D19: ◆底稿BKD本期和上期审定数与Lead核对一致，Lead表与A3一致；
B20: 4 | C20: 合理性测试 | D20: ◆若测试对象适合采用合理性测试方法，测试逻辑合理，偏差阈值设定合理 | E20: 基础程序
C21: （如适用） | D21: ◆测试差异小于偏差阈值，或大于偏差阈值已在底稿中执行进一步跟进、调查，并在底稿中进行恰当的解释及记录，以支持审计结论。 | E21: 基础程序
B22: 5 | C22: 抽样 | D22: 抽样过程正确，主要包括以下方面: | E22: 基础程序
D23: ◆不同交易类别（包括负数等）已区分不同样本总体；各样本总体金额和BKD中样本池金额一致（或虽与BKD不一致，但小于SAD且解释合理）；剔除项合理、金额准确，且已对重大剔除项执行或索引了恰当的审计程序；
D24: ◆剔除不同交易类别后的样本总体与抽样工具中的样本总体一致；
D25: ◆抽样工具中的参数设置正确，包括实体类型（复杂实体or非复杂实体）、CRA、TT、P&L ARTs表的适用性（40倍CAP）、其他程序取得的证据水平、预期的错报数量；
D26: 提示：TOD程序不应对完整性认定错报风险，一般参考GAM中资产/收益账户选取测试阈值
D27: ◆关键项选取恰当，定量关键项使用正确的测试阈值，性质特殊的费用选取为定性关键项，并合理记录选取理由；
B28: 6 | C28: 详细测试 | D28: 样本测试过程正确，底稿记录恰当，主要包括以下方面: | E28: 基础程序
D29: ◆测试样本与抽样工具输出的样本结果一致；
D30: ◆检查支持性文件正确、恰当，能满足测试属性需求，且记录了关键信息。支持性文件包括能证实费用真实发生，以及发生期间、金额、分类正确的文件。关键信息为上述文件的名称、编号；针对计提类样本（如有），已检查在当期被准确冲销并使用替代样本执行测试或恰当索引至相关测试底稿
D31: ◆对于负值样本总体（如有），绝对值大于TT的，已执行审计程序进行应对，包括对负数费用按性质分类，针对不同费用分类分析其合理性，以及对异常性质的负值，大于SAD的单项执行相关测试；
D32: ◆如果测试结果存在例外情况，均已调查跟进并恰当记录；
B33: 7 | C33: 截止性测试 | D33: ◆已根据费用实际发生到入账之间的时间确定截止性期间，并在底稿中恰当记录范围及选取原因； | E33: 基础程序
D34: ◆已采用判断抽样的方式选取关键项和代表性样本，并在底稿中恰当记录选取过程和结果；
D35: ◆检查样本对应的支持性证据，已恰当记录证据名称、编号以及费用的期间；
D36: ◆如果测试结果存在例外情况，均已调查跟进并恰当记录；

Sheet 汇总
B2: VC.00 | C2: VC&VD.00 Lead （认定：O、M、C、P&D） | F2: 程序页 | G2: 执行 | H2: 不执行的原因 | I2: 注意事项 | K2: 汇总 -基础操作指引-【01】 | M2: 汇总 -进阶实操提示-【01】 | O2: 汇总 -易错点-【01】
B3: 1 | C3: 我们获取或编制了销售费用/管理费用重大账户的引导表，将本期金额与试算表核对一致，并将上期金额与最终的前期试算表核对一致（如适用）。 | F3: Uexp.00 Lead | G3: 是 | K3: 1、汇总页列示与费用科目相关的PSP程序，若执行，则在执行列选择是，若不执行，则选择否，并需在不执行的原因列写明原因 | M3: 常见不执行相关审计程序的情况有： 1）拒绝VC&VD.01.1 实质性分析程序SAP：被审计单位不存在可以执行SAP的费用项目或者虽可以执行SAP但耗时较长且无法有效减少TOD工作量的费用项目 2）VC&VD.01.2 详细测试 TOD：通过执行SAP及在其他科目已执行的程序，已获得关于该账户充分适当的证据水平，无需进一步执行细节测试 3）拒绝VD.01.03复核法律费用：被审计单位不存在法律诉讼费用 4）拒绝VC&VD.01.4 截止性测试：通过执行SAP及在其他科目已执行的程序，已获得关于该账户充分适当的证据水平，无需进一步执行截止性测试 | O3: 1、错误拒绝PSP，未执行必要的PSP。 2、未使用标准底稿，导致未执行必要的PSP，或PSP执行不到位。 3、有限风险账户和不重大账户，不需要执行所有程序但执行了所有PSP，导致over audit。 4、各底稿页实际执行的程序与程序要求不一致，或少执行必要审计程序。 5、拒绝PSP未解释原因，或解释不具体。 6、底稿中存在highlight内容，或隐藏了不适用的底稿页。
B4: VC&VD.01.1 | C4: VC&VD.00 BKD（认定：O、M、C、P&D） | F4: 程序页 | G4: 执行 | H4: 不执行的原因 | I4: 注意事项
B5: 1 | C5: 我们记录了我们对期间内账户波动的预期以及做出这些预期的基础和理由。 对比当期金额和上期金额，调查变动大于范围或与预期不符的变动情况。并就异常事项检查记账凭证、合同等支持性证据，评估其发生的合理性。 | F5: VC.00 销售费用BKD | G5: 是
B6: 2 | F6: VD.00 管理费用BKD | G6: 是
B7: VC&VD.01.1 | C7: VC&VD.01.1 实质性分析程序SAP（认定：O、M、C、P&D） | F7: 程序页 | G7: 执行 | H7: 不执行的原因 | I7: 注意事项
B8: 1 | C8: 如执行分析性复核程序，则使用264GL完成相应记录。如不执行，可直接执行VC&VD.01.2 详细测试 TOD。 | F8: 如执行，请项目组添加底稿索引，如不执行请直接删除该程序。 | G8: 是
B9: VC&VD.01.2 | C9: VC&VD.01.2 详细测试 TOD（认定：O、M、P&D） | F9: 程序页 | G9: 执行 | H9: 不执行的原因 | I9: 注意事项
B10: 1 | C10: 若通过实质分析性复核程序取得的证据不足以就账户余额得出结论，则执行详细测试。 | F10: VC&VD.01.2 详细测试 TOD | G10: 是
B11: VD.01.03 | C11: VD.01.03复核法律费用（认定：O、M、C、P&D） | F11: 程序页 | G11: 执行 | H11: 不执行的原因 | I11: 注意事项
B12: 1 | C12: 我们对金额大于测试阈值的法律费用相关账户进行复核（如有），查看其交易性质及发票金额是否与账面一致，同时对性质特殊（如诉讼等）的法律费用向律师发送审计询问函，对回函差异进行调查，对于未决诉讼应执行相关程序请检查勾稽到预期信用损失、预计负债等底稿。 | F12: VD.01.03复核法律费用 | G12: 是
B13: VC&VD.01.4 | C13: VC&VD.01.4 截止性测试（认定：O、C） | F13: 程序页 | G13: 执行 | H13: 不执行的原因 | I13: 注意事项
B14: 1 | C14: 结合我们对于被审计单位费用确认时点的理解，考虑截止性测试的涵盖期间。 | F14: VC&VD.01.4 截止性测试 | G14: 是
B15: 2 | C15: 记录确定截止性测试样本的策略。
Q53: 抽样策略： ●主要审计问题为多计： 因为完整性认定的应对程序主要是search for，而TOD程序主要是应对发生和计量认定。 （该选项对样本量计算结果无影响。） ●问题4：从其他审计程序中获得的保证水平： 费用的抽样属于在为损益表(PL)科目确定代表性样本规模 1、质胜之道2024/12/18发布的《年终审计提醒》： 情景一：项目组评价并确定+S53+P53:Q109+O53:Q109

Sheet 汇总 (2)
A1: 固定资产底稿交付样例 | M1: 固定资产标准工作流程（SOP）
N2: 基础操作指引 | P2: 进阶实操提示 | R2: 易错点
N4: 汇总 -基础操作指引-【01】 | P4: 汇总 -进阶实操提示-【01】 | R4: 汇总 -易错点-【01】
B5: K.00 | C5: K.00 Lead Sheet | F5: 程序页 | G5: 注意事项 | H5: CI 点 | I5: 是否执行 | J5: 不执行的原因 | N5: 1、汇总页仅列示与固定资产科目相关的部分PSP程序， 2、本底稿的审计程序，通常情况下程序均需执行，若审计项目组根据风险情况判断不执行，需写明原因； | P5: 常见不执行相关审计程序的情况有： 1）拒绝折旧测试：被审计单位系新设公司，本年度约95%的资产全部为年底采购，期末无需计提折旧，因此，我们不执行折旧测试； 2）拒绝新增测试：本年度无新增固定资产或者新增资产的原值小于TE，且各单项资产均小于TT，且无性质异常的单项新增固定资产。 3）拒绝处置测试：本年度无处置固定资产或者处置资产的净值、处置损益均小于TE，且各单项处置净值小于TT，且无性质异常的单项处置资产。 注：上市公司为应对监管风险，即使新增/处置不重大，也可能通过降低测试阈值（TT）或抽取金额前3大的方式确定关键性样本，需在底稿中记录抽样过程和结果。 | R5: 1、错误拒绝PSP，未执行必要的PSP。 2、有限风险账户，不重大账户不需要执行所有程序但执行了所有PSP。 3、各底稿页执行程序表记录与实际执行程序不一致，且少执行必要审计程序。 4、拒绝PSP未解释原因，或解释不具体。 5、底稿中存在highlight内容。
B6: 1 | C6: 获取和编制固定资产两期变动的引导表，并与试算平衡表和上年底稿核对一致。对固定资产变动建立预期并说明理由，对不符合预期的变动以及异常变动进行调查和分析。 | F6: K.00 Lead Sheet
B7: K.01.1 | C7: K.01 Agree SL to GL | F7: 程序页 | G7: 注意事项 | H7: CI 点 | N7: PO操作指引 1、目标：提供指引使得staff能够较为快速看懂如何正确执行该程序 2、使用对象：staff 3、来源： 1）上年SOP； 2）Canvas form PSP程序描述； 3）答疑平台/复盘问题/CI kaizen/Exception; 4、主要内容：Step-by-step说明底稿的编制要求，具体操作说明只放最普适性的内容
B8: 1 | C8: 获取固定资产后推明细表，并将其与试算平衡表和固定资产清单核对一致。 | F8: K.01.1 Agree SL to GL
B9: K.02.1 | C9: K.02.1 新增测试 | F9: 程序页 | G9: 注意事项 | H9: CI 点
B10: 1 | C10: 获取当期按类别划分的所有固定资产新增列表，并将该列表与固定资产后推核对一致，调查超过SAD名义金额的差额。 | F10: K.02.1b 新增清单 | G10: 若在建工程为不重大账户未开底稿，则项目组需要在K1SWP中核对在建工程转入与转出金额是否一致，并按照J.02.2.2转出测试的属性测试执行该程序。 | R10: PO操作指引 1、目标：指出执行审计程序过程中的易错点，用以发现问题 2、使用对象：所有人 3、来源：<QEL认证底稿问题清单>及<质检底稿中常见问题清单>；建议增设相关审计调整事项，以及被监管重点关注的事项的内容; 原版本SOP的review chceklist 4、主要内容：易错场景及案例
B11: 2 | C11: 对本年新增资产执行关键性样本测试和代表性样本测试（如需要）。 | F11: K.02.1 新增测试 | M11: 1） | N11: Canvas form（对于指引需要标注哪些内容是来着canvas form） | P11: PO操作指引 1、目标：应对实务中不同业务场景，以及在执行程序时的相关考虑，是基于操作指引更为进阶的判断事项； 2、使用对象：所有人 3、来源： 1）上年SOP； 2）Canvas form I Bubble； 3）答疑平台/复盘问题/CI kaizen/Exception; 4、主要内容：放置实操不同场景下的处理方式，涉及的理论部分先总结归纳，涉及存粹的方法论可link 到Atlas及GC Knowledge
B12: K.02.2 | C12: K.02.2 处置测试 | F12: 程序页 | G12: 注意事项 | H12: CI 点 | M12: 2） | N12: FY25-Q&A问答平台 2.0.xlsx
B13: 1 | C13: 获取当期按类别划分的所有固定资产处置列表，包括记录的处置的损益，并将该列表与固定资产后推核对一致，我们调查超过SAD名义金额的差额。 | F13: K.02.2b 处置清单 | M13: 3） | N13: FY25-项目复盘-提升建议及经验总结汇总.xlsx
B14: 2 | C14: 对本年处置资产执行关键性样本测试和代表性样本测试（如需要）。 | F14: K.02.2 处置测试 | M14: 4） | N14: CI Programme Kaizen | O14: 1） | P14: Canvas form I Bubble（要标注哪些内容是来着canvas form） | Q14: 1) | R14: QEL认证底稿问题清单
B15: K.03.1 | C15: K.03.1 折旧测试 | F15: 程序页 | G15: 注意事项 | H15: CI 点 | M15: 5） | N15: WP COE Exception事项统计-FY25 updating | O15: 2） | P15: FY25-Q&A问答平台 2.0.xlsx | Q15: 2) | R15: 质检底稿中常见问题清单
B16: 1 | C16: 如选择执行实质性分析程序（SAP）测试折旧费用， 若SAP能提供充分、适当的审计证据则可不用执行细节测试（TOD）或By Item测试。 | F16: K.03.1 SAP | O16: 3） | P16: FY25-项目复盘-提升建议及经验总结汇总.xlsx | Q16: 3) | R16: 被监管重点关注的事项
B17: 2 | C17: 如选择执行详细测试TOD测试 | F17: K.03.2 折旧测试TOD | O17: 4） | P17: CI Programme Kaizen
B18: 3 | C18: 如选择执行详细测试By item测试，可点击链接获取公式： | F18: 小灯泡 | O18: 5） | P18: WP COE Exception事项统计-FY25 updating
N19: 怎么找到canvas form
N34: 怎么找到i bubble
N50: 如发现step4中只有Conclusion的smt，则点击该smt，并按以下步骤进行操作
N119: 最后的页面如下，I Bubble即在对应的感叹号中

Sheet Uexp.00 Lead
B1: 标准工作底稿: VC&VD SWP 销售费用&管理费用
B2: 客户名称 | C2: XYZ公司 | D2: 此工作底稿需要与以下 Canvas PSP guided workflow forms一起使用： • VC&VD.00 销售费用&管理费用引导表 • VC&VD.01 销售费用&管理费用实质性程序 • 账户结论
B3: 期末 | C3: 46022 | P3: 基础操作指引-【01】 | T3: 进阶实操提示-【01】 | V3: 易错点-【01】
B4: 分析日期 | C4: 46054 | P4: 填列基本信息： 1、期末：填列资产负债表日，若为一般年度法定审计项目，填写202X-12-31；若为IPO审计服务等对某个特定会计期间进行审计，应填写期末时间。 2、分析日期：指底稿编制时间，据实填写。 3、可容忍误差（TE）、名义金额（SAD）:以Canvas中相关底稿为准进行填列，具体位置请与项目组FIC/EIC沟通确认。填列执行程序所使用的PM/TE/SAD，若审定后的PM/TE/SAD与执行程序所使用的数据有变化，需要添加专门的note说明是否需要补充审计程序，但无需更改此处的数据。 4、公认会计准则：为被审计单位选定的会计准则（如“企业会计准则”），请根据公司适用的准则和报告出具的目的确定。 5、货币/单位：填列记账本位币。企业通常应选择人民币作为记账本位币，业务收支以人民币以外的货币为主的企业，可以按规定选定其中一种货币作为记账本位币。 | T4: 填列基本信息： 若项目组在执行程序的过程中更新了执行程序所使用的PM/TE/SAD数据，则此处需要同步更新。注意定期\每次交付前与项目组书面确认执行程序所使用的PM/TE/SAD的变化情况。 | V4: 填列基本信息： 1、执行程序所使用的TE/SAD取数错误或未更新 2、客户名称、期末、货币/单位等基础信息未更新。
B5: 可容忍误差(TE) | C5: 787500
B6: 名义金额(SAD) | C6: 52500
B7: 适用会计准则 | C7: 企业会计准则
B8: 记账本位币 | C8: CNY
B9: VC&VD.00 LEAD
A10: 62442a70-4601-4582-abe9-90996a0f33f2
B11: 返回汇总页
B13: 安永标记
B14: TB | C14: 已与科目余额表核对无误
B15: PY | C15: 与上年最终审定数核对一致
B16: A3 | C16: 与未审数、审定数核对一致
B17: A5 | C17: 与审计调整核对一致
B18: FS | C18: 与FS.0x与财务报表核对无误
B19: w | C19: 低于SAD的金额——放弃进一步调查
B20: Rx | C20: 重新计算，无异常
B21: X | C21: 满足属性
B22: m | C22: 余额/活动不符合测试范围–无需进一步调查
B23: SL | C23: 已与明细账核对无误
P24: 基础操作指引-【02】 | T24: 进阶实操提示-【02】 | V24: 易错点-【02】
B25: 表1 | P25: 填列表1： 链接至VC.00 销售费用BKD/VD.00 管理费用BKD | T25: 无 | V25: 填列表1： 链接错误或者未更新
B26: 科目名称 | C26: 索引号 | D26: 本期账面数 | E26: 本期账表调整数 | F26: 本期未审数 | G26: 本期审计调整数 | H26: 本期审定数 | I26: 上期审定数
B27: 销售费用 | C27: VC.00 销售费用BKD | D27: ='VC.00 销售费用BKD'!E48 -> 5809450.1 | E27: ='VC.00 销售费用BKD'!F48 -> 0 | F27: =SUM(D27:E27) -> 5809450.1 | G27: ='VC.00 销售费用BKD'!I48 -> 0 | H27: =SUM(F27:G27) -> 5809450.1 | I27: ='VC.00 销售费用BKD'!K48 -> 4568425.6
B28: 管理费用 | C28: VD.00 管理费用BKD | D28: ='VD.00 管理费用BKD'!E73 -> 7841994.1 | E28: ='VD.00 管理费用BKD'!F73 -> 0 | F28: =SUM(D28:E28) -> 7841994.1 | G28: ='VD.00 管理费用BKD'!I73 -> 0 | H28: =SUM(F28:G28) -> 7841994.1 | I28: ='VD.00 管理费用BKD'!K73 -> 6586443.8

Sheet VC.00 销售费用BKD
B1: 标准底稿: VC SWP 销售费用 | U1: 基础操作指引-【01】 | W1: 进阶实操提示-【01】 | Y1: 易错点-【01】
B2: VC.00 编制汇总表并比较余额 | U2: 综合风险评估（CRA）与测试阈值（TT）： 1、根据Canvas中各科目认定的CRA设置情况填写CRA级别，并与FIC/EIC沟通确认 2、根据Canvas中CRA底稿中测试阈值系数的设定情况，检查底稿中自动计算的测试阈值，如与设定不符，按照设定进行修改。 | W2: 综合风险评估（CRA）与测试阈值（TT）： 1、GAM中规定了资产/收入账户和负债/费用账户，在不同综合风险评估等级下的测试阈值系数区间（占TE的比例）（见右图），底稿中的TT系数默认按照GAM建议区间的上限设定，如审计项目运用职业判断确定的测试阈值并非按区间上限计算，则应当手动修改D列测试阈值的系数公式。 2、对于负债和费用账户，当我们为关键项设置定量测试阈值： ①一般情况下，我们并不根据负债或费用账户的定量测试阈值来识别关键项，因为我们主要关注其完整性而非存在性的认定。因此，我们选择测试项的标准可能取决于其他因素（例如，我们可能根据整个审计期间的采购活动金额，选择一组供应商样本来寄发函证）。 ②如果我们出于分类或估值测试目的而根据测试阈值识别负债或费用账户的关键项，我们可使用与资产账户相同的测试阈值。（对于资产和收益账户，当我们为关键项设置定量测试阈值：一般情况下，我们将可容忍误差作为起点，因为某个账户余额或交易类别中超过可容忍误差的个别项可能具有重要性随着相关认定的综合风险评估水平增加，我们会考虑降低关键项的测试阈值，以反映当评估的重大错报风险水平增加时所需的额外审计证据。当我们确定基于定量阈值识别关键项的做法适当时，我们可能考虑使用 实质性——设计 2.2.2 中的综合风险评估的示例阈值。）（右图） ③但如果我们设计的完整性测试采用对等总体（例如：中期或资产负债表日后的现金支出），我们会降低测试阈值以便将小的错报汇总。 ④我们对未入账负债的测试可能包括根据某个测试阈值，检查在资产负债表日后过账的费用或出具的支票，以确定相关负债是否在适当期间入账（即，用于发现这种低估的总体涉及的交易符合从被测试账户中遗漏的标准）。 （GAM 实质性 TOD：实质性详细测试 2.2.2 识别金额较大的负债和费用账户关键项） ●(名词解释)审计风险模型： 审计风险是固有风险评估、控制风险评估和检查风险的函数。在我们识别重大错报风险后，我们对其进行评估。我们对重大错报风险的评估包括评估固有风险和控制风险，这两者共同构成我们的综合风险评估。 ●(名词解释)CRA和TT： 根据固有风险和控制风险的不同，综合风险评估的等级有四种：最低Minimal、低Low、中等Moderate、高High，分别对应较低风险信赖控制、较高风险信赖控制、较低风险不信赖控制、较高风险不信赖控制。 我们的综合风险评估越高（即，从我们对固有风险和控制风险的评估中得出），我们需要从检查程序中获得的保证水平就越高，从而导致需要执行“更多”的实质性程序，将审计风险保持在5％（“更多”包括程序的性质、时间和范围）。 | Y2: 综合风险评估（CRA）与测试阈值（TT）： 1、CRA选择错误或未更新 2、测试阈值系数不在GAM建议的区间内，且没有合理的解释
B4: 返回汇总页
D6: Threshold(s)
B7: 认定 | C7: CRA | D7: 各项认定1 | E7: 所有相关认定 2
B8: 完整性 (C) | C8: Minimal | D8: =IF(C8="Minimal",'Uexp.00 Lead'!$C$5*50%,IF(C8="Low",'Uexp.00 Lead'!$C$5*25%,IF(C8="Moderate",'Uexp.00 Lead'!$C$5*15%,IF(C8="High",'Uexp.00 Lead'!$C$5*10%,IF(C8="N/A","-",))))) -> 393750 | E8: =MIN($D$8:$D$11) -> 393750
B9: 发生 (O) | C9: Minimal | D9: =IF(C9="Minimal",'Uexp.00 Lead'!$C$5*100%,IF(C9="Low",'Uexp.00 Lead'!$C$5*75%,IF(C9="Moderate",'Uexp.00 Lead'!$C$5*50%,IF(C9="High",'Uexp.00 Lead'!$C$5*25%,IF(C9="N/A","-",))))) -> 787500
B10: 计量（M） | C10: Minimal | D10: =IF(C10="Minimal",'Uexp.00 Lead'!$C$5*100%,IF(C10="Low",'Uexp.00 Lead'!$C$5*75%,IF(C10="Moderate",'Uexp.00 Lead'!$C$5*50%,IF(C10="High",'Uexp.00 Lead'!$C$5*25%,IF(C10="N/A","-",))))) -> 787500
B11: 列报和披露 (P&D) | C11: Minimal | D11: =IF(C11="Minimal",'Uexp.00 Lead'!$C$5*100%,IF(C11="Low",'Uexp.00 Lead'!$C$5*75%,IF(C11="Moderate",'Uexp.00 Lead'!$C$5*50%,IF(C11="High",'Uexp.00 Lead'!$C$5*25%,IF(C11="N/A","-",))))) -> 787500
B12: 1 各项认定的测试阈值，是根据EY GAM SUBSTANTIVE DESIGN 2.2.1
B13: 中的示例测试阈值（用占TE的百分比表示）在相应风险等级（CRA）区间的上限计算得出的。
B14: 除负德/费用类别账户的完整性认定应当使用负债/费用账户表之外，其他类别账户和认定均可使用资产/收入账户表。
B15: 2 所有相关认定的测试阈值，是所有有效认定对应之测试阈值的最小值。我们在 Lead中使用该测试阈值：（a）作为选取总账账户进行测试的起点；（b）作为（需要进一步调查的）金额波动范围的起点。
B17: 在下文中描述我们当期对账户波动的预期，以及这些预期的理由。 | U17: 基础操作指引-【02】 | W17: 进阶实操提示-【02】 | Y17: 易错点-【02】
B18: 1.本年XYZ公司销售部门员工人数较上年略有增加，根据公司薪酬预算，人均薪酬预计和上年持平，预期员工工资较上年有所上升。 2.本年XYZ公司扩大了市场推广业务的覆盖城市，因此预计服务费将较上年增加。 | U18: 设定预期： 对于可以预期的费用项目，在此处记录预期的结果和理由，无法预期的无需记录。 比如： 1、职工薪酬：主要从销售部门员工人数变动、工资变动情况进行预期分析； 2、市场服务费：根据合同约定和实际执行情况，对服务费进行预期分析。 | W18: 设定预期： 若审定结果的波动与预期的波动不一致，需分析原因，如预期波动不合理，需更新预期波动，如表明存在潜在错报，需进一步调查落实。 | Y18: 设定预期： 1、未记录波动预期。 2、仅记录预期结果，未记录依据和理由。 3、记录的波动预期与实际情况差异较大。
B22: 波动范围
B23: 波动幅度 | C23: =E8 -> 393750
B24: 波动幅度（%）： | C24: 0.1
E27: |--------- TB ---------| | K27: |------- PY -------|
B28: 表1 | E28: ="货币/单位: "&'[1]Uexp.00 Lead'!C8 -> 货币/单位:
E29: ='[1]Uexp.00 Lead'!C3 -> 46022 | K29: =DATE(YEAR($E$29)-1,12,31) -> 45657 | L29: 本期和上期发生额 | N29: For X-ref | O29: Notes | P29: 进一步调查基于波动幅度？ | Q29: 进一步调查基于定性考虑？ | U29: 基础操作指引-【03】 | W29: 进阶实操提示-【03】 | Y29: 易错点-【03】
B30: 账套名称/账套编码 | C30: 总账科目编码 | D30: 科目名称 | E30: 本期账面数 | F30: 账表调整数 | G30: 本期未审数 | H30: 结构比 | I30: 审计调整数 | J30: 本期审定数 | K30: 上期审定数 | L30: 变动金额 | M30: 变动% | U30: 表1填写： 1、BKD具体步骤如下： ①将本期费用辅助明细按金额大小排序，然后按照费用性质匹配(可用Vlookup函数)上期审定明细数； ②账表调整数和审计调整数取自调整汇总表，调整汇总表需列明每个调整的调整分录、其来源及原因，避免贴死数； ③搭建与A3的link，并将本期和上期金额与A3核对一致。 2、选出需进行变动分析明细： ①将本期与上期审定数比较，对L列变动绝对值金额大于波动阈值，且M列变动率绝对值大于波动范围（%）的明细项在P列标记为是(已设置公式)；P列选“是”；Q列需基于定性考虑选择“是”或者“否”； ②对于P或Q列选“是”的费用项目，需在O列填写note索引并在下方Notes处进行分析； ③N列X-ref的是在其他section执行了程序的费用明细，一般包括： 工资及奖金、职工福利费、职工教育经费等职工薪酬项目：Tie to 应付职工薪酬计提金额中与该账户相关的部分 折旧费：Tie to 固定资产/使用权资产累计折旧计提金额中与该账户相关的部分 摊销费：Tie to 无形资产累计摊销计提金额中与该账户相关的部分 长期待摊费用摊销：Tie to 长期待摊费用累计摊销计提金额中与该账户相关的部分 租赁费：Tie to 使用权资产租赁负债底稿中直接计入当期损益的租赁费底稿（短期租赁/低价值租赁/变动租金）中与该账户相关的部分 关联方交易：Tie to 应付关联方或关联方函证交易金额 对于上述类型明细进行x-ref时，需索引至具体的底稿sheet，如<P2_101薪酬分析>，而不是PAL2&VB_SWP_职工薪酬，应在被索引的底稿的具体sheet中的某个单元格中找到被索引的数据。 | W30: 表1填写： 1、BKD明细项如出现负数，应核实清楚负数产生的原因，如系入账和冲销明细项错配所致，影响披露的，应调整BKD中的明细项；如系冲销以前年度多确认的费用，与FIC/EIC沟通，判断是否需追溯调整以前年度损益。 2、保持职业怀疑,当发现某费用科目中的某项费用存在错报时，对其他费用科目类似性质的费用亦考虑是否存在类似错报。 如销售费用的水电费存在跨期情况,那管理费用/制造费用的水电费是否也存在跨期。 3、关注性质特殊或异常项的费用明细： 1)销售费用明细中如遇到销售佣金、运输费、推广费、预计产品质量保证金损失、包装物等易错项目时，要保持职业怀疑，需先判断被审计单位的会计处理是否正确，并及时与FIC/EIC沟通。 (1)销售佣金： 会计准则中关于"增量成本（如销售佣金）"指引：a.准则规定：增量成本，是指企业不取得合同就不会发生的成本（如销售佣金等）。企业为取得合同发生的增量成本预期能够收回的，应当作为合同取得成本确认为一项资产；但是，该资产摊销期限不超过一年的，可以在发生时计入当期损益。b.应关注，若销售佣金为增量成本，应当采用与该资产相关的商品收入确认相同的基础进行摊销，计入当期损益。 (2)运输费用或推广费： 当发现销售费用中核算了运输费或推广费，需要按照新收入准则（企业会计准则第14号——收入）对运输费/推广费计入销售费用还是作为履约成本进行判断，检查其计入销售费用是否合理。 以“运输费用”为例，需要获取运输合同：(1)检查该运输费是否与履行客户合同有关：对于与履行客户合同无关的运输费用，若运输费用属于使存货达到目前场所和状态的必要支出，形成了预期会给企业带来经济利益的资源时，运输费用应当计入存货成本，否则应计入当期损益；(2)对于与履行合同相关的运输活动，发生在商品的控制转移之前的，不构成单项履约义务，相关支出应作为商品销售成本披露；发生在商品的控制转移之后的，构成单项履约义务，企业应当在确认运输服务收入的同时，将相关支出作为运输服务成本披露。 (3)预计产品质量保证金损失："服务类质保”根据收入准则，应作为“单项履约义务”分摊交易价格，同时通过“合同履约成本”归集至营业成本；“保证类质保”，根据《企业会计准则解释第18号》，应借记“主营业务成本”、“其他业务成本”等科目；本解释自印发之日（2024年12月6日）起实施，在施行日需要将原计入销售费用的质保金发生额转入当年的营业成本，从施行日至2024年12月31日应直接计入营业成本（即2024年全年发生额应记入营业成本）；其次，需要追溯调整至比较报表最早期初，那么2023年计入销售费用的质保金也应调整至2023年营业成本。故发现销售费用存在质保费用时，需立即与EIC/FIC沟通。 (4)包装物一般计入主营业务成本，而不是销售费用。因为这类包装物已经构成了产品实体的组成部分，如用于盛装液体、气体产品的瓶、罐等。如果销售费用遇到包装物，需要判断被审计单位的会计处理是否正确。 2)在费用中遇到特许权使用费、技术服务费、关联方管理费、物料消耗费等性质特殊的异常费用项，无论金额是否重大，均应从定性角度了解费用的性质，分析是否存在潜在错报风险。 3)明细项如出现“其他”项金额较大（如大于TT）或性质特殊（例如存在性质特殊的负数冲销），需进一步拆分明细项，识别其中是否包含了异常项，其他项的金额占比一般不超过总金额的10%。 4)在费用中碰到“租赁费”时，相关检查程序可在<LRE_承租人>底稿中执行并在费用底稿中建立交叉索引。 5)医药医疗行业、游戏行业、传媒行业和小家电行业等的销售费用是监管检查重点，保持高度职业怀疑，对上述行业销售费用中的广告费、销售佣金、推广费等项目予以特别关注，如发现存在舞弊风险，立即与EIC/FIC沟通。 | Y30: 表1填写： 1、本期金额未按金额大小排序 2、账表调整或审计调整明细的数字是死数，没有来源 3、若需插行时，相关列公式未拉全，导致遗漏重要变动信息； 4、A3不刷新link或用死数，未与A3核对一致； 5、需要分析的项目没有添加note进行分析 6、需要X-ref到其他底稿的项目漏X-ref或没有ref到具体的底稿表中
B31: XYZ公司 | C31: 6601.01 | D31: 职工薪酬\工资及奖金 | E31: 2050964.2 | G31: =E31+F31 -> 2050964.2 | H31: =IF($G$48<>0,G31/$G$48,"") -> 0.35303931 | J31: =G31+I31 -> 2050964.2 | K31: 1673163.8 | L31: =J31-K31 -> 377800.4 | M31: =IF(K31<>0,L31/K31,1) -> 0.2258 | N31: P2_101薪酬分析 | O31: NB1 | P31: =IF(AND(ABS(L31)>=$C$23,ABS(M31)>=$C$24),"是","否") -> 否 | Q31: 否
B32: XYZ公司 | C32: 6601.19 | D32: 服务费 | E32: 1132075.5 | G32: =E32+F32 -> 1132075.5 | H32: =IF($G$48<>0,G32/$G$48,"") -> 0.19486792 | J32: =G32+I32 -> 1132075.5 | K32: 84845.07 | L32: =J32-K32 -> 1047230.4 | M32: =IF(K32<>0,L32/K32,1) -> 12.342855 | N32: 表2 | O32: NB2 | P32: =IF(AND(ABS(L32)>=$C$23,ABS(M32)>=$C$24),"是","否") -> 是 | Q32: 是
B33: XYZ公司 | C33: 6601.02 | D33: 职工薪酬\劳动保险费 | E33: 580468.35 | G33: =E33+F33 -> 580468.35 | H33: =IF($G$48<>0,G33/$G$48,"") -> 0.099917951 | J33: =G33+I33 -> 580468.35 | K33: 146795.02 | L33: =J33-K33 -> 433673.33 | M33: =IF(K33<>0,L33/K33,1) -> 2.9542782 | N33: P2_101薪酬分析 | O33: NB1 | P33: =IF(AND(ABS(L33)>=$C$23,ABS(M33)>=$C$24),"是","否") -> 是 | Q33: 否
B34: XYZ公司 | C34: 6601.17 | D34: 差旅费 | E34: 486066.89 | G34: =E34+F34 -> 486066.89 | H34: =IF($G$48<>0,G34/$G$48,"") -> 0.083668313 | J34: =G34+I34 -> 486066.89 | K34: 689449.12 | L34: =J34-K34 -> -203382.23 | M34: =IF(K34<>0,L34/K34,1) -> -0.29499237 | P34: =IF(AND(ABS(L34)>=$C$23,ABS(M34)>=$C$24),"是","否") -> 否 | Q34: 否
B35: XYZ公司 | C35: 6601.18 | D35: 车辆使用费 | E35: 380717.88 | G35: =E35+F35 -> 380717.88 | H35: =IF($G$48<>0,G35/$G$48,"") -> 0.065534237 | J35: =G35+I35 -> 380717.88 | K35: 306763.58 | L35: =J35-K35 -> 73954.3 | M35: =IF(K35<>0,L35/K35,1) -> 0.24107914 | P35: =IF(AND(ABS(L35)>=$C$23,ABS(M35)>=$C$24),"是","否") -> 否 | Q35: 否
B36: XYZ公司 | C36: 6601.07.01 | D36: 固定资产折旧 | E36: 282392 | G36: =E36+F36 -> 282392 | H36: =IF($G$48<>0,G36/$G$48,"") -> 0.048609076 | J36: =G36+I36 -> 282392 | K36: 295887.06 | L36: =J36-K36 -> -13495.06 | M36: =IF(K36<>0,L36/K36,1) -> -0.045608821 | N36: K.03.1 折旧测试 | P36: =IF(AND(ABS(L36)>=$C$23,ABS(M36)>=$C$24),"是","否") -> 否 | Q36: 否
B37: XYZ公司 | C37: 6601.08 | D37: 租赁费 | E37: 267385.77 | G37: =E37+F37 -> 267385.77 | H37: =IF($G$48<>0,G37/$G$48,"") -> 0.046026003 | J37: =G37+I37 -> 267385.77 | K37: 279692.23 | L37: =J37-K37 -> -12306.46 | M37: =IF(K37<>0,L37/K37,1) -> -0.044000007 | N37: LR_410短期租赁和低价值租赁 | P37: =IF(AND(ABS(L37)>=$C$23,ABS(M37)>=$C$24),"是","否") -> 否 | Q37: 否
B38: XYZ公司 | C38: 6601.03 | D38: 职工薪酬\住房公积金 | E38: 192708 | G38: =E38+F38 -> 192708 | H38: =IF($G$48<>0,G38/$G$48,"") -> 0.03317147 | J38: =G38+I38 -> 192708 | K38: 519667.28 | L38: =J38-K38 -> -326959.28 | M38: =IF(K38<>0,L38/K38,1) -> -0.62917042 | N38: P2_101薪酬分析 | O38: NB1 | P38: =IF(AND(ABS(L38)>=$C$23,ABS(M38)>=$C$24),"是","否") -> 否 | Q38: 否
B39: XYZ公司 | C39: 6601.04 | D39: 职工薪酬\福利费 | E39: 163280.1 | G39: =E39+F39 -> 163280.1 | H39: =IF($G$48<>0,G39/$G$48,"") -> 0.028105948 | J39: =G39+I39 -> 163280.1 | K39: 61258.27 | L39: =J39-K39 -> 102021.83 | M39: =IF(K39<>0,L39/K39,1) -> 1.6654377 | N39: P2_101薪酬分析 | O39: NB1 | P39: =IF(AND(ABS(L39)>=$C$23,ABS(M39)>=$C$24),"是","否") -> 否 | Q39: 否
B40: XYZ公司 | C40: 6601.15 | D40: 广告宣传费 | E40: 115134.76 | G40: =E40+F40 -> 115134.76 | H40: =IF($G$48<>0,G40/$G$48,"") -> 0.01981853 | J40: =G40+I40 -> 115134.76 | K40: 11099.18 | L40: =J40-K40 -> 104035.58 | M40: =IF(K40<>0,L40/K40,1) -> 9.3732672 | P40: =IF(AND(ABS(L40)>=$C$23,ABS(M40)>=$C$24),"是","否") -> 否 | Q40: 否
B41: XYZ公司 | C41: 6601.05 | D41: 职工薪酬\工会经费 | E41: 86815.22 | G41: =E41+F41 -> 86815.22 | H41: =IF($G$48<>0,G41/$G$48,"") -> 0.014943793 | J41: =G41+I41 -> 86815.22 | K41: 173767.36 | L41: =J41-K41 -> -86952.138 | M41: =IF(K41<>0,L41/K41,1) -> -0.50039397 | N41: P2_101薪酬分析 | O41: NB1 | P41: =IF(AND(ABS(L41)>=$C$23,ABS(M41)>=$C$24),"是","否") -> 否 | Q41: 否
B42: XYZ公司 | C42: 6601.99 | D42: 其他 | E42: 31895.44 | G42: =E42+F42 -> 31895.44 | H42: =IF($G$48<>0,G42/$G$48,"") -> 0.0054902683 | J42: =G42+I42 -> 31895.44 | K42: 10045 | L42: =J42-K42 -> 21850.44 | M42: =IF(K42<>0,L42/K42,1) -> 2.1752554 | P42: =IF(AND(ABS(L42)>=$C$23,ABS(M42)>=$C$24),"是","否") -> 否 | Q42: 否
B43: XYZ公司 | C43: 6601.13 | D43: 通信/网络费 | E43: 17697.9 | G43: =E43+F43 -> 17697.9 | H43: =IF($G$48<>0,G43/$G$48,"") -> 0.0030463985 | J43: =G43+I43 -> 17697.9 | K43: 8650.2 | L43: =J43-K43 -> 9047.7 | M43: =IF(K43<>0,L43/K43,1) -> 1.0459527 | P43: =IF(AND(ABS(L43)>=$C$23,ABS(M43)>=$C$24),"是","否") -> 否 | Q43: 否
B44: XYZ公司 | C44: 6601.09 | D44: 水电气费 | E44: 12400 | G44: =E44+F44 -> 12400 | H44: =IF($G$48<>0,G44/$G$48,"") -> 0.0021344533 | J44: =G44+I44 -> 12400 | K44: 435.75 | L44: =J44-K44 -> 11964.25 | M44: =IF(K44<>0,L44/K44,1) -> 27.456684 | P44: =IF(AND(ABS(L44)>=$C$23,ABS(M44)>=$C$24),"是","否") -> 否 | Q44: 否
B45: XYZ公司 | C45: 6601.10 | D45: 办公费 | E45: 8694.7 | G45: =E45+F45 -> 8694.7 | H45: =IF($G$48<>0,G45/$G$48,"") -> 0.0014966477 | J45: =G45+I45 -> 8694.7 | K45: 4980 | L45: =J45-K45 -> 3714.7 | M45: =IF(K45<>0,L45/K45,1) -> 0.74592369 | P45: =IF(AND(ABS(L45)>=$C$23,ABS(M45)>=$C$24),"是","否") -> 否 | Q45: 否
B46: XYZ公司 | C46: 6601.12 | D46: 物耗 | E46: 753.4 | G46: =E46+F46 -> 753.4 | H46: =IF($G$48<>0,G46/$G$48,"") -> 0.00012968525 | J46: =G46+I46 -> 753.4 | K46: 301926.65 | L46: =J46-K46 -> -301173.25 | M46: =IF(K46<>0,L46/K46,1) -> -0.99750469 | P46: =IF(AND(ABS(L46)>=$C$23,ABS(M46)>=$C$24),"是","否") -> 否 | Q46: 否
D48: 合计 | E48: =SUM(E30:E47) -> 5809450.1 | F48: =SUM(F30:F47) -> 0 | G48: =SUM(G30:G47) -> 5809450.1 | H48: =SUM(H30:H47) -> 1 | I48: =SUM(I30:I47) -> 0 | J48: =SUM(J30:J47) -> 5809450.1 | K48: =SUM(K30:K47) -> 4568425.6 | L48: =J48-K48 -> 1241024.5 | M48: =IF(K48<>0,L48/K48,1) -> 0.27165256
E49: Rx | F49: Rx | G49: Rx | H49: Rx | I49: Rx | J49: Rx | K49: Rx
...

Sheet VD.00 管理费用BKD
B1: 标准底稿: VD SWP 管理费用 | V1: 基础操作指引-【01】 | X1: 进阶实操提示-【01】 | Z1: 易错点-【01】
B2: VD.00 编制汇总表并比较余额 | V2: 综合风险评估（CRA）与测试阈值（TT）： 同<VC.00销售费用BKD-基础操作指引-【01】>。 | X2: 综合风险评估（CRA）与测试阈值（TT）： 同<VC.00销售费用BKD-进阶实操提示-【01】>。 | Z2: 综合风险评估（CRA）与测试阈值（TT）： 同<VC.00销售费用BKD-易错点-【01】>。
B4: 返回汇总页
D6: Threshold(s)
B7: 认定 | C7: CRA | D7: 各项认定1 | E7: 所有相关认定 2
B8: 完整性 (C) | C8: Minimal | D8: =IF(C8="Minimal",'Uexp.00 Lead'!$C$5*50%,IF(C8="Low",'Uexp.00 Lead'!$C$5*25%,IF(C8="Moderate",'Uexp.00 Lead'!$C$5*15%,IF(C8="High",'Uexp.00 Lead'!$C$5*10%,IF(C8="N/A","-",))))) -> 393750 | E8: =MIN($D$8:$D$11) -> 393750
B9: 发生 (O) | C9: Minimal | D9: =IF(C9="Minimal",'Uexp.00 Lead'!$C$5*100%,IF(C9="Low",'Uexp.00 Lead'!$C$5*75%,IF(C9="Moderate",'Uexp.00 Lead'!$C$5*50%,IF(C9="High",'Uexp.00 Lead'!$C$5*25%,IF(C9="N/A","-",))))) -> 787500
B10: 计量（M） | C10: Minimal | D10: =IF(C10="Minimal",'Uexp.00 Lead'!$C$5*100%,IF(C10="Low",'Uexp.00 Lead'!$C$5*75%,IF(C10="Moderate",'Uexp.00 Lead'!$C$5*50%,IF(C10="High",'Uexp.00 Lead'!$C$5*25%,IF(C10="N/A","-",))))) -> 787500
B11: 列报和披露 (P&D) | C11: Minimal | D11: =IF(C11="Minimal",'Uexp.00 Lead'!$C$5*100%,IF(C11="Low",'Uexp.00 Lead'!$C$5*75%,IF(C11="Moderate",'Uexp.00 Lead'!$C$5*50%,IF(C11="High",'Uexp.00 Lead'!$C$5*25%,IF(C11="N/A","-",))))) -> 787500
B12: 1 各项认定的测试阈值，是根据EY GAM SUBSTANTIVE DESIGN 2.2.1
B13: 中的示例测试阈值（用占TE的百分比表示）在相应风险等级（CRA）区间的上限计算得出的。
B14: 除负债/费用类别账户的完整性认定应当使用负债/费用账户表之外，其他类别账户和认定均可使用资产/收入账户表。
B15: 2 所有相关认定的测试阈值，是所有有效认定对应之测试阈值的最小值。我们在 Lead中使用该测试阈值：（a）作为选取总账账户进行测试的起点；（b）作为（需要进一步调查的）金额波动范围的起点。
B17: 在下文中描述我们当期对账户波动的预期，以及这些预期的理由。 | V17: 基础操作指引-【02】 | X17: 进阶实操提示-【02】 | Z17: 易错点-【02】
B18: 1.本年管理部门员工人无变动，且XYZ公司本年制定的人均薪酬预算与上年持平，预计本年薪酬总额与上年薪酬总额基本持平。 2.本年XYZ公司对产品进行了更新换代，对××产品生产线进行了停产，停产生产线产生的相关折旧计入管理费用，预计管理费用折旧费将增加。 | V18: 设定预期： 同<VC.00销售费用BKD-基础操作指引-【02】>。 | X18: 设定预期： 同<VC.00销售费用BKD-进阶实操提示-【02】>。 | Z18: 设定预期： 同<VC.00销售费用BKD-易错点-【02】>。
B22: 波动范围
B23: 波动幅度 | C23: =E8 -> 393750
B24: 波动幅度（%）： | C24: 0.1
E27: |------- TB -------| | K27: |------- PY -------|
B28: 表1 | E28: ="货币/单位: "&'Uexp.00 Lead'!C8 -> 货币/单位: CNY | V28: 基础操作指引-【03】 | X28: 进阶实操提示-【03】 | Z28: 易错点-【03】
E29: ='Uexp.00 Lead'!C3 -> 46022 | K29: =DATE(YEAR($E$29)-1,12,31) -> 45657 | L29: 本期和上期发生额 | N29: For X-ref | O29: Notes | P29: 进一步调查基于波动幅度？ | Q29: 进一步调查基于定性考虑？ | V29: 表1填写： 同<VC.00销售费用BKD-基础操作指引-【03】>。 | X29: 表1填写： 参考<VC.00销售费用BKD-进阶实操提示-【03】>中的部分提示。 | Z29: 表1填写： 同<VC.00销售费用BKD-易错点-【03】>。
B30: 账套名称/账套编码 | C30: 总账科目编码 | D30: 科目名称 | E30: 本期账面数 | F30: 账表调整数 | G30: 本期未审数 | H30: 结构比 | I30: 审计调整数 | J30: 本期审定数 | K30: 上期审定数 | L30: 变动金额 | M30: 变动%
B31: XYZ公司 | C31: 6602010101 | D31: 职工薪酬\工资\工资 | E31: 2509657.5 | G31: =E31+F31 -> 2509657.5 | H31: =IF($G$73<>0,G31/$G$73,"") -> 0.32002798 | J31: =G31+I31 -> 2509657.5 | K31: 2574974.8 | L31: =J31-K31 -> -65317.33 | M31: =IF(K31<>0,L31/K31,1) -> -0.025366201 | N31: P2_101薪酬分析 | P31: =IF(AND(ABS(L31)>=$C$23,ABS(M31)>=$C$24),"是","否") -> 否 | Q31: 否
B32: XYZ公司 | C32: 66020401 | D32: 固定资产折旧费\房屋建筑 | E32: 1151542.4 | G32: =E32+F32 -> 1151542.4 | H32: =IF($G$73<>0,G32/$G$73,"") -> 0.14684306 | J32: =G32+I32 -> 1151542.4 | K32: 543448.2 | L32: =J32-K32 -> 608094.19 | M32: =IF(K32<>0,L32/K32,1) -> 1.1189552 | N32: K.03.1 折旧测试 | O32: NB1 | P32: =IF(AND(ABS(L32)>=$C$23,ABS(M32)>=$C$24),"是","否") -> 是 | Q32: 否
B33: XYZ公司 | C33: 660224 | D33: 物业管理费 | E33: 961328.21 | G33: =E33+F33 -> 961328.21 | H33: =IF($G$73<>0,G33/$G$73,"") -> 0.12258721 | J33: =G33+I33 -> 961328.21 | K33: 150934.03 | L33: =J33-K33 -> 810394.18 | M33: =IF(K33<>0,L33/K33,1) -> 5.3691946 | O33: NB2 | P33: =IF(AND(ABS(L33)>=$C$23,ABS(M33)>=$C$24),"是","否") -> 是 | Q33: 否
B34: XYZ公司 | C34: 6602010301 | D34: 职工薪酬\社会保险费 | E34: 697278.95 | G34: =E34+F34 -> 697278.95 | H34: =IF($G$73<>0,G34/$G$73,"") -> 0.088916026 | J34: =G34+I34 -> 697278.95 | K34: 623118.97 | L34: =J34-K34 -> 74159.975 | M34: =IF(K34<>0,L34/K34,1) -> 0.11901415 | N34: P2_101薪酬分析 | P34: =IF(AND(ABS(L34)>=$C$23,ABS(M34)>=$C$24),"是","否") -> 否 | Q34: 否
B35: XYZ公司 | C35: 66021399 | D35: 中介机构费\法律服务费 | E35: 333180 | G35: =E35+F35 -> 333180 | H35: =IF($G$73<>0,G35/$G$73,"") -> 0.042486642 | J35: =G35+I35 -> 333180 | K35: 158247.75 | L35: =J35-K35 -> 174932.25 | M35: =IF(K35<>0,L35/K35,1) -> 1.1054328 | N35: VD.01.3复核法律费用 | P35: =IF(AND(ABS(L35)>=$C$23,ABS(M35)>=$C$24),"是","否") -> 否 | Q35: 否
B36: XYZ公司 | C36: 66020501 | D36: 无形资产摊销\土地使用权摊销 | E36: 248113.56 | G36: =E36+F36 -> 248113.56 | H36: =IF($G$73<>0,G36/$G$73,"") -> 0.03163909 | J36: =G36+I36 -> 248113.56 | K36: 310141.98 | L36: =J36-K36 -> -62028.42 | M36: =IF(K36<>0,L36/K36,1) -> -0.20000008 | N36: L1.03 摊销测试 | P36: =IF(AND(ABS(L36)>=$C$23,ABS(M36)>=$C$24),"是","否") -> 否 | Q36: 否
B37: XYZ公司 | C37: 66020402 | D37: 固定资产折旧费\机器设备 | E37: 207269.62 | G37: =E37+F37 -> 207269.62 | H37: =IF($G$73<>0,G37/$G$73,"") -> 0.026430729 | J37: =G37+I37 -> 207269.62 | K37: 924.84 | L37: =J37-K37 -> 206344.78 | M37: =IF(K37<>0,L37/K37,1) -> 223.11403 | N37: K.03.1 折旧测试 | P37: =IF(AND(ABS(L37)>=$C$23,ABS(M37)>=$C$24),"是","否") -> 否 | Q37: 否
B38: XYZ公司 | C38: 6602010201 | D38: 职工薪酬\职工福利 | E38: 203363.02 | G38: =E38+F38 -> 203363.02 | H38: =IF($G$73<>0,G38/$G$73,"") -> 0.025932565 | J38: =G38+I38 -> 203363.02 | K38: 209036.26 | L38: =J38-K38 -> -5673.235 | M38: =IF(K38<>0,L38/K38,1) -> -0.027139957 | N38: P2_101薪酬分析 | P38: =IF(AND(ABS(L38)>=$C$23,ABS(M38)>=$C$24),"是","否") -> 否 | Q38: 否
B39: XYZ公司 | C39: 660217 | D39: 技术服务费 | E39: 192453 | G39: =E39+F39 -> 192453 | H39: =IF($G$73<>0,G39/$G$73,"") -> 0.024541334 | J39: =G39+I39 -> 192453 | K39: 192121.24 | L39: =J39-K39 -> 331.76 | M39: =IF(K39<>0,L39/K39,1) -> 0.0017268262 | P39: =IF(AND(ABS(L39)>=$C$23,ABS(M39)>=$C$24),"是","否") -> 否 | Q39: 否
B40: XYZ公司 | C40: 66020104 | D40: 职工薪酬\住房公积金 | E40: 170710.07 | G40: =E40+F40 -> 170710.07 | H40: =IF($G$73<>0,G40/$G$73,"") -> 0.021768707 | J40: =G40+I40 -> 170710.07 | K40: 192332.49 | L40: =J40-K40 -> -21622.42 | M40: =IF(K40<>0,L40/K40,1) -> -0.11242209 | N40: P2_101薪酬分析 | P40: =IF(AND(ABS(L40)>=$C$23,ABS(M40)>=$C$24),"是","否") -> 否 | Q40: 否
B41: XYZ公司 | C41: 660203 | D41: 水电气费 | E41: 147964.75 | G41: =E41+F41 -> 147964.75 | H41: =IF($G$73<>0,G41/$G$73,"") -> 0.018868256 | J41: =G41+I41 -> 147964.75 | K41: 143559.64 | L41: =J41-K41 -> 4405.105 | M41: =IF(K41<>0,L41/K41,1) -> 0.030684842 | P41: =IF(AND(ABS(L41)>=$C$23,ABS(M41)>=$C$24),"是","否") -> 否 | Q41: 否
B42: XYZ公司 | C42: 660208 | D42: 差旅费 | E42: 131453.27 | G42: =E42+F42 -> 131453.27 | H42: =IF($G$73<>0,G42/$G$73,"") -> 0.016762735 | J42: =G42+I42 -> 131453.27 | K42: 25717.98 | L42: =J42-K42 -> 105735.29 | M42: =IF(K42<>0,L42/K42,1) -> 4.1113373 | P42: =IF(AND(ABS(L42)>=$C$23,ABS(M42)>=$C$24),"是","否") -> 否 | Q42: 否
B43: XYZ公司 | C43: 660222 | D43: 劳动保护费 | E43: 125820 | G43: =E43+F43 -> 125820 | H43: =IF($G$73<>0,G43/$G$73,"") -> 0.016044388 | J43: =G43+I43 -> 125820 | K43: 99000 | L43: =J43-K43 -> 26820 | M43: =IF(K43<>0,L43/K43,1) -> 0.27090909 | P43: =IF(AND(ABS(L43)>=$C$23,ABS(M43)>=$C$24),"是","否") -> 否 | Q43: 否
B44: XYZ公司 | C44: 66021303 | D44: 中介机构费\上市公司财务报告年度审计费 | E44: 90849.06 | G44: =E44+F44 -> 90849.06 | H44: =IF($G$73<>0,G44/$G$73,"") -> 0.011584944 | J44: =G44+I44 -> 90849.06 | K44: 84150.94 | L44: =J44-K44 -> 6698.12 | M44: =IF(K44<>0,L44/K44,1) -> 0.079596496 | P44: =IF(AND(ABS(L44)>=$C$23,ABS(M44)>=$C$24),"是","否") -> 否 | Q44: 否
B45: XYZ公司 | C45: 660218 | D45: 修理费 | E45: 83407.77 | G45: =E45+F45 -> 83407.77 | H45: =IF($G$73<>0,G45/$G$73,"") -> 0.010636041 | J45: =G45+I45 -> 83407.77 | K45: 86987.625 | L45: =J45-K45 -> -3579.855 | M45: =IF(K45<>0,L45/K45,1) -> -0.041153612 | P45: =IF(AND(ABS(L45)>=$C$23,ABS(M45)>=$C$24),"是","否") -> 否 | Q45: 否
B46: XYZ公司 | C46: 66021001 | D46: 车辆费用\车辆燃油费 | E46: 66292.65 | G46: =E46+F46 -> 66292.65 | H46: =IF($G$73<>0,G46/$G$73,"") -> 0.008453545 | J46: =G46+I46 -> 66292.65 | K46: 8106.51 | L46: =J46-K46 -> 58186.14 | M46: =IF(K46<>0,L46/K46,1) -> 7.1777053 | P46: =IF(AND(ABS(L46)>=$C$23,ABS(M46)>=$C$24),"是","否") -> 否 | Q46: 否
B47: XYZ公司 | C47: 66020105 | D47: 职工薪酬\工会经费 | E47: 62920.29 | G47: =E47+F47 -> 62920.29 | H47: =IF($G$73<>0,G47/$G$73,"") -> 0.0080235064 | J47: =G47+I47 -> 62920.29 | K47: 47299.905 | L47: =J47-K47 -> 15620.385 | M47: =IF(K47<>0,L47/K47,1) -> 0.33024136 | N47: P2_101薪酬分析 | P47: =IF(AND(ABS(L47)>=$C$23,ABS(M47)>=$C$24),"是","否") -> 否 | Q47: 否
B48: XYZ公司 | C48: 66021401 | D48: 财产保险费\固定资产保险费 | E48: 51210.52 | G48: =E48+F48 -> 51210.52 | H48: =IF($G$73<>0,G48/$G$73,"") -> 0.0065302931 | J48: =G48+I48 -> 51210.52 | K48: 50309.58 | L48: =J48-K48 -> 900.94 | M48: =IF(K48<>0,L48/K48,1) -> 0.017907921 | P48: =IF(AND(ABS(L48)>=$C$23,ABS(M48)>=$C$24),"是","否") -> 否 | Q48: 否
...

Sheet VC&VD.01.2 TOD 年审
C2: 该底稿适用项目组年审时执行全年TOD程序。即不在预审分配样本执行TOD。 | W2: 基础操作指引-【01】 | Y2: 进阶实操提示-【01】 | AA2: 易错点-【01】
C3: 目标 | W3: 样本总体： 填写D列“总体名称”、E列“数据来源 X-ref”、F列从<VC.00销售费用BKD><VD.00管理费用BKD>的合计数进行link。 | Y3: 样本总体： 1、执行费用详细测试考虑样本总体时，哪些费用类型可以一并考虑？ 1）利润表代表性抽样应用于包含具有类似特征（如大小和风险）的项目的总体，因为具有不同特征的总体可能面临不同的重大错报风险。因此，在执行相同认定的审计程序时，我们常从执行效率角度，将具有相似风险特征的总体作为一个整体执行抽样。 2)在常见的费用类型中，如折旧摊销等属于长期资产流程，工资薪金属于职工薪酬流程；这些和其他费用会计处理和风险上存在显著的差异，不属于同一重大流程，此时不应将其和其他费用作为一个总体执行代表性样本选择。 3)实务中，研发费用需要进行单独讨论：如在剔除上述费用后，剩余研发费用的性质和其他销售管理费用一致，同处于一个流程，此时可以将研发费用纳入剩余费用的抽样范围。如剩余性质的研发费用核算与一般的销售管理费用显著不同，例如涉及资本化处理等，此处研发费用应作为单独的SCOT了解，并单独执行细节测试抽样，检查要素也须对应调整。 4)相对地，项目组也可以选择按照不同费用科目（销售费用、管理费用等），单独按科目抽样执行细节测试，无须耗费大量时间合并费用总体（尤其是针对大型企业）。 2、可以预审时确认哪几个费用科目可以合并抽样，不得将非同一交易类别的营业外收支、其他收益等与销售费用、管理费用合并抽样。 3、对使用SAP、Oracle系统的被审计单位，存在较多预提和冲销、分摊、系统自动生成凭证无附件的情况，建议按费用性质单独执行TOD程序，而无需考虑该费用性质列报于何费用科目。 4、任何在底稿中出现数字须要有验证的过程; 不建议将population放在底稿中，但是我们的底稿记录需要足以被“Reperform". | AA3: 样本总体： 1、将风险不同的制造费用与销售费用、管理费用合并抽样； 2、将非同一交易类别的营业外收支、其他收益等损益科目与销售费用、管理费用合并抽样； 3、不考虑CRA风险水平可能存在不同，任何情况下均将销售费用和管理费用合并抽样。 4、抽样策略1.1中F列总体金额错误填写为剔除后样本总体金额，未与BKD核对一致； 5、未填写D列“总体名称”、E列“数据来源 X-ref”； 6、样本总体金额包含了结转本年利润的金额，抽样前未将样本总体的加总金额与BKD核对一致。
C4: 通过在全年费用交易中选取关键项（key item）和代表性样本进行细节测试，确保对费用交易在本年度内准确记录并正确分类。
C5: 非同一重大交易类别且不具有类似特征(如不同CRA)的费用类型，应当分别进行TOD测试。
C9: 抽样策略
C10: 1 | D10: 确定样本总体和完整性测试
C12: 1.1 | D12: 总体名称 | E12: 数据来源 X-ref | F12: 金额
D13: 销售费用 | E13: VC.00销售费用BKD | F13: ='VC.00 销售费用BKD'!E48 -> 5809450.1
D14: 管理费用 | E14: VD.00管理费用BKD | F14: ='VD.00 管理费用BKD'!E73 -> 7841994.1
D15: 总体金额 | F15: =SUM(F13:F14) -> 13651444 | W15: 基础操作指引-【02】 | Y15: 进阶实操提示-【02】 | AA15: 易错点-【02】
F16: Rx | W16: 剔除样本： 1、a.在其他底稿中已执行程序项：D列按照拟剔除的费用性质填写D列；G列“金额”需从<VC.00销售费用BKD>、<VD.00管理费用BKD>等link数值，不能贴死数。E列“数据来源X-ref”对应填写link的相关表格如<VC.00销售费用BKD>、<VD.00管理费用BKD>等。F列“执行审计工作底稿X-ref”填写剔除项执行程序的底稿名称（注意要填对具体执行程序sheet名）；a.的剔除项需在将数据上传skywind抽样工具前进行手工剔除。 2、b.负值： 1）在完成a的剔除工作后，再对总体中剩余的负值进行剔除，对负值剔除可以在Skywind抽样工具中执行剔除；如在skywind中进行了负值的剔除，负值G列填写的金额需要与<VC&VD.01.2 TOD 抽样工具输出-年审>中“必要的数据排除项金额”核对一致。 2）剔除的负值项需单独执行审计程序，并将抽样策略及检查情况记录于表2中。 3、“扣除剔除项后样本总体金额”：需与<VC&VD.01.2 TOD 抽样工具输出-年审>中“样本池总金额”核对一致。 | Y16: 剔除样本： 1、“1.2剔除项”的说明 a.在其他底稿中已执行程序项（by nature剔除）： (1)由于归属于不同的重大交易类别，已在其他底稿执行审计程序的明细项：如折旧摊销、职工薪酬、租赁费等。这些剔除项应索引并link数据来源（例如link销售费用、管理费用明细项)，并X-ref到执行审计工作的具体底稿，需在canvas中找到具体的底稿，确保已对其执行了审计程序。 (2)在本底稿其他审计程序中已获得充分、适当审计证据的明细项：对于剔除的在本底稿其他程序执行过程序的费用明细项，剔除时需确认已经通过执行上述程序获取该项费用充分适当的审计证据； (3)剔除上述两类明细项后，剩余总体中还存在金额重大的预提和冲销费用过程明细项：考虑剔除预提和冲销费用，并对已剔除的预提和冲销费用单独执行检查程序. 识别预提和冲销费用并考虑是否在TOD测试时予以剔除可参考如下步骤： Step（1）：询问被审计单位了解其采取预提和冲销进行账务处理的费用类型，并检查其财务系统对预提和冲销费用类型是否有相关标识；或根据凭证摘要的描述及发生额为负数等条件筛选出账务处理为预提和冲销的费用类型并向被审计单位进行验证（如根据摘要筛选带“暂估”、“冲”、“冲销”等字样，且其发生额为负数的JE）; Step（2）：判断已识别的预提和冲销费用类型的重要性，如费用金额不重大（如发生额小于TT）且发生错报的风险低，可以不考虑剔除，纳入样本池抽样；如费用金额重大或发生错报的风险高，应将该费用类型予以剔除（不考虑剔除项合计金额是否为零），并单独执行检查程序。 此处列举“预提和冲销”是为了说明：如果已识别出预提和冲销的JE并已在其他底稿执行程序，在确定样本总体时可以剔除。实务中如果剔除了本月计提，下月全额冲销，正负对抵为0的项目，需要在底稿中进行相应的说明和记录，即已对剔除项执行了工作。 对于预提和冲销类费用如何抽样进行凭证的检查，参考小灯泡中的<VC&VD.01.2 TOD-注释1：预提冲销负数处理> | AA16: 剔除样本： 1、未落实费用明细项是否已在其他底稿或其他程序获取充分适当的审计证据时就剔除该明细项； 2、未剔除金额重大且容易剔除的预提冲销费用项； 3、未将a.剔除项在上传抽样工具前进行手工剔除； 4、未记录剔除样本的原因； 5、未记录剔除项数据来源和执行审计工作的底稿名称； 6、E列“数据来源X-ref”错误索引至执行程序的底稿； 7、“扣除剔除项后样本总体金额”未与<VC&VD.01.2 TOD 抽样工具输出-年审>中“样本池总金额”核对一致。 8、G列剔除项金额没有link数据来源，直接贴死数。 9、先link数据来源，然后在BKD做了排序，导致链接的数据出错
C17: 1.2 | D17: 剔除： | E17: 数据来源 X-ref | F17: 执行审计工作底稿X-ref | G17: 金额
D18: a. 在其他底稿中已执行程序项：(以下可由项目组自定义)
D19: 固定资产折旧费 | E19: VC.00 销售费用BKD | F19: K.03.1 折旧测试 | G19: ='VC.00 销售费用BKD'!E36 -> 282392
D20: 固定资产折旧费 | E20: VD.00 管理费用BKD | F20: K.03.1 折旧测试 | G20: ='VD.00 管理费用BKD'!E32+'VD.00 管理费用BKD'!E37+'VD.00 管理费用BKD'!E50+'VD.00 管理费用BKD'!E57+'VD.00 管理费用BKD'!E61 -> 1438209.2
D21: 无形资产摊销费 | E21: VD.00 管理费用BKD | F21: L1.01.1 BKD | G21: ='VD.00 管理费用BKD'!E36+'VD.00 管理费用BKD'!E66 -> 249267.3
D22: 工资薪酬 | E22: VC.00 销售费用BKD | F22: VB01.1工资SAP/VB.02雇主成本SAP | G22: ='VC.00 销售费用BKD'!C64 -> 3074235.9
D23: 工资薪酬 | E23: VD.00 管理费用BKD | F23: VB01.1工资SAP/VB.02雇主成本SAP | G23: ='VD.00 管理费用BKD'!E31+'VD.00 管理费用BKD'!E34+'VD.00 管理费用BKD'!E38+'VD.00 管理费用BKD'!E40+'VD.00 管理费用BKD'!E47+'VD.00 管理费用BKD'!E65 -> 3645321.8
D24: 租赁费 | E24: VC.00 销售费用BKD | F24: LR_使用权资产租赁负债 | G24: ='VC.00 销售费用BKD'!E37 -> 267385.77
D25: 服务费 | E25: VC.00 销售费用BKD 表2 | F25: VC.00 销售费用BKD 表2 | G25: ='VC.00 销售费用BKD'!E32 -> 1132075.5
D26: 中介机构费\法律服务费 | E26: VD.00 管理费用BKD | F26: VD.01.3复核法律费用 | G26: ='VD.00 管理费用BKD'!E35 -> 333180
D27: b. 负值 | E27: VC&VD.01.2 TOD 抽样工具输出-年审 | F27: 对于负值我们执行的审计工作详见以下表2 | G27: -1093226.4
D29: 剔除样本合计 | G29: =SUM(G19:G27) -> 9328841.1
G30: Rx
D31: 扣除剔除项后样本总体金额： | G31: =F15-G29 -> 4322603.2
C34: 2 | D34: 确定关键项（key item） | E34: 数量 | F34: 金额 | W34: 基础操作指引-【03】 | Y34: 进阶实操提示-【03】 | AA34: 易错点-【03】
D35: 单笔发生额大于测试阈值 | E35: 0 | F35: 0 | W35: 确定关键项（key item）及抽取代表性样本： 1、确定关键项：如何选择Key items？ 确定关键项应同时考虑定性、定量因素： 1）定量：将单笔大于测试阈值（testing threshold）的作为key item，注意：费用TOD程序应对的认定包括发生、计量、列报和披露，不涉及完整性认定，因此应选择发生、计量、列报和披露认定所对应的测试阈值中最小的测试阈值作为key item的定量标准； 当项目组认为基于定量标准来识别关键项合适时，可以使用《实质性设计:设计实质性程序》中2.2中给出的各类账户在不同CRA下的测试阈值百分比辅助确定关键项的定量标准，但需要提醒的是：该百分比区间仅为参考，项目组还应结合上述其他因素综合考虑。另外，某些情况下，测试阈值可以超过 TE，例如：当相关总体中存在一些金额高于TE的项，这些项在金额上明显异于其他项，项目组同时设计了其他相关实质性程序以应对同一认定。当项目组将关键项的定量阈值设置为超过 TE 的金额，应在底稿中妥善记录理由。 2）定性：选取性质特殊或存在风险的项目作为Key item，如具有某些定性特征因而更有可能包含重大错报的项，例如可疑、异常、存在较高重大错报风险或存在错报历史的项异常项或交易、于资产负债表日或中期报告日或附近时间所记录的交易、关联方交易等。我们需要将选择定性因素的标准记录于底稿中。一般通过BKD的ARP分析识别的定性项目可作为此处的定性样本。 定量关键性样本的测试阈值、定性关键性样本的定性因素需要确定相应的标准。 2、关键项数量和金额与<VC&VD.01.2 TOD 抽样工具输出-年审>的关键项信息核对一致。 3、使用安永抽样工具确定扣除关键项后的剩余样本总体中的代表性样本的数量，若选择上传样本总体，能通过工具直接输出具体的代表性样本，若选择不上传总体，则可通过EY Random工具输出具体的代表性样本。 | Y35: 确定关键项（key item）及抽取代表性样本： 1、如费用科目剔除职工薪酬、折旧摊销等非同一SCOT费用类型后，发生额小于TE无需使用抽样工具抽样或为非复杂实体抽取样本数量为0时，在底稿做如下描述：剔除XXX费用类型后，剩余样本总体无金额大于测试阈值的样本，且从性质判断均不重大，我们认为无需再进一步执行抽样检查。 2、对于通过某费用类科目统一归集，再分摊至其他费用、成本科目的费用项目，通常这类业务记账标识等与预提冲销会有区别，应与被审计单位沟通各自的识别标记，以免混淆；这种情境下，此类费用项目应在统一归集及分摊的损益表科目执行TOD程序，且需在TOD抽样时作为单独的剔除项执行测试，其他科目直接剔除并ref。 3、注意“使用安永抽样工具对扣除关键项后的剩余样本总体抽取代表性样本”，上传skywind的样本总体应该是G31单元格，不应该是E42单元格，若未将关键性样本纳入样本总体，且剩余总体小于TE的情况下，skywind工具会报错。 4、实务中，若样本量特别大，上传会导致工具严重卡顿的情况下，可以选择不上传数据，仅使用工具选择样本量，然后线下手动选择关键样本以及使用EY random工具选择具体的代表性样本。 | AA35: 确定关键项（key item）及抽取代表性样本： 1、已单独执行审计程序的费用明细项仍包括在样本池中进行抽样； 2、性质特殊的项未作为关键样本； 3、上传到工具中的样本总体未包含关键项和负值项
D37: 合计 | E37: =SUM(E35:E35) -> 0 | F37: =SUM(F35:F35) -> 0
E38: Rx | F38: Rx
C40: 3 | D40: 使用安永抽样工具对扣除关键项后的剩余样本总体抽取代表性样本
D42: 扣除剔除项和关键项后剩余样本总体： | E42: =G31-F37 -> 4322603.2
W49: ●关于抽样策略的更多指引，可参考：
W50: 《审计抽样指南》
B51: 表1 | C51: 我们对抽出的关键项和代表性样本执行以下程序： | W51: 《ASSR1 - 审计抽样在实质性程序中的应用》
C52: 安永属性测试说明：获取相关支持性文件（如采购订单、发票、交货单、供应商合同、供应商借项通知单、结算单），检查了日记账分录，并得出结论：所记录的费用为： | W52: 基础操作指引-【04】 | Y52: 进阶实操提示-【04】 | AA52: 易错点-【04】
C53: A | D53: 金额与支持性文件核对一致。 | W53: 检查样本： 1、将<VC&VD.01.2 TOD 抽样工具输出-年审>抽取的样本粘贴至表1； 2、在D列填充样本类型为关键项/代表性样本； 3、需要检查支持性证据并在K,L,M,N列中记录以下信息： （1）供应商/分包商名称：根据获取的支持性文件填写供应商/分包商名称； （2）获得的支持性证据的名称及编号：“支持性证据”的名称需要全部填列，“编号”可列示合同/发票/结算资料编号等，可以只列举其中主要的一项关键支持性文件编号。 填写支持性文件的编号是为了让TOD详细测试足以“Reperform"，即其他有经验的人员通过检查同样的支持性证据，足以形成同样的审计结论。由于TOD测试样本的支持性证据通常不会被上传canvas存档，因此需要在底稿中记录获取的支持性证据及编号（编号可只填列其中关键一项，如发票号、费用报销单编号等），以便于可以reperform. （3）获得的关键交易凭据日期（费用实际发生日期）：根据获取到的支持性文件填写费用实际发生日期（如系某一期间的费用，可填列到月），费用实际发生日期的支持性文件包括但不限于：交货单、服务确认单、结算明细、行程单等，发票日期通常较难代表实际交易发生日期。如获取到多个支持性文件时，应相互验证检查业务实际发生日期准确后再填列。 （4）获得的交易凭据金额（费用实际发生金额）：根据获取到的支持性文件填列费用实际发生金额，费用实际发生金额的支持性文件包括但不限于结算资料、发票、合同/协议等。 4、O列check支持性证据金额与凭证金额之间的差异，若存在差异，需关注并解释； 5、费用详细测试所要求执行的“安永属性测试”的具体说明： A.金额与支持性文件核对一致。——支持性文件显示的金额和账面记录金额一致。 B.记录在恰当的期间。——根据获取的支持性文件，检查费用的实际发生日期是否恰当； C.分类恰当（即金额被记录至适当的账户，并包含在恰当的利润表项目中），这是基于费用的性质以及我们对该实体会计政策的理解。——检查是否根据支持性文件，根据费用的性质计入了适当的明细账户（例如：销售费用/差旅费）。 对于每一个测试属性，根据执行的情况填写Y或者N，不能填不适用（N/A）。 | Y53: 检查样本： 1、保有职业怀疑，当在TOD发现例外情况时，在第一时间反馈给EIC。发现错报时候要考虑该错报是否具有共同特征，总体中是否有其他样本存在同样的错误: 比如管理费用的水电费跨期，销售费用/制造费用的水电费是否跨期； 2、对于测试属性B<如果该笔费用尚未支付，检查证据以确认其在期末是否适当计提>，此处的确认是否计提不是检查计提明细，而是要检查外部证据，对于按期计提的费用，应进行retest； 3、费用的原始凭证/支持性证据通常包括哪些？ 通常包括：合同；经批准的采购申请单、费用报销单、采购/费用明细清单；计提计算表、发票、结算资料。 1> 广告费、业务宣传费：合同、公司内部审批单、计量/结算单、发票； 2> 业务招待费：业务招待费审批单、费用报销审批单、发票； 3> 低值易耗品：公司内部审批单、领用单/领用统计表（视公司情况而不同）、出库单； 4> 差旅费：出差申请单、费用报销审批单、行程单、发票； 5> 办公费：费用报销审批单、办公用品明细、发票； 6> 会议费：费用报销审批单、合同、会议通知、会议签到表、会议纪要、发票； 7> 中介机构费、咨询费（含顾问费）、诉讼费：合同、费用报销审批单、账单、发票； 8> 培训费：培训通知、费用报销审批单、培训签到表、发票； 9> 会员费：费用报销审批单、会员证明、发票； 10> 计提类型的费用：计提测算表以及计提所依据的相关原始外部证据（如合同、记载数量的相关支持性证据） 提醒：付款水单不是细节测试必须获取的支持性文件，如果是IPO项目，需根据实际情况选择是否获取银行水单以执行相关核查工作。 举例： （1）某项目抽中的TOD样本为某部门的水电费，会计凭证附件为管理层自制的“内部分摊计算表”，需要注意该“内部分摊计算表”并不构成外部的“支持性证据”；我们需要进一步将内部分摊计算表所记录的水电费总金额和水电费账单及发票进行对比，并检查分摊依据是否合理。实务中常见的分摊依据举例：1.按部门使用面积；2.按部门独立抄表的水电表的读数等。 （2）TOD 查看的是预提计算表一定要验证预提逻辑的合理性和基数的准确性。 提醒：检查样本时，应详细记录所检查支持性证据的信息，以达到可以“reperform”的程度。 另外提示：若发现错报，则需参考<TOD错报处理方案>的指引进行处理 请参考GAM 审计抽样<4.8 评价样本结果并对其作出结论>进行处理 | AA53: 检查样本： 1、测试的样本与<VC&VD.01.2 TOD 抽样工具输出-年审>抽样结果不一致； 2、未按"安永属性测试”执行测试，或实际是例外，但记录为无异常； 3、O列check支持性证据金额与凭证金额之间存在差异，未解释； 4、对检查出的例外情况，未执行进一步的审计工作； 5、检查原始凭证为费用按部门使用量计算的分配表，未进一步检查到分摊前的总金额、并检查分摊依据是否合理； 6、未记录检查样本支持性证据的信息，如费用实际发生日期、实际发生金额、支持性文件编号； 7、获得的支持性证据的名称及编号只填写了“记账凭证”字样。
C54: B | D54: 记录在恰当的期间。
C55: C | D55: 分类恰当（即金额被记录至适当的账户，并包含在恰当的利润表项目中），这是基于费用的性质以及我们对该实体会计政策的理解。
P58: EY Works
C59: 抽样ID | D59: 样本类型 | E59: 凭证日期 | F59: 凭证号 | G59: 凭证摘要 | H59: 科目编码 | I59: 科目名称 | J59: 凭证金额 | K59: 供应商/分包商名称 | L59: 获得的支持性证据的名称及编号 | M59: 获得的交易凭据日期（费用实际发生日期） | N59: 获得的交易凭据金额（费用实际发生金额） | O59: 支持性证据金额与凭证金额之间的差异 | P59: A | Q59: B | R59: C | S59: 如有异常，请解释
...

Sheet VC&VD.01.2 TOD 抽样工具输出-年审
B1: Skywind-TOD | G1: 抽样策略工作底稿
A2: 客户名称 | D2: XYZ公司
A3: 截止日期 | D3: 2025/12/31
A4: Canvas ID | D4: 0000
A6: 抽样项目基础信息 | O6: 基础操作指引-【01】 | Q6: 进阶实操提示-【01】 | S6: 易错点-【01】
O7: 基础信息： 1、审计期间：若只在年末执行TOD测试，则选”期末“； 2、测试涵盖的认定：细节测试验证发生，计量，列报和披露，不涉及完整性认定； 3、可容忍误差 （TE）、是否存在与上述认定相关的舞弊或特别风险、综合风险评估（CRA）、是否为PCAOB审计等信息，需要按照Canvas设置和Canvas内对应底稿的评估结果进行填列并与项目组沟通确认。 以上信息填列错误可能会导致样本量计算不准确，导致审计程序执行不足或过度审计。在不确定时请及时与FIC或EIC确认。 | Q7: 基础信息： ●实体复杂度： 实体是否为非复杂实体（结论）：项目按性质分为两类：复杂和非复杂（NCE），其中NCE需要满足以下条件：该实体非PIE或该实体非PIE的组成部分且该审计程序不用于支持集团审计结论。 ●信息及时更新： 底稿完成前再次确认最终TE金额。如抽样完成后，TE变小，需要根据TE的变动情况考虑重新计算应抽取的样本数量并检查补充样本，同时在TOD底稿做好记录。即当最终的TE大于抽样时的TE无需重新执行抽样程序补充样本；否则需要根据最终的TE重新抽取样本，新抽取的样本数量剔除已经检查的样本数量后再在新抽取的样本中补充检查剩余的样本，剩余样本选择的理由需在底稿中进行记录。 | S7: 基础信息： 1、基本信息填列不正确，导致样本量计算错误； 2、TE、CRA等信息发生变化，未及时更新； 3、认定选错 4、实体是否为PIE选择错误。常见于PIE的组成部分，比如公司是PIE公司的组成部分，scope为特定程序，且销售费用、管理费用包含在该特定程序的范围内，即该公司的销售费用、管理费用程序为集团审计结论提供证据。审计团队在填列参数时，错误的选择为非PIE。
A8: 版本号 | F8: V2.0.0
A9: Skywind TOD 抽样记录 | F9: 033ABBD5B21C4C05ADF7A4E16AB86948
A10: 测试类型 | F10: 详细测试
A11: 重大账户类型 | F11: 费用
A12: 抽样科目 | F12: U.管理费用, U.销售费用
A13: 审计期间 | F13: 期末
A14: 是否已执行利润表中期抽样 | F14: 否
A15: 可容忍误差 （TE） | F15: 787,500.00
A16: 测试涵盖的认定 | F16: 存在/发生, 计量/计价, 列报和披露
A17: 是否存在与上述认定相关的舞弊或特别风险？ | F17: 否
A18: 综合风险评估 | F18: 最低
A19: 是否为PCAOB审计？ | F19: 否
... A22: 是否适用于非复杂方法？ | F22: 否
O23: 基础操作指引-【02】
A24: 源数据汇总 | O24: 数据导入： 将做完a类剔除项之后的样本总体导入抽样工具。 数据导入有三种方式： 1、Excel/CSV明细：直接上传整个文件 （1）选择文件并上传 （2）选择数据源所在sheet页 （3）匹配详细信息，指选择金额列和抽样单位，其中金额列为必选字段。 2、援引底稿：在打开的文件中直接选定数据源 （1）点击抓取数据，在打开的文件中直接选定数据源，并确定 （2）匹配详细信息，指选择金额列和抽样单位，其中金额列为必选字段。 3、账套：云端导入账套
A26: 导入的数据文件
A27: 文件名 | E27: 文件类型 | G27: sheet | H27: 上传日期
A28: 样例-20251231 XYZ公司-抽样样本池.xlsx | E28: xlsx | H28: 2025/10/09
A30: 匹配详细信息
A31: 抽样单位列： | F31: Month, 日期, 凭证号, 摘要, 科目代码, 科目, 科目名称, 序号
A32: 抽样单位货币列： | F32: 净额
A33: 抽样单位详情：
O34: 基础操作指引-【03】 | Q34: 进阶实操提示-【03】 | S34: 易错点-【03】
A35: 样本池汇总 | O35: 样本池： 1、已上传数据：由于前述步骤已执行清单与销售费用、管理费用明细表、样本总体核对，已上传数据应与上述金额一致。 2、必要的数据排除项：由于其他非本程序测试范围的资产交易类型均在其他程序中执行，建议在上传数据时，仅上传本次测试的样本总体明细。即不建议将内部研发、企业合并等其他交易明细一同上传后再剔除。除此之外常见的数据排除项是已经确定的关键项、负值项。 3、请确保代表性样本金额合计与<VC&VD.01.2 TOD 年审>代表性样本总体金额一致； | Q35: 样本池： ●负值剔除项： 1、如果费用明细TOD样本池中存在负数样本，应对负值异常项进行调查： 2、对于金额不重大的负值，在抽样过程中进行剔除，并记录原因和对抽样结果的影响。 | S35: 样本池： 1、未使用Skywind工具或Smart Sampling抽样工具进行抽样，或未在底稿保留选样输出结果； 2、样本总体与<VC&VD.01.2 TOD 年审>金额不一致； 3、对上传数据不当剔除，亦未进行说明。
A37: 数据上传转换步骤
A38: 已上传数据 | F38: 3,229,376.78
A39: 必要的数据排除项 | F39: -1,093,226.37
A40: 必要的数据排除项类型 | F40: 所有负值
A41: 样本池总体金额 | F41: 4,322,603.15
A42: 排除项总量 | F42: 148
A43: 已删除零余额（行数） | F43: 0
A44: 已删除空余额（行数） | F44: 0
A45: 已删除负余额（行数） | F45: 148
A46: 已删除正余额（行数） | F46: 0
...

Sheet VC&VD.01.2 TOD 预审+剩余期间
C2: 该底稿适用项目组将TOD样本在年审预审中进行分配，并分别在预审和年审中执行TOD。
C3: 目标
C4: 通过在全年费用交易中选取关键项（key item）和代表性样本进行细节测试，确保对费用交易在本年度内准确记录并正确分类。
C5: 非同一重大交易类别且不具有类似特征(如不同CRA)的费用类型，应当分别进行TOD测试。
W6: 基础操作指引-【01】 | AL6: 进阶实操提示-【01】 | AT6: 易错点-【01】
W7: 抽样策略： 1、预审和年审分别使用抽样工具抽样时，抽样策略中“样本总体”和“剔除项”金额的填列方式： 1）预审时，在1.1的F列link抽样科目BKD中的合计金额、在1.2的G列link对应科目BKD中二级明细的金额，因年审时需要将BKD中的预审金额更新为整个期间的金额，故应在年审时断开上述“预审期间”列与BKD的link； 2）年审时，在1.1 的G列建立公式“=对应科目BKD中的合计金额-F列预审期间的金额”、在1.2 H列建立公式“=对应科目BKD中二级明细金额-G列预审期间的金额”。 2、预审期间的“负值”金额和“扣除剔除项后样本总体金额”应与<VC&VD.01.2 TOD 抽样工具输出-预审>的剔除负值金额、抽样总体金额核对一致；剩余期间的“负值”金额和“扣除剔除项后样本总体金额”应与<VC&VD.01.2 TOD 抽样工具输出-剩余期间>的剔除负值金额、抽样总体金额核对一致。 提示：以下2种场景下，建议预审期间只抽Key item进行测试，无需使用抽样工具抽代表性样本进行测试，年审期间使用抽样工具一次抽取所有的key item和代表性样本进行测试： 场景一：CRA为最低 场景二：剔除key item后剩余的样本总体小于2倍TE 另外，对于剔除key item后剩余的样本总体大于2倍TE且小于5倍TE的场景，需与项目组沟通确定是否可以在预审期间只抽Key item进行测试、不使用抽样工具抽代表性样本进行测试 | AL7: 抽样策略： | AT7: 抽样策略： 1、使用Skywind抽样工具在中期和年审之间分配样本时错误的选用了MUS抽样方法； 2、对剩余期间补充抽样时，应在预审抽样记录的基础上进行，否则skywind生成抽样结果时，无法将剩余期间补充抽样和预审抽样合并输出。 3、分段执行TOD时，错误分配各期间的样本量（2025年2月20日质胜之道发布过【底稿常见错误提示-方法论篇】里的”常见错误1： 分段执行TOD时，错误分配各期间的样本量“）
C8: 抽样策略 | AL8: 1、在预审和年审分配TOD测试样本是为了审计效率考虑，将一部分审计工作放到预审来做。这样做可以平衡预审与年审之间的工作量，有利于及早发现重大会计与审计问题，及时调整审计策略，也使得项目组和被审计单位有更为充足的时间解决问题。 2、只有在使用Random（随机抽样方法）进行抽样时，我们可以使用Skywind抽样工具在中期和年审之间分配样本。 如计划使用MUS抽样方法,由于抽样方式必须是 full population 的原因，只能在年末一次完成，不能在预审和年审之间拆分样本。 3、问题：如果执行IPO审计，如已在630审计时对费用进行了详细测试，930审计时能否将630作为预审抽样，将930作为剩余期间抽样？如果需要发表审计意见的期间是1-9月，且1-6月已经使用安永抽样工具使用随机抽样方法进行了抽样测试；930审计时可以将1-9月作为完整的期间重新计算代表性样本数量，并按照上面3的描述，使用skywind重新计算1-9月整个期间的代表性样本数量，并将代表性样本在1-6月和7-9月之间分配。
C9: 1 | D9: 确定样本总体和完整性测试
F10: AA | G10: BB | H10: CC=AA+BB
C11: 1.1 | D11: 总体名称 | E11: 数据来源 X-ref | F11: 预审期间（如1-9月份） | G11: 剩余期间（如10-12月份) | H11: 合计
D12: 销售费用 | E12: VC.00销售费用BKD | F12: 4317866.6 | G12: ='VC.00 销售费用BKD'!E48-'VC&VD.01.2 TOD 预审+剩余期间'!F12 -> 1491583.5 | H12: =F12+G12 -> 5809450.1
D13: 管理费用 | E13: VD.00管理费用BKD | F13: 5869257.8 | G13: ='VD.00 管理费用BKD'!E73-'VC&VD.01.2 TOD 预审+剩余期间'!F13 -> 1972736.3 | H13: =F13+G13 -> 7841994.1
D14: 总体金额 | F14: =SUM(F12:F13) -> 10187124 | G14: =SUM(G12:G13) -> 3464319.8 | H14: =F14+G14 -> 13651444
F15: Rx | G15: Rx
G17: AA | H17: BB | I17: CC=AA+BB
C18: 1.2 | D18: 剔除 | E18: 数据来源 X-ref | F18: 执行审计工作底稿X-ref | G18: 预审期间（如1-9月份） | H18: 剩余期间（如10-12月份) | I18: 合计
D19: a. 在其他底稿中已执行程序项：（以下可由项目组自定义）
D20: 固定资产折旧费 | E20: VC.00 销售费用BKD | F20: K.03.1 折旧测试 | G20: 207524 | H20: =I20-G20 -> 74868 | I20: ='VC.00 销售费用BKD'!E36 -> 282392
D21: 固定资产折旧费 | E21: VD.00 管理费用BKD | F21: K.03.1 折旧测试 | G21: 1091108.2 | H21: =I21-G21 -> 347101.02 | I21: ='VD.00 管理费用BKD'!E32+'VD.00 管理费用BKD'!E37+'VD.00 管理费用BKD'!E50+'VD.00 管理费用BKD'!E57+'VD.00 管理费用BKD'!E61 -> 1438209.2
D22: 无形资产摊销费 | E22: VD.00 管理费用BKD | F22: L1.01.1 BKD | G22: 187238.91 | H22: =I22-G22 -> 62028.39 | I22: ='VD.00 管理费用BKD'!E36+'VD.00 管理费用BKD'!E66 -> 249267.3
D23: 工资薪酬 | E23: VC.00 销售费用BKD | F23: VB01.1工资SAP/VB.02雇主成本SAP | G23: 2301885.8 | H23: =I23-G23 -> 772350.14 | I23: ='VC.00 销售费用BKD'!C64 -> 3074235.9
D24: 工资薪酬 | E24: VD.00 管理费用BKD | F24: VB01.1工资SAP/VB.02雇主成本SAP | G24: 2596627.7 | H24: =I24-G24 -> 1048694.2 | I24: ='VD.00 管理费用BKD'!E31+'VD.00 管理费用BKD'!E34+'VD.00 管理费用BKD'!E38+'VD.00 管理费用BKD'!E40+'VD.00 管理费用BKD'!E47+'VD.00 管理费用BKD'!E65 -> 3645321.8
D25: 租赁费 | E25: VC.00 销售费用BKD | F25: LR.04 租赁费 | G25: 200619.03 | H25: =I25-G25 -> 66766.74 | I25: ='VC.00 销售费用BKD'!E37 -> 267385.77
D26: 服务费 | E26: VC.00 销售费用BKD 表2 | F26: VC.00 表2 | G26: 849056.6 | H26: =I26-G26 -> 283018.86 | I26: ='VC.00 销售费用BKD'!E32 -> 1132075.5
D27: 中介机构费\法律服务费 | E27: VD.00 管理费用BKD | F27: VD.01.3复核法律费用 | G27: 233180 | H27: =I27-G27 -> 100000 | I27: ='VD.00 管理费用BKD'!E35 -> 333180
D28: b. 负值（包括预提冲销产生的负值） | E28: VC&VD.01.2 TOD 抽样工具输出-年审 | F28: 对于负值我们执行的审计工作详见以下表2 | G28: -983656.66 | H28: =I28-G28 -> -109569.71 | I28: -1093226.4
D30: 剔除样本合计 | G30: =SUM(G20:G28) -> 6683583.5 | H30: =SUM(H20:H28) -> 2645257.6 | I30: =SUM(I20:I28) -> 9328841.1
G31: Rx | H31: Rx | I31: Rx
D32: 扣除剔除项后样本总体金额： | G32: =F14-G30 -> 3503540.9 | H32: =G14-H30 -> 819062.22 | I32: =H14-I30 -> 4322603.2
E35: AA | F35: BB | G35: CC | H35: DD | I35: EE=AA+CC | J35: FF=BB+DD
C36: 2 | D36: 确定关键项（key item） | E36: 预审期间（如1-9月份） | G36: 剩余期间（如10-12月份） | I36: 合计
E37: 数量 | F37: 金额 | G37: 数量 | H37: 金额 | I37: 数量 | J37: 金额
D38: 单笔发生额大于测试阈值 | E38: 0 | F38: 0 | G38: 0 | H38: 0 | I38: =G38+E38 -> 0 | J38: =H38+F38 -> 0
D40: 合计 | E40: =SUM(E38:E38) -> 0 | F40: =SUM(F38:F38) -> 0 | G40: =SUM(G38:G38) -> 0 | H40: =SUM(H38:H38) -> 0 | I40: =E40+G40 -> 0 | J40: =H40+F40 -> 0
E41: Rx | F41: Rx | G41: Rx | H41: Rx | I41: Rx | J41: Rx
C43: 3 | D43: 使用安永抽样工具对扣除关键项后的剩余样本总体抽取代表性样本
E44: 预审期间（如1-9月份） | F44: 剩余期间（如10-12月份) | G44: 合计
D45: 扣除剔除项和关键项后剩余样本总体： | E45: =G32-F40 -> 3503540.9 | F45: =H32-H40 -> 819062.22 | G45: =I32-J40 -> 4322603.2
C47: 4 | D47: 请项目组在以下填写年审预审分配代表性样本的策略：
D48: 由于交易在整个期间均匀发生，能以相似的方式分配样本，我们使用skywind智能抽样工具抽样，共抽出5个代表性样本，skywind智能抽样工具计算出在中期（1-9月）抽取4个代表性样本，剩余期间（10-12月）抽取1个代表性样本。
...

Sheet VC&VD.01.2 TOD 抽样工具输出-预审
B1: Skywind-TOD | G1: 抽样策略工作底稿
A2: 客户名称 | D2: XYZ公司
A3: 截止日期 | D3: 45930
A4: Canvas ID | D4: 0000 | O4: 相关操作请参考<VC&VD.01.2 TOD 抽样工具输出-年审>，此处不再介绍。
A6: 抽样项目基础信息
A8: 版本号 | F8: V2.0.0
A9: Skywind TOD 抽样记录 | F9: 167D8781D8154D7882F64C9BFC59101E
A10: 测试类型 | F10: 详细测试
A11: 重大账户类型 | F11: 费用
A12: 抽样科目 | F12: U.管理费用, U.销售费用
A13: 审计期间 | F13: 中期
A14: 是否已执行利润表中期抽样
A15: 可容忍误差 （TE） | F15: 787,500.00
A16: 测试涵盖的认定 | F16: 存在/发生, 计量/计价, 列报和披露
A17: 是否存在与上述认定相关的舞弊或特别风险？ | F17: 否
A18: 综合风险评估 | F18: 最低
A19: 是否为PCAOB审计？ | F19: 否
A20: 您是否正在上传数据以进行样本选择？ | F20: 是
A21: 是否适用于非复杂方法？（结论） | F21: 否
A22: 是否适用于非复杂方法？ | F22: 否
A24: 源数据汇总
A26: 导入的数据文件
A27: 文件名 | E27: 文件类型 | G27: sheet | H27: 上传日期
A28: 样例-20251231 XYZ公司-抽样样本池.xlsx | E28: xlsx | H28: 2025/10/09
A30: 匹配详细信息
A31: 抽样单位列： | F31: Month, 日期, 凭证号, 摘要, 科目代码, 科目, 科目名称, 序号
A32: 抽样单位货币列： | F32: 净额
A33: 抽样单位详情：
A35: 样本池汇总
A37: 数据上传转换步骤
A38: 已上传数据 | F38: 2,519,884.27
A39: 必要的数据排除项 | F39: -983,656.66
A40: 必要的数据排除项类型 | F40: 所有负值
A41: 样本池总体金额 | F41: 3,503,540.93
A42: 排除项总量 | F42: 94
A43: 已删除零余额（行数） | F43: 0
A44: 已删除空余额（行数） | F44: 0
A45: 已删除负余额（行数） | F45: 94
A46: 已删除正余额（行数） | F46: 0
A47: 关键项
...

Sheet VD.01.3 复核法律费用
B1: 标准工作底稿: VD SWP 管理费用
B2: VD.01.3 复核法律费用
B4: 复核法律费用
B6: 返回汇总页
B8: 安永属性测试说明:
B9: 我们对金额大于测试阈值的法律费用相关账户进行复核（如有），查看其交易性质及金额是否与账面一致，同时对性质特殊（如诉讼等）的法律费用向律师发送审计询问函，对回函差异进行调查，对于未决诉讼，应执行相关程序，请检查勾稽到预期信用损失、预计负债等底稿。
B11: 表1 | R11: 基础操作指引-【01】 | V11: 进阶实操提示-【01】 | X11: 易错点-【01】
